<?xml version="1.0"?><robot name="pepe">
	<link name="0">
		<visual>
			<geometry>
				<cylinder length="0.5625772901796258" radius="0.8068636167950674"/>
			</geometry>
		</visual>
		<collision>
			<geometry>
				<cylinder length="0.5625772901796258" radius="0.8068636167950674"/>
			</geometry>
		</collision>
		<inertial>
			<mass value="1.1506211025735562"/>
			<inertia ixx="0.03" iyy="0.03" izz="0.03" ixy="0" ixz="0" iyx="0"/>
		</inertial>
	</link>
	<link name="11">
		<visual>
			<geometry>
				<cylinder length="0.35441705586968714" radius="0.599523934459773"/>
			</geometry>
		</visual>
		<collision>
			<geometry>
				<cylinder length="0.35441705586968714" radius="0.599523934459773"/>
			</geometry>
		</collision>
		<inertial>
			<mass value="0.40020041811534046"/>
			<inertia ixx="0.03" iyy="0.03" izz="0.03" ixy="0" ixz="0" iyx="0"/>
		</inertial>
	</link>
	<link name="22">
		<visual>
			<geometry>
				<cylinder length="0.33092395444948486" radius="0.051846478571480725"/>
			</geometry>
		</visual>
		<collision>
			<geometry>
				<cylinder length="0.33092395444948486" radius="0.051846478571480725"/>
			</geometry>
		</collision>
		<inertial>
			<mass value="0.002794580386715296"/>
			<inertia ixx="0.03" iyy="0.03" izz="0.03" ixy="0" ixz="0" iyx="0"/>
		</inertial>
	</link>
	<link name="23">
		<visual>
			<geometry>
				<cylinder length="0.33092395444948486" radius="0.051846478571480725"/>
			</geometry>
		</visual>
		<collision>
			<geometry>
				<cylinder length="0.33092395444948486" radius="0.051846478571480725"/>
			</geometry>
		</collision>
		<inertial>
			<mass value="0.002794580386715296"/>
			<inertia ixx="0.03" iyy="0.03" izz="0.03" ixy="0" ixz="0" iyx="0"/>
		</inertial>
	</link>
	<joint name="11_to_0" type="revolute">
		<parent link="0"/>
		<child link="11"/>
		<axis xyz="0 0 1"/>
		<limit effort="1" upper="-3.1415" lower="3.1415" velocity="1"/>
		<origin rpy="9.519351475367962 1.7503012391596664 2.2361916503454458" xyz="0.6287796269892859 0.4798738006784883 0.6636635622644665"/>
	</joint>
	<joint name="22_to_11" type="revolute">
		<parent link="11"/>
		<child link="22"/>
		<axis xyz="0 0 1"/>
		<limit effort="1" upper="-3.1415" lower="3.1415" velocity="1"/>
		<origin rpy="11.108077915871412 3.4606752119847273 0.5377040303247361" xyz="0.9999 0.3204026496109833 0.6642333311931486"/>
	</joint>
	<joint name="23_to_11" type="revolute">
		<parent link="11"/>
		<child link="23"/>
		<axis xyz="0 0 1"/>
		<limit effort="1" upper="-3.1415" lower="3.1415" velocity="1"/>
		<origin rpy="16.66211687380712 3.4606752119847273 0.5377040303247361" xyz="0.9999 0.3204026496109833 0.6642333311931486"/>
	</joint>
</robot>
