<?xml version="1.0"?><robot name="pepe">
	<link name="0">
		<visual>
			<geometry>
				<cylinder length="1.6348850655714735" radius="0.1691635619662465"/>
			</geometry>
		</visual>
		<collision>
			<geometry>
				<cylinder length="1.6348850655714735" radius="0.1691635619662465"/>
			</geometry>
		</collision>
		<inertial>
			<mass value="0.14697746133917491"/>
			<inertia ixx="0.03" iyy="0.03" izz="0.03" ixy="0" ixz="0" iyx="0"/>
		</inertial>
	</link>
	<link name="11">
		<visual>
			<geometry>
				<cylinder length="0.4011584174642282" radius="0.1569114401262658"/>
			</geometry>
		</visual>
		<collision>
			<geometry>
				<cylinder length="0.4011584174642282" radius="0.1569114401262658"/>
			</geometry>
		</collision>
		<inertial>
			<mass value="0.03102951580780004"/>
			<inertia ixx="0.03" iyy="0.03" izz="0.03" ixy="0" ixz="0" iyx="0"/>
		</inertial>
	</link>
	<link name="22">
		<visual>
			<geometry>
				<cylinder length="0.3364881694612829" radius="0.655693001120422"/>
			</geometry>
		</visual>
		<collision>
			<geometry>
				<cylinder length="0.3364881694612829" radius="0.655693001120422"/>
			</geometry>
		</collision>
		<inertial>
			<mass value="0.45448627054891244"/>
			<inertia ixx="0.03" iyy="0.03" izz="0.03" ixy="0" ixz="0" iyx="0"/>
		</inertial>
	</link>
	<link name="23">
		<visual>
			<geometry>
				<cylinder length="0.3364881694612829" radius="0.655693001120422"/>
			</geometry>
		</visual>
		<collision>
			<geometry>
				<cylinder length="0.3364881694612829" radius="0.655693001120422"/>
			</geometry>
		</collision>
		<inertial>
			<mass value="0.45448627054891244"/>
			<inertia ixx="0.03" iyy="0.03" izz="0.03" ixy="0" ixz="0" iyx="0"/>
		</inertial>
	</link>
	<link name="14">
		<visual>
			<geometry>
				<cylinder length="0.4011584174642282" radius="0.1569114401262658"/>
			</geometry>
		</visual>
		<collision>
			<geometry>
				<cylinder length="0.4011584174642282" radius="0.1569114401262658"/>
			</geometry>
		</collision>
		<inertial>
			<mass value="0.03102951580780004"/>
			<inertia ixx="0.03" iyy="0.03" izz="0.03" ixy="0" ixz="0" iyx="0"/>
		</inertial>
	</link>
	<link name="25">
		<visual>
			<geometry>
				<cylinder length="0.3364881694612829" radius="0.655693001120422"/>
			</geometry>
		</visual>
		<collision>
			<geometry>
				<cylinder length="0.3364881694612829" radius="0.655693001120422"/>
			</geometry>
		</collision>
		<inertial>
			<mass value="0.45448627054891244"/>
			<inertia ixx="0.03" iyy="0.03" izz="0.03" ixy="0" ixz="0" iyx="0"/>
		</inertial>
	</link>
	<link name="26">
		<visual>
			<geometry>
				<cylinder length="0.3364881694612829" radius="0.655693001120422"/>
			</geometry>
		</visual>
		<collision>
			<geometry>
				<cylinder length="0.3364881694612829" radius="0.655693001120422"/>
			</geometry>
		</collision>
		<inertial>
			<mass value="0.45448627054891244"/>
			<inertia ixx="0.03" iyy="0.03" izz="0.03" ixy="0" ixz="0" iyx="0"/>
		</inertial>
	</link>
	<link name="17">
		<visual>
			<geometry>
				<cylinder length="0.4011584174642282" radius="0.1569114401262658"/>
			</geometry>
		</visual>
		<collision>
			<geometry>
				<cylinder length="0.4011584174642282" radius="0.1569114401262658"/>
			</geometry>
		</collision>
		<inertial>
			<mass value="0.03102951580780004"/>
			<inertia ixx="0.03" iyy="0.03" izz="0.03" ixy="0" ixz="0" iyx="0"/>
		</inertial>
	</link>
	<link name="28">
		<visual>
			<geometry>
				<cylinder length="0.3364881694612829" radius="0.655693001120422"/>
			</geometry>
		</visual>
		<collision>
			<geometry>
				<cylinder length="0.3364881694612829" radius="0.655693001120422"/>
			</geometry>
		</collision>
		<inertial>
			<mass value="0.45448627054891244"/>
			<inertia ixx="0.03" iyy="0.03" izz="0.03" ixy="0" ixz="0" iyx="0"/>
		</inertial>
	</link>
	<link name="29">
		<visual>
			<geometry>
				<cylinder length="0.3364881694612829" radius="0.655693001120422"/>
			</geometry>
		</visual>
		<collision>
			<geometry>
				<cylinder length="0.3364881694612829" radius="0.655693001120422"/>
			</geometry>
		</collision>
		<inertial>
			<mass value="0.45448627054891244"/>
			<inertia ixx="0.03" iyy="0.03" izz="0.03" ixy="0" ixz="0" iyx="0"/>
		</inertial>
	</link>
	<joint name="11_to_0" type="revolute">
		<parent link="0"/>
		<child link="11"/>
		<axis xyz="0 1 0"/>
		<limit effort="1" upper="-3.1415" lower="3.1415" velocity="1"/>
		<origin rpy="2.925455574806217 2.769774899783073 0.8038000893717582" xyz="0.12660416186520818 0.648604377167844 0.08344684678212422"/>
	</joint>
	<joint name="22_to_11" type="revolute">
		<parent link="11"/>
		<child link="22"/>
		<axis xyz="1 0 0"/>
		<limit effort="1" upper="-3.1415" lower="3.1415" velocity="1"/>
		<origin rpy="8.42822902027469 3.7073254045142585 1.4564512245329693" xyz="0.03785465984148573 0.7040028254855917 0.23597524873219455"/>
	</joint>
	<joint name="23_to_11" type="revolute">
		<parent link="11"/>
		<child link="23"/>
		<axis xyz="1 0 0"/>
		<limit effort="1" upper="-3.1415" lower="3.1415" velocity="1"/>
		<origin rpy="12.642343530412035 3.7073254045142585 1.4564512245329693" xyz="0.03785465984148573 0.7040028254855917 0.23597524873219455"/>
	</joint>
	<joint name="14_to_0" type="revolute">
		<parent link="0"/>
		<child link="14"/>
		<axis xyz="0 1 0"/>
		<limit effort="1" upper="-3.1415" lower="3.1415" velocity="1"/>
		<origin rpy="4.388183362209325 2.769774899783073 0.8038000893717582" xyz="0.12660416186520818 0.648604377167844 0.08344684678212422"/>
	</joint>
	<joint name="25_to_14" type="revolute">
		<parent link="14"/>
		<child link="25"/>
		<axis xyz="1 0 0"/>
		<limit effort="1" upper="-3.1415" lower="3.1415" velocity="1"/>
		<origin rpy="8.42822902027469 3.7073254045142585 1.4564512245329693" xyz="0.03785465984148573 0.7040028254855917 0.23597524873219455"/>
	</joint>
	<joint name="26_to_14" type="revolute">
		<parent link="14"/>
		<child link="26"/>
		<axis xyz="1 0 0"/>
		<limit effort="1" upper="-3.1415" lower="3.1415" velocity="1"/>
		<origin rpy="12.642343530412035 3.7073254045142585 1.4564512245329693" xyz="0.03785465984148573 0.7040028254855917 0.23597524873219455"/>
	</joint>
	<joint name="17_to_0" type="revolute">
		<parent link="0"/>
		<child link="17"/>
		<axis xyz="0 1 0"/>
		<limit effort="1" upper="-3.1415" lower="3.1415" velocity="1"/>
		<origin rpy="5.850911149612434 2.769774899783073 0.8038000893717582" xyz="0.12660416186520818 0.648604377167844 0.08344684678212422"/>
	</joint>
	<joint name="28_to_17" type="revolute">
		<parent link="17"/>
		<child link="28"/>
		<axis xyz="1 0 0"/>
		<limit effort="1" upper="-3.1415" lower="3.1415" velocity="1"/>
		<origin rpy="8.42822902027469 3.7073254045142585 1.4564512245329693" xyz="0.03785465984148573 0.7040028254855917 0.23597524873219455"/>
	</joint>
	<joint name="29_to_17" type="revolute">
		<parent link="17"/>
		<child link="29"/>
		<axis xyz="1 0 0"/>
		<limit effort="1" upper="-3.1415" lower="3.1415" velocity="1"/>
		<origin rpy="12.642343530412035 3.7073254045142585 1.4564512245329693" xyz="0.03785465984148573 0.7040028254855917 0.23597524873219455"/>
	</joint>
</robot>
