<?xml version="1.0"?><robot name="pepe">
	<link name="0">
		<visual>
			<geometry>
				<cylinder length="1.9998" radius="0.575373322585344"/>
			</geometry>
		</visual>
		<collision>
			<geometry>
				<cylinder length="1.9998" radius="0.575373322585344"/>
			</geometry>
		</collision>
		<inertial>
			<mass value="2.0798685134506556"/>
			<inertia ixx="0.03" iyy="0.03" izz="0.03" ixy="0" ixz="0" iyx="0"/>
		</inertial>
	</link>
	<link name="11">
		<visual>
			<geometry>
				<cylinder length="0.4712421439808423" radius="0.9999"/>
			</geometry>
		</visual>
		<collision>
			<geometry>
				<cylinder length="0.4712421439808423" radius="0.9999"/>
			</geometry>
		</collision>
		<inertial>
			<mass value="1.480154782225108"/>
			<inertia ixx="0.03" iyy="0.03" izz="0.03" ixy="0" ixz="0" iyx="0"/>
		</inertial>
	</link>
	<link name="12">
		<visual>
			<geometry>
				<cylinder length="0.4712421439808423" radius="0.9999"/>
			</geometry>
		</visual>
		<collision>
			<geometry>
				<cylinder length="0.4712421439808423" radius="0.9999"/>
			</geometry>
		</collision>
		<inertial>
			<mass value="1.480154782225108"/>
			<inertia ixx="0.03" iyy="0.03" izz="0.03" ixy="0" ixz="0" iyx="0"/>
		</inertial>
	</link>
	<link name="13">
		<visual>
			<geometry>
				<cylinder length="0.4712421439808423" radius="0.9999"/>
			</geometry>
		</visual>
		<collision>
			<geometry>
				<cylinder length="0.4712421439808423" radius="0.9999"/>
			</geometry>
		</collision>
		<inertial>
			<mass value="1.480154782225108"/>
			<inertia ixx="0.03" iyy="0.03" izz="0.03" ixy="0" ixz="0" iyx="0"/>
		</inertial>
	</link>
	<joint name="11_to_0" type="revolute">
		<parent link="0"/>
		<child link="11"/>
		<axis xyz="0 0 1"/>
		<limit effort="1" upper="-3.1415" lower="3.1415" velocity="1"/>
		<origin rpy="12.565113977297736 6.282556988648868 6.282556988648868" xyz="0.9620143527404951 0.9992085664588672 0.5231248412405833"/>
	</joint>
	<joint name="12_to_0" type="revolute">
		<parent link="0"/>
		<child link="12"/>
		<axis xyz="0 0 1"/>
		<limit effort="1" upper="-3.1415" lower="3.1415" velocity="1"/>
		<origin rpy="18.847670965946605 6.282556988648868 6.282556988648868" xyz="0.9620143527404951 0.9992085664588672 0.5231248412405833"/>
	</joint>
	<joint name="13_to_0" type="revolute">
		<parent link="0"/>
		<child link="13"/>
		<axis xyz="0 0 1"/>
		<limit effort="1" upper="-3.1415" lower="3.1415" velocity="1"/>
		<origin rpy="25.130227954595473 6.282556988648868 6.282556988648868" xyz="0.9620143527404951 0.9992085664588672 0.5231248412405833"/>
	</joint>
</robot>
