<?xml version="1.0"?><robot name="pepe">
	<link name="0">
		<visual>
			<geometry>
				<cylinder length="1.9998" radius="0.9247680377079103"/>
			</geometry>
		</visual>
		<collision>
			<geometry>
				<cylinder length="1.9998" radius="0.9247680377079103"/>
			</geometry>
		</collision>
		<inertial>
			<mass value="5.3728171262644695"/>
			<inertia ixx="0.03" iyy="0.03" izz="0.03" ixy="0" ixz="0" iyx="0"/>
		</inertial>
	</link>
	<link name="11">
		<visual>
			<geometry>
				<cylinder length="0.46760508841096937" radius="0.7927918971962551"/>
			</geometry>
		</visual>
		<collision>
			<geometry>
				<cylinder length="0.46760508841096937" radius="0.7927918971962551"/>
			</geometry>
		</collision>
		<inertial>
			<mass value="0.9233099306693617"/>
			<inertia ixx="0.03" iyy="0.03" izz="0.03" ixy="0" ixz="0" iyx="0"/>
		</inertial>
	</link>
	<link name="22">
		<visual>
			<geometry>
				<cylinder length="0.3511852875271282" radius="0.9999"/>
			</geometry>
		</visual>
		<collision>
			<geometry>
				<cylinder length="0.3511852875271282" radius="0.9999"/>
			</geometry>
		</collision>
		<inertial>
			<mass value="1.1030604741529875"/>
			<inertia ixx="0.03" iyy="0.03" izz="0.03" ixy="0" ixz="0" iyx="0"/>
		</inertial>
	</link>
	<link name="33">
		<visual>
			<geometry>
				<cylinder length="1.7248786681420325" radius="0.921018508619313"/>
			</geometry>
		</visual>
		<collision>
			<geometry>
				<cylinder length="1.7248786681420325" radius="0.921018508619313"/>
			</geometry>
		</collision>
		<inertial>
			<mass value="4.596689190374097"/>
			<inertia ixx="0.03" iyy="0.03" izz="0.03" ixy="0" ixz="0" iyx="0"/>
		</inertial>
	</link>
	<link name="44">
		<visual>
			<geometry>
				<cylinder length="1.9998" radius="0.9247680377079103"/>
			</geometry>
		</visual>
		<collision>
			<geometry>
				<cylinder length="1.9998" radius="0.9247680377079103"/>
			</geometry>
		</collision>
		<inertial>
			<mass value="5.3728171262644695"/>
			<inertia ixx="0.03" iyy="0.03" izz="0.03" ixy="0" ixz="0" iyx="0"/>
		</inertial>
	</link>
	<link name="55">
		<visual>
			<geometry>
				<cylinder length="0.3981271315755335" radius="0.6282750377540588"/>
			</geometry>
		</visual>
		<collision>
			<geometry>
				<cylinder length="0.3981271315755335" radius="0.6282750377540588"/>
			</geometry>
		</collision>
		<inertial>
			<mass value="0.49370924243067194"/>
			<inertia ixx="0.03" iyy="0.03" izz="0.03" ixy="0" ixz="0" iyx="0"/>
		</inertial>
	</link>
	<link name="66">
		<visual>
			<geometry>
				<cylinder length="1.9998" radius="0.9247680377079103"/>
			</geometry>
		</visual>
		<collision>
			<geometry>
				<cylinder length="1.9998" radius="0.9247680377079103"/>
			</geometry>
		</collision>
		<inertial>
			<mass value="5.3728171262644695"/>
			<inertia ixx="0.03" iyy="0.03" izz="0.03" ixy="0" ixz="0" iyx="0"/>
		</inertial>
	</link>
	<link name="57">
		<visual>
			<geometry>
				<cylinder length="0.3981271315755335" radius="0.6282750377540588"/>
			</geometry>
		</visual>
		<collision>
			<geometry>
				<cylinder length="0.3981271315755335" radius="0.6282750377540588"/>
			</geometry>
		</collision>
		<inertial>
			<mass value="0.49370924243067194"/>
			<inertia ixx="0.03" iyy="0.03" izz="0.03" ixy="0" ixz="0" iyx="0"/>
		</inertial>
	</link>
	<link name="68">
		<visual>
			<geometry>
				<cylinder length="1.9998" radius="0.9247680377079103"/>
			</geometry>
		</visual>
		<collision>
			<geometry>
				<cylinder length="1.9998" radius="0.9247680377079103"/>
			</geometry>
		</collision>
		<inertial>
			<mass value="5.3728171262644695"/>
			<inertia ixx="0.03" iyy="0.03" izz="0.03" ixy="0" ixz="0" iyx="0"/>
		</inertial>
	</link>
	<link name="59">
		<visual>
			<geometry>
				<cylinder length="0.3981271315755335" radius="0.6282750377540588"/>
			</geometry>
		</visual>
		<collision>
			<geometry>
				<cylinder length="0.3981271315755335" radius="0.6282750377540588"/>
			</geometry>
		</collision>
		<inertial>
			<mass value="0.49370924243067194"/>
			<inertia ixx="0.03" iyy="0.03" izz="0.03" ixy="0" ixz="0" iyx="0"/>
		</inertial>
	</link>
	<link name="610">
		<visual>
			<geometry>
				<cylinder length="1.9998" radius="0.9247680377079103"/>
			</geometry>
		</visual>
		<collision>
			<geometry>
				<cylinder length="1.9998" radius="0.9247680377079103"/>
			</geometry>
		</collision>
		<inertial>
			<mass value="5.3728171262644695"/>
			<inertia ixx="0.03" iyy="0.03" izz="0.03" ixy="0" ixz="0" iyx="0"/>
		</inertial>
	</link>
	<link name="311">
		<visual>
			<geometry>
				<cylinder length="1.7248786681420325" radius="0.921018508619313"/>
			</geometry>
		</visual>
		<collision>
			<geometry>
				<cylinder length="1.7248786681420325" radius="0.921018508619313"/>
			</geometry>
		</collision>
		<inertial>
			<mass value="4.596689190374097"/>
			<inertia ixx="0.03" iyy="0.03" izz="0.03" ixy="0" ixz="0" iyx="0"/>
		</inertial>
	</link>
	<link name="412">
		<visual>
			<geometry>
				<cylinder length="1.9998" radius="0.9247680377079103"/>
			</geometry>
		</visual>
		<collision>
			<geometry>
				<cylinder length="1.9998" radius="0.9247680377079103"/>
			</geometry>
		</collision>
		<inertial>
			<mass value="5.3728171262644695"/>
			<inertia ixx="0.03" iyy="0.03" izz="0.03" ixy="0" ixz="0" iyx="0"/>
		</inertial>
	</link>
	<link name="513">
		<visual>
			<geometry>
				<cylinder length="0.3981271315755335" radius="0.6282750377540588"/>
			</geometry>
		</visual>
		<collision>
			<geometry>
				<cylinder length="0.3981271315755335" radius="0.6282750377540588"/>
			</geometry>
		</collision>
		<inertial>
			<mass value="0.49370924243067194"/>
			<inertia ixx="0.03" iyy="0.03" izz="0.03" ixy="0" ixz="0" iyx="0"/>
		</inertial>
	</link>
	<link name="614">
		<visual>
			<geometry>
				<cylinder length="1.9998" radius="0.9247680377079103"/>
			</geometry>
		</visual>
		<collision>
			<geometry>
				<cylinder length="1.9998" radius="0.9247680377079103"/>
			</geometry>
		</collision>
		<inertial>
			<mass value="5.3728171262644695"/>
			<inertia ixx="0.03" iyy="0.03" izz="0.03" ixy="0" ixz="0" iyx="0"/>
		</inertial>
	</link>
	<link name="515">
		<visual>
			<geometry>
				<cylinder length="0.3981271315755335" radius="0.6282750377540588"/>
			</geometry>
		</visual>
		<collision>
			<geometry>
				<cylinder length="0.3981271315755335" radius="0.6282750377540588"/>
			</geometry>
		</collision>
		<inertial>
			<mass value="0.49370924243067194"/>
			<inertia ixx="0.03" iyy="0.03" izz="0.03" ixy="0" ixz="0" iyx="0"/>
		</inertial>
	</link>
	<link name="616">
		<visual>
			<geometry>
				<cylinder length="1.9998" radius="0.9247680377079103"/>
			</geometry>
		</visual>
		<collision>
			<geometry>
				<cylinder length="1.9998" radius="0.9247680377079103"/>
			</geometry>
		</collision>
		<inertial>
			<mass value="5.3728171262644695"/>
			<inertia ixx="0.03" iyy="0.03" izz="0.03" ixy="0" ixz="0" iyx="0"/>
		</inertial>
	</link>
	<link name="517">
		<visual>
			<geometry>
				<cylinder length="0.3981271315755335" radius="0.6282750377540588"/>
			</geometry>
		</visual>
		<collision>
			<geometry>
				<cylinder length="0.3981271315755335" radius="0.6282750377540588"/>
			</geometry>
		</collision>
		<inertial>
			<mass value="0.49370924243067194"/>
			<inertia ixx="0.03" iyy="0.03" izz="0.03" ixy="0" ixz="0" iyx="0"/>
		</inertial>
	</link>
	<link name="618">
		<visual>
			<geometry>
				<cylinder length="1.9998" radius="0.9247680377079103"/>
			</geometry>
		</visual>
		<collision>
			<geometry>
				<cylinder length="1.9998" radius="0.9247680377079103"/>
			</geometry>
		</collision>
		<inertial>
			<mass value="5.3728171262644695"/>
			<inertia ixx="0.03" iyy="0.03" izz="0.03" ixy="0" ixz="0" iyx="0"/>
		</inertial>
	</link>
	<link name="319">
		<visual>
			<geometry>
				<cylinder length="1.7248786681420325" radius="0.921018508619313"/>
			</geometry>
		</visual>
		<collision>
			<geometry>
				<cylinder length="1.7248786681420325" radius="0.921018508619313"/>
			</geometry>
		</collision>
		<inertial>
			<mass value="4.596689190374097"/>
			<inertia ixx="0.03" iyy="0.03" izz="0.03" ixy="0" ixz="0" iyx="0"/>
		</inertial>
	</link>
	<link name="420">
		<visual>
			<geometry>
				<cylinder length="1.9998" radius="0.9247680377079103"/>
			</geometry>
		</visual>
		<collision>
			<geometry>
				<cylinder length="1.9998" radius="0.9247680377079103"/>
			</geometry>
		</collision>
		<inertial>
			<mass value="5.3728171262644695"/>
			<inertia ixx="0.03" iyy="0.03" izz="0.03" ixy="0" ixz="0" iyx="0"/>
		</inertial>
	</link>
	<link name="521">
		<visual>
			<geometry>
				<cylinder length="0.3981271315755335" radius="0.6282750377540588"/>
			</geometry>
		</visual>
		<collision>
			<geometry>
				<cylinder length="0.3981271315755335" radius="0.6282750377540588"/>
			</geometry>
		</collision>
		<inertial>
			<mass value="0.49370924243067194"/>
			<inertia ixx="0.03" iyy="0.03" izz="0.03" ixy="0" ixz="0" iyx="0"/>
		</inertial>
	</link>
	<link name="622">
		<visual>
			<geometry>
				<cylinder length="1.9998" radius="0.9247680377079103"/>
			</geometry>
		</visual>
		<collision>
			<geometry>
				<cylinder length="1.9998" radius="0.9247680377079103"/>
			</geometry>
		</collision>
		<inertial>
			<mass value="5.3728171262644695"/>
			<inertia ixx="0.03" iyy="0.03" izz="0.03" ixy="0" ixz="0" iyx="0"/>
		</inertial>
	</link>
	<link name="523">
		<visual>
			<geometry>
				<cylinder length="0.3981271315755335" radius="0.6282750377540588"/>
			</geometry>
		</visual>
		<collision>
			<geometry>
				<cylinder length="0.3981271315755335" radius="0.6282750377540588"/>
			</geometry>
		</collision>
		<inertial>
			<mass value="0.49370924243067194"/>
			<inertia ixx="0.03" iyy="0.03" izz="0.03" ixy="0" ixz="0" iyx="0"/>
		</inertial>
	</link>
	<link name="624">
		<visual>
			<geometry>
				<cylinder length="1.9998" radius="0.9247680377079103"/>
			</geometry>
		</visual>
		<collision>
			<geometry>
				<cylinder length="1.9998" radius="0.9247680377079103"/>
			</geometry>
		</collision>
		<inertial>
			<mass value="5.3728171262644695"/>
			<inertia ixx="0.03" iyy="0.03" izz="0.03" ixy="0" ixz="0" iyx="0"/>
		</inertial>
	</link>
	<link name="525">
		<visual>
			<geometry>
				<cylinder length="0.3981271315755335" radius="0.6282750377540588"/>
			</geometry>
		</visual>
		<collision>
			<geometry>
				<cylinder length="0.3981271315755335" radius="0.6282750377540588"/>
			</geometry>
		</collision>
		<inertial>
			<mass value="0.49370924243067194"/>
			<inertia ixx="0.03" iyy="0.03" izz="0.03" ixy="0" ixz="0" iyx="0"/>
		</inertial>
	</link>
	<link name="626">
		<visual>
			<geometry>
				<cylinder length="1.9998" radius="0.9247680377079103"/>
			</geometry>
		</visual>
		<collision>
			<geometry>
				<cylinder length="1.9998" radius="0.9247680377079103"/>
			</geometry>
		</collision>
		<inertial>
			<mass value="5.3728171262644695"/>
			<inertia ixx="0.03" iyy="0.03" izz="0.03" ixy="0" ixz="0" iyx="0"/>
		</inertial>
	</link>
	<link name="227">
		<visual>
			<geometry>
				<cylinder length="0.3511852875271282" radius="0.9999"/>
			</geometry>
		</visual>
		<collision>
			<geometry>
				<cylinder length="0.3511852875271282" radius="0.9999"/>
			</geometry>
		</collision>
		<inertial>
			<mass value="1.1030604741529875"/>
			<inertia ixx="0.03" iyy="0.03" izz="0.03" ixy="0" ixz="0" iyx="0"/>
		</inertial>
	</link>
	<link name="328">
		<visual>
			<geometry>
				<cylinder length="1.7248786681420325" radius="0.921018508619313"/>
			</geometry>
		</visual>
		<collision>
			<geometry>
				<cylinder length="1.7248786681420325" radius="0.921018508619313"/>
			</geometry>
		</collision>
		<inertial>
			<mass value="4.596689190374097"/>
			<inertia ixx="0.03" iyy="0.03" izz="0.03" ixy="0" ixz="0" iyx="0"/>
		</inertial>
	</link>
	<link name="429">
		<visual>
			<geometry>
				<cylinder length="1.9998" radius="0.9247680377079103"/>
			</geometry>
		</visual>
		<collision>
			<geometry>
				<cylinder length="1.9998" radius="0.9247680377079103"/>
			</geometry>
		</collision>
		<inertial>
			<mass value="5.3728171262644695"/>
			<inertia ixx="0.03" iyy="0.03" izz="0.03" ixy="0" ixz="0" iyx="0"/>
		</inertial>
	</link>
	<link name="530">
		<visual>
			<geometry>
				<cylinder length="0.3981271315755335" radius="0.6282750377540588"/>
			</geometry>
		</visual>
		<collision>
			<geometry>
				<cylinder length="0.3981271315755335" radius="0.6282750377540588"/>
			</geometry>
		</collision>
		<inertial>
			<mass value="0.49370924243067194"/>
			<inertia ixx="0.03" iyy="0.03" izz="0.03" ixy="0" ixz="0" iyx="0"/>
		</inertial>
	</link>
	<link name="631">
		<visual>
			<geometry>
				<cylinder length="1.9998" radius="0.9247680377079103"/>
			</geometry>
		</visual>
		<collision>
			<geometry>
				<cylinder length="1.9998" radius="0.9247680377079103"/>
			</geometry>
		</collision>
		<inertial>
			<mass value="5.3728171262644695"/>
			<inertia ixx="0.03" iyy="0.03" izz="0.03" ixy="0" ixz="0" iyx="0"/>
		</inertial>
	</link>
	<link name="532">
		<visual>
			<geometry>
				<cylinder length="0.3981271315755335" radius="0.6282750377540588"/>
			</geometry>
		</visual>
		<collision>
			<geometry>
				<cylinder length="0.3981271315755335" radius="0.6282750377540588"/>
			</geometry>
		</collision>
		<inertial>
			<mass value="0.49370924243067194"/>
			<inertia ixx="0.03" iyy="0.03" izz="0.03" ixy="0" ixz="0" iyx="0"/>
		</inertial>
	</link>
	<link name="633">
		<visual>
			<geometry>
				<cylinder length="1.9998" radius="0.9247680377079103"/>
			</geometry>
		</visual>
		<collision>
			<geometry>
				<cylinder length="1.9998" radius="0.9247680377079103"/>
			</geometry>
		</collision>
		<inertial>
			<mass value="5.3728171262644695"/>
			<inertia ixx="0.03" iyy="0.03" izz="0.03" ixy="0" ixz="0" iyx="0"/>
		</inertial>
	</link>
	<link name="534">
		<visual>
			<geometry>
				<cylinder length="0.3981271315755335" radius="0.6282750377540588"/>
			</geometry>
		</visual>
		<collision>
			<geometry>
				<cylinder length="0.3981271315755335" radius="0.6282750377540588"/>
			</geometry>
		</collision>
		<inertial>
			<mass value="0.49370924243067194"/>
			<inertia ixx="0.03" iyy="0.03" izz="0.03" ixy="0" ixz="0" iyx="0"/>
		</inertial>
	</link>
	<link name="635">
		<visual>
			<geometry>
				<cylinder length="1.9998" radius="0.9247680377079103"/>
			</geometry>
		</visual>
		<collision>
			<geometry>
				<cylinder length="1.9998" radius="0.9247680377079103"/>
			</geometry>
		</collision>
		<inertial>
			<mass value="5.3728171262644695"/>
			<inertia ixx="0.03" iyy="0.03" izz="0.03" ixy="0" ixz="0" iyx="0"/>
		</inertial>
	</link>
	<link name="336">
		<visual>
			<geometry>
				<cylinder length="1.7248786681420325" radius="0.921018508619313"/>
			</geometry>
		</visual>
		<collision>
			<geometry>
				<cylinder length="1.7248786681420325" radius="0.921018508619313"/>
			</geometry>
		</collision>
		<inertial>
			<mass value="4.596689190374097"/>
			<inertia ixx="0.03" iyy="0.03" izz="0.03" ixy="0" ixz="0" iyx="0"/>
		</inertial>
	</link>
	<link name="437">
		<visual>
			<geometry>
				<cylinder length="1.9998" radius="0.9247680377079103"/>
			</geometry>
		</visual>
		<collision>
			<geometry>
				<cylinder length="1.9998" radius="0.9247680377079103"/>
			</geometry>
		</collision>
		<inertial>
			<mass value="5.3728171262644695"/>
			<inertia ixx="0.03" iyy="0.03" izz="0.03" ixy="0" ixz="0" iyx="0"/>
		</inertial>
	</link>
	<link name="538">
		<visual>
			<geometry>
				<cylinder length="0.3981271315755335" radius="0.6282750377540588"/>
			</geometry>
		</visual>
		<collision>
			<geometry>
				<cylinder length="0.3981271315755335" radius="0.6282750377540588"/>
			</geometry>
		</collision>
		<inertial>
			<mass value="0.49370924243067194"/>
			<inertia ixx="0.03" iyy="0.03" izz="0.03" ixy="0" ixz="0" iyx="0"/>
		</inertial>
	</link>
	<link name="639">
		<visual>
			<geometry>
				<cylinder length="1.9998" radius="0.9247680377079103"/>
			</geometry>
		</visual>
		<collision>
			<geometry>
				<cylinder length="1.9998" radius="0.9247680377079103"/>
			</geometry>
		</collision>
		<inertial>
			<mass value="5.3728171262644695"/>
			<inertia ixx="0.03" iyy="0.03" izz="0.03" ixy="0" ixz="0" iyx="0"/>
		</inertial>
	</link>
	<link name="540">
		<visual>
			<geometry>
				<cylinder length="0.3981271315755335" radius="0.6282750377540588"/>
			</geometry>
		</visual>
		<collision>
			<geometry>
				<cylinder length="0.3981271315755335" radius="0.6282750377540588"/>
			</geometry>
		</collision>
		<inertial>
			<mass value="0.49370924243067194"/>
			<inertia ixx="0.03" iyy="0.03" izz="0.03" ixy="0" ixz="0" iyx="0"/>
		</inertial>
	</link>
	<link name="641">
		<visual>
			<geometry>
				<cylinder length="1.9998" radius="0.9247680377079103"/>
			</geometry>
		</visual>
		<collision>
			<geometry>
				<cylinder length="1.9998" radius="0.9247680377079103"/>
			</geometry>
		</collision>
		<inertial>
			<mass value="5.3728171262644695"/>
			<inertia ixx="0.03" iyy="0.03" izz="0.03" ixy="0" ixz="0" iyx="0"/>
		</inertial>
	</link>
	<link name="542">
		<visual>
			<geometry>
				<cylinder length="0.3981271315755335" radius="0.6282750377540588"/>
			</geometry>
		</visual>
		<collision>
			<geometry>
				<cylinder length="0.3981271315755335" radius="0.6282750377540588"/>
			</geometry>
		</collision>
		<inertial>
			<mass value="0.49370924243067194"/>
			<inertia ixx="0.03" iyy="0.03" izz="0.03" ixy="0" ixz="0" iyx="0"/>
		</inertial>
	</link>
	<link name="643">
		<visual>
			<geometry>
				<cylinder length="1.9998" radius="0.9247680377079103"/>
			</geometry>
		</visual>
		<collision>
			<geometry>
				<cylinder length="1.9998" radius="0.9247680377079103"/>
			</geometry>
		</collision>
		<inertial>
			<mass value="5.3728171262644695"/>
			<inertia ixx="0.03" iyy="0.03" izz="0.03" ixy="0" ixz="0" iyx="0"/>
		</inertial>
	</link>
	<link name="344">
		<visual>
			<geometry>
				<cylinder length="1.7248786681420325" radius="0.921018508619313"/>
			</geometry>
		</visual>
		<collision>
			<geometry>
				<cylinder length="1.7248786681420325" radius="0.921018508619313"/>
			</geometry>
		</collision>
		<inertial>
			<mass value="4.596689190374097"/>
			<inertia ixx="0.03" iyy="0.03" izz="0.03" ixy="0" ixz="0" iyx="0"/>
		</inertial>
	</link>
	<link name="445">
		<visual>
			<geometry>
				<cylinder length="1.9998" radius="0.9247680377079103"/>
			</geometry>
		</visual>
		<collision>
			<geometry>
				<cylinder length="1.9998" radius="0.9247680377079103"/>
			</geometry>
		</collision>
		<inertial>
			<mass value="5.3728171262644695"/>
			<inertia ixx="0.03" iyy="0.03" izz="0.03" ixy="0" ixz="0" iyx="0"/>
		</inertial>
	</link>
	<link name="546">
		<visual>
			<geometry>
				<cylinder length="0.3981271315755335" radius="0.6282750377540588"/>
			</geometry>
		</visual>
		<collision>
			<geometry>
				<cylinder length="0.3981271315755335" radius="0.6282750377540588"/>
			</geometry>
		</collision>
		<inertial>
			<mass value="0.49370924243067194"/>
			<inertia ixx="0.03" iyy="0.03" izz="0.03" ixy="0" ixz="0" iyx="0"/>
		</inertial>
	</link>
	<link name="647">
		<visual>
			<geometry>
				<cylinder length="1.9998" radius="0.9247680377079103"/>
			</geometry>
		</visual>
		<collision>
			<geometry>
				<cylinder length="1.9998" radius="0.9247680377079103"/>
			</geometry>
		</collision>
		<inertial>
			<mass value="5.3728171262644695"/>
			<inertia ixx="0.03" iyy="0.03" izz="0.03" ixy="0" ixz="0" iyx="0"/>
		</inertial>
	</link>
	<link name="548">
		<visual>
			<geometry>
				<cylinder length="0.3981271315755335" radius="0.6282750377540588"/>
			</geometry>
		</visual>
		<collision>
			<geometry>
				<cylinder length="0.3981271315755335" radius="0.6282750377540588"/>
			</geometry>
		</collision>
		<inertial>
			<mass value="0.49370924243067194"/>
			<inertia ixx="0.03" iyy="0.03" izz="0.03" ixy="0" ixz="0" iyx="0"/>
		</inertial>
	</link>
	<link name="649">
		<visual>
			<geometry>
				<cylinder length="1.9998" radius="0.9247680377079103"/>
			</geometry>
		</visual>
		<collision>
			<geometry>
				<cylinder length="1.9998" radius="0.9247680377079103"/>
			</geometry>
		</collision>
		<inertial>
			<mass value="5.3728171262644695"/>
			<inertia ixx="0.03" iyy="0.03" izz="0.03" ixy="0" ixz="0" iyx="0"/>
		</inertial>
	</link>
	<link name="550">
		<visual>
			<geometry>
				<cylinder length="0.3981271315755335" radius="0.6282750377540588"/>
			</geometry>
		</visual>
		<collision>
			<geometry>
				<cylinder length="0.3981271315755335" radius="0.6282750377540588"/>
			</geometry>
		</collision>
		<inertial>
			<mass value="0.49370924243067194"/>
			<inertia ixx="0.03" iyy="0.03" izz="0.03" ixy="0" ixz="0" iyx="0"/>
		</inertial>
	</link>
	<link name="651">
		<visual>
			<geometry>
				<cylinder length="1.9998" radius="0.9247680377079103"/>
			</geometry>
		</visual>
		<collision>
			<geometry>
				<cylinder length="1.9998" radius="0.9247680377079103"/>
			</geometry>
		</collision>
		<inertial>
			<mass value="5.3728171262644695"/>
			<inertia ixx="0.03" iyy="0.03" izz="0.03" ixy="0" ixz="0" iyx="0"/>
		</inertial>
	</link>
	<link name="152">
		<visual>
			<geometry>
				<cylinder length="0.46760508841096937" radius="0.7927918971962551"/>
			</geometry>
		</visual>
		<collision>
			<geometry>
				<cylinder length="0.46760508841096937" radius="0.7927918971962551"/>
			</geometry>
		</collision>
		<inertial>
			<mass value="0.9233099306693617"/>
			<inertia ixx="0.03" iyy="0.03" izz="0.03" ixy="0" ixz="0" iyx="0"/>
		</inertial>
	</link>
	<link name="253">
		<visual>
			<geometry>
				<cylinder length="0.3511852875271282" radius="0.9999"/>
			</geometry>
		</visual>
		<collision>
			<geometry>
				<cylinder length="0.3511852875271282" radius="0.9999"/>
			</geometry>
		</collision>
		<inertial>
			<mass value="1.1030604741529875"/>
			<inertia ixx="0.03" iyy="0.03" izz="0.03" ixy="0" ixz="0" iyx="0"/>
		</inertial>
	</link>
	<link name="354">
		<visual>
			<geometry>
				<cylinder length="1.7248786681420325" radius="0.921018508619313"/>
			</geometry>
		</visual>
		<collision>
			<geometry>
				<cylinder length="1.7248786681420325" radius="0.921018508619313"/>
			</geometry>
		</collision>
		<inertial>
			<mass value="4.596689190374097"/>
			<inertia ixx="0.03" iyy="0.03" izz="0.03" ixy="0" ixz="0" iyx="0"/>
		</inertial>
	</link>
	<link name="455">
		<visual>
			<geometry>
				<cylinder length="1.9998" radius="0.9247680377079103"/>
			</geometry>
		</visual>
		<collision>
			<geometry>
				<cylinder length="1.9998" radius="0.9247680377079103"/>
			</geometry>
		</collision>
		<inertial>
			<mass value="5.3728171262644695"/>
			<inertia ixx="0.03" iyy="0.03" izz="0.03" ixy="0" ixz="0" iyx="0"/>
		</inertial>
	</link>
	<link name="556">
		<visual>
			<geometry>
				<cylinder length="0.3981271315755335" radius="0.6282750377540588"/>
			</geometry>
		</visual>
		<collision>
			<geometry>
				<cylinder length="0.3981271315755335" radius="0.6282750377540588"/>
			</geometry>
		</collision>
		<inertial>
			<mass value="0.49370924243067194"/>
			<inertia ixx="0.03" iyy="0.03" izz="0.03" ixy="0" ixz="0" iyx="0"/>
		</inertial>
	</link>
	<link name="657">
		<visual>
			<geometry>
				<cylinder length="1.9998" radius="0.9247680377079103"/>
			</geometry>
		</visual>
		<collision>
			<geometry>
				<cylinder length="1.9998" radius="0.9247680377079103"/>
			</geometry>
		</collision>
		<inertial>
			<mass value="5.3728171262644695"/>
			<inertia ixx="0.03" iyy="0.03" izz="0.03" ixy="0" ixz="0" iyx="0"/>
		</inertial>
	</link>
	<link name="558">
		<visual>
			<geometry>
				<cylinder length="0.3981271315755335" radius="0.6282750377540588"/>
			</geometry>
		</visual>
		<collision>
			<geometry>
				<cylinder length="0.3981271315755335" radius="0.6282750377540588"/>
			</geometry>
		</collision>
		<inertial>
			<mass value="0.49370924243067194"/>
			<inertia ixx="0.03" iyy="0.03" izz="0.03" ixy="0" ixz="0" iyx="0"/>
		</inertial>
	</link>
	<link name="659">
		<visual>
			<geometry>
				<cylinder length="1.9998" radius="0.9247680377079103"/>
			</geometry>
		</visual>
		<collision>
			<geometry>
				<cylinder length="1.9998" radius="0.9247680377079103"/>
			</geometry>
		</collision>
		<inertial>
			<mass value="5.3728171262644695"/>
			<inertia ixx="0.03" iyy="0.03" izz="0.03" ixy="0" ixz="0" iyx="0"/>
		</inertial>
	</link>
	<link name="560">
		<visual>
			<geometry>
				<cylinder length="0.3981271315755335" radius="0.6282750377540588"/>
			</geometry>
		</visual>
		<collision>
			<geometry>
				<cylinder length="0.3981271315755335" radius="0.6282750377540588"/>
			</geometry>
		</collision>
		<inertial>
			<mass value="0.49370924243067194"/>
			<inertia ixx="0.03" iyy="0.03" izz="0.03" ixy="0" ixz="0" iyx="0"/>
		</inertial>
	</link>
	<link name="661">
		<visual>
			<geometry>
				<cylinder length="1.9998" radius="0.9247680377079103"/>
			</geometry>
		</visual>
		<collision>
			<geometry>
				<cylinder length="1.9998" radius="0.9247680377079103"/>
			</geometry>
		</collision>
		<inertial>
			<mass value="5.3728171262644695"/>
			<inertia ixx="0.03" iyy="0.03" izz="0.03" ixy="0" ixz="0" iyx="0"/>
		</inertial>
	</link>
	<link name="362">
		<visual>
			<geometry>
				<cylinder length="1.7248786681420325" radius="0.921018508619313"/>
			</geometry>
		</visual>
		<collision>
			<geometry>
				<cylinder length="1.7248786681420325" radius="0.921018508619313"/>
			</geometry>
		</collision>
		<inertial>
			<mass value="4.596689190374097"/>
			<inertia ixx="0.03" iyy="0.03" izz="0.03" ixy="0" ixz="0" iyx="0"/>
		</inertial>
	</link>
	<link name="463">
		<visual>
			<geometry>
				<cylinder length="1.9998" radius="0.9247680377079103"/>
			</geometry>
		</visual>
		<collision>
			<geometry>
				<cylinder length="1.9998" radius="0.9247680377079103"/>
			</geometry>
		</collision>
		<inertial>
			<mass value="5.3728171262644695"/>
			<inertia ixx="0.03" iyy="0.03" izz="0.03" ixy="0" ixz="0" iyx="0"/>
		</inertial>
	</link>
	<link name="564">
		<visual>
			<geometry>
				<cylinder length="0.3981271315755335" radius="0.6282750377540588"/>
			</geometry>
		</visual>
		<collision>
			<geometry>
				<cylinder length="0.3981271315755335" radius="0.6282750377540588"/>
			</geometry>
		</collision>
		<inertial>
			<mass value="0.49370924243067194"/>
			<inertia ixx="0.03" iyy="0.03" izz="0.03" ixy="0" ixz="0" iyx="0"/>
		</inertial>
	</link>
	<link name="665">
		<visual>
			<geometry>
				<cylinder length="1.9998" radius="0.9247680377079103"/>
			</geometry>
		</visual>
		<collision>
			<geometry>
				<cylinder length="1.9998" radius="0.9247680377079103"/>
			</geometry>
		</collision>
		<inertial>
			<mass value="5.3728171262644695"/>
			<inertia ixx="0.03" iyy="0.03" izz="0.03" ixy="0" ixz="0" iyx="0"/>
		</inertial>
	</link>
	<link name="566">
		<visual>
			<geometry>
				<cylinder length="0.3981271315755335" radius="0.6282750377540588"/>
			</geometry>
		</visual>
		<collision>
			<geometry>
				<cylinder length="0.3981271315755335" radius="0.6282750377540588"/>
			</geometry>
		</collision>
		<inertial>
			<mass value="0.49370924243067194"/>
			<inertia ixx="0.03" iyy="0.03" izz="0.03" ixy="0" ixz="0" iyx="0"/>
		</inertial>
	</link>
	<link name="667">
		<visual>
			<geometry>
				<cylinder length="1.9998" radius="0.9247680377079103"/>
			</geometry>
		</visual>
		<collision>
			<geometry>
				<cylinder length="1.9998" radius="0.9247680377079103"/>
			</geometry>
		</collision>
		<inertial>
			<mass value="5.3728171262644695"/>
			<inertia ixx="0.03" iyy="0.03" izz="0.03" ixy="0" ixz="0" iyx="0"/>
		</inertial>
	</link>
	<link name="568">
		<visual>
			<geometry>
				<cylinder length="0.3981271315755335" radius="0.6282750377540588"/>
			</geometry>
		</visual>
		<collision>
			<geometry>
				<cylinder length="0.3981271315755335" radius="0.6282750377540588"/>
			</geometry>
		</collision>
		<inertial>
			<mass value="0.49370924243067194"/>
			<inertia ixx="0.03" iyy="0.03" izz="0.03" ixy="0" ixz="0" iyx="0"/>
		</inertial>
	</link>
	<link name="669">
		<visual>
			<geometry>
				<cylinder length="1.9998" radius="0.9247680377079103"/>
			</geometry>
		</visual>
		<collision>
			<geometry>
				<cylinder length="1.9998" radius="0.9247680377079103"/>
			</geometry>
		</collision>
		<inertial>
			<mass value="5.3728171262644695"/>
			<inertia ixx="0.03" iyy="0.03" izz="0.03" ixy="0" ixz="0" iyx="0"/>
		</inertial>
	</link>
	<link name="370">
		<visual>
			<geometry>
				<cylinder length="1.7248786681420325" radius="0.921018508619313"/>
			</geometry>
		</visual>
		<collision>
			<geometry>
				<cylinder length="1.7248786681420325" radius="0.921018508619313"/>
			</geometry>
		</collision>
		<inertial>
			<mass value="4.596689190374097"/>
			<inertia ixx="0.03" iyy="0.03" izz="0.03" ixy="0" ixz="0" iyx="0"/>
		</inertial>
	</link>
	<link name="471">
		<visual>
			<geometry>
				<cylinder length="1.9998" radius="0.9247680377079103"/>
			</geometry>
		</visual>
		<collision>
			<geometry>
				<cylinder length="1.9998" radius="0.9247680377079103"/>
			</geometry>
		</collision>
		<inertial>
			<mass value="5.3728171262644695"/>
			<inertia ixx="0.03" iyy="0.03" izz="0.03" ixy="0" ixz="0" iyx="0"/>
		</inertial>
	</link>
	<link name="572">
		<visual>
			<geometry>
				<cylinder length="0.3981271315755335" radius="0.6282750377540588"/>
			</geometry>
		</visual>
		<collision>
			<geometry>
				<cylinder length="0.3981271315755335" radius="0.6282750377540588"/>
			</geometry>
		</collision>
		<inertial>
			<mass value="0.49370924243067194"/>
			<inertia ixx="0.03" iyy="0.03" izz="0.03" ixy="0" ixz="0" iyx="0"/>
		</inertial>
	</link>
	<link name="673">
		<visual>
			<geometry>
				<cylinder length="1.9998" radius="0.9247680377079103"/>
			</geometry>
		</visual>
		<collision>
			<geometry>
				<cylinder length="1.9998" radius="0.9247680377079103"/>
			</geometry>
		</collision>
		<inertial>
			<mass value="5.3728171262644695"/>
			<inertia ixx="0.03" iyy="0.03" izz="0.03" ixy="0" ixz="0" iyx="0"/>
		</inertial>
	</link>
	<link name="574">
		<visual>
			<geometry>
				<cylinder length="0.3981271315755335" radius="0.6282750377540588"/>
			</geometry>
		</visual>
		<collision>
			<geometry>
				<cylinder length="0.3981271315755335" radius="0.6282750377540588"/>
			</geometry>
		</collision>
		<inertial>
			<mass value="0.49370924243067194"/>
			<inertia ixx="0.03" iyy="0.03" izz="0.03" ixy="0" ixz="0" iyx="0"/>
		</inertial>
	</link>
	<link name="675">
		<visual>
			<geometry>
				<cylinder length="1.9998" radius="0.9247680377079103"/>
			</geometry>
		</visual>
		<collision>
			<geometry>
				<cylinder length="1.9998" radius="0.9247680377079103"/>
			</geometry>
		</collision>
		<inertial>
			<mass value="5.3728171262644695"/>
			<inertia ixx="0.03" iyy="0.03" izz="0.03" ixy="0" ixz="0" iyx="0"/>
		</inertial>
	</link>
	<link name="576">
		<visual>
			<geometry>
				<cylinder length="0.3981271315755335" radius="0.6282750377540588"/>
			</geometry>
		</visual>
		<collision>
			<geometry>
				<cylinder length="0.3981271315755335" radius="0.6282750377540588"/>
			</geometry>
		</collision>
		<inertial>
			<mass value="0.49370924243067194"/>
			<inertia ixx="0.03" iyy="0.03" izz="0.03" ixy="0" ixz="0" iyx="0"/>
		</inertial>
	</link>
	<link name="677">
		<visual>
			<geometry>
				<cylinder length="1.9998" radius="0.9247680377079103"/>
			</geometry>
		</visual>
		<collision>
			<geometry>
				<cylinder length="1.9998" radius="0.9247680377079103"/>
			</geometry>
		</collision>
		<inertial>
			<mass value="5.3728171262644695"/>
			<inertia ixx="0.03" iyy="0.03" izz="0.03" ixy="0" ixz="0" iyx="0"/>
		</inertial>
	</link>
	<link name="278">
		<visual>
			<geometry>
				<cylinder length="0.3511852875271282" radius="0.9999"/>
			</geometry>
		</visual>
		<collision>
			<geometry>
				<cylinder length="0.3511852875271282" radius="0.9999"/>
			</geometry>
		</collision>
		<inertial>
			<mass value="1.1030604741529875"/>
			<inertia ixx="0.03" iyy="0.03" izz="0.03" ixy="0" ixz="0" iyx="0"/>
		</inertial>
	</link>
	<link name="379">
		<visual>
			<geometry>
				<cylinder length="1.7248786681420325" radius="0.921018508619313"/>
			</geometry>
		</visual>
		<collision>
			<geometry>
				<cylinder length="1.7248786681420325" radius="0.921018508619313"/>
			</geometry>
		</collision>
		<inertial>
			<mass value="4.596689190374097"/>
			<inertia ixx="0.03" iyy="0.03" izz="0.03" ixy="0" ixz="0" iyx="0"/>
		</inertial>
	</link>
	<link name="480">
		<visual>
			<geometry>
				<cylinder length="1.9998" radius="0.9247680377079103"/>
			</geometry>
		</visual>
		<collision>
			<geometry>
				<cylinder length="1.9998" radius="0.9247680377079103"/>
			</geometry>
		</collision>
		<inertial>
			<mass value="5.3728171262644695"/>
			<inertia ixx="0.03" iyy="0.03" izz="0.03" ixy="0" ixz="0" iyx="0"/>
		</inertial>
	</link>
	<link name="581">
		<visual>
			<geometry>
				<cylinder length="0.3981271315755335" radius="0.6282750377540588"/>
			</geometry>
		</visual>
		<collision>
			<geometry>
				<cylinder length="0.3981271315755335" radius="0.6282750377540588"/>
			</geometry>
		</collision>
		<inertial>
			<mass value="0.49370924243067194"/>
			<inertia ixx="0.03" iyy="0.03" izz="0.03" ixy="0" ixz="0" iyx="0"/>
		</inertial>
	</link>
	<link name="682">
		<visual>
			<geometry>
				<cylinder length="1.9998" radius="0.9247680377079103"/>
			</geometry>
		</visual>
		<collision>
			<geometry>
				<cylinder length="1.9998" radius="0.9247680377079103"/>
			</geometry>
		</collision>
		<inertial>
			<mass value="5.3728171262644695"/>
			<inertia ixx="0.03" iyy="0.03" izz="0.03" ixy="0" ixz="0" iyx="0"/>
		</inertial>
	</link>
	<link name="583">
		<visual>
			<geometry>
				<cylinder length="0.3981271315755335" radius="0.6282750377540588"/>
			</geometry>
		</visual>
		<collision>
			<geometry>
				<cylinder length="0.3981271315755335" radius="0.6282750377540588"/>
			</geometry>
		</collision>
		<inertial>
			<mass value="0.49370924243067194"/>
			<inertia ixx="0.03" iyy="0.03" izz="0.03" ixy="0" ixz="0" iyx="0"/>
		</inertial>
	</link>
	<link name="684">
		<visual>
			<geometry>
				<cylinder length="1.9998" radius="0.9247680377079103"/>
			</geometry>
		</visual>
		<collision>
			<geometry>
				<cylinder length="1.9998" radius="0.9247680377079103"/>
			</geometry>
		</collision>
		<inertial>
			<mass value="5.3728171262644695"/>
			<inertia ixx="0.03" iyy="0.03" izz="0.03" ixy="0" ixz="0" iyx="0"/>
		</inertial>
	</link>
	<link name="585">
		<visual>
			<geometry>
				<cylinder length="0.3981271315755335" radius="0.6282750377540588"/>
			</geometry>
		</visual>
		<collision>
			<geometry>
				<cylinder length="0.3981271315755335" radius="0.6282750377540588"/>
			</geometry>
		</collision>
		<inertial>
			<mass value="0.49370924243067194"/>
			<inertia ixx="0.03" iyy="0.03" izz="0.03" ixy="0" ixz="0" iyx="0"/>
		</inertial>
	</link>
	<link name="686">
		<visual>
			<geometry>
				<cylinder length="1.9998" radius="0.9247680377079103"/>
			</geometry>
		</visual>
		<collision>
			<geometry>
				<cylinder length="1.9998" radius="0.9247680377079103"/>
			</geometry>
		</collision>
		<inertial>
			<mass value="5.3728171262644695"/>
			<inertia ixx="0.03" iyy="0.03" izz="0.03" ixy="0" ixz="0" iyx="0"/>
		</inertial>
	</link>
	<link name="387">
		<visual>
			<geometry>
				<cylinder length="1.7248786681420325" radius="0.921018508619313"/>
			</geometry>
		</visual>
		<collision>
			<geometry>
				<cylinder length="1.7248786681420325" radius="0.921018508619313"/>
			</geometry>
		</collision>
		<inertial>
			<mass value="4.596689190374097"/>
			<inertia ixx="0.03" iyy="0.03" izz="0.03" ixy="0" ixz="0" iyx="0"/>
		</inertial>
	</link>
	<link name="488">
		<visual>
			<geometry>
				<cylinder length="1.9998" radius="0.9247680377079103"/>
			</geometry>
		</visual>
		<collision>
			<geometry>
				<cylinder length="1.9998" radius="0.9247680377079103"/>
			</geometry>
		</collision>
		<inertial>
			<mass value="5.3728171262644695"/>
			<inertia ixx="0.03" iyy="0.03" izz="0.03" ixy="0" ixz="0" iyx="0"/>
		</inertial>
	</link>
	<link name="589">
		<visual>
			<geometry>
				<cylinder length="0.3981271315755335" radius="0.6282750377540588"/>
			</geometry>
		</visual>
		<collision>
			<geometry>
				<cylinder length="0.3981271315755335" radius="0.6282750377540588"/>
			</geometry>
		</collision>
		<inertial>
			<mass value="0.49370924243067194"/>
			<inertia ixx="0.03" iyy="0.03" izz="0.03" ixy="0" ixz="0" iyx="0"/>
		</inertial>
	</link>
	<link name="690">
		<visual>
			<geometry>
				<cylinder length="1.9998" radius="0.9247680377079103"/>
			</geometry>
		</visual>
		<collision>
			<geometry>
				<cylinder length="1.9998" radius="0.9247680377079103"/>
			</geometry>
		</collision>
		<inertial>
			<mass value="5.3728171262644695"/>
			<inertia ixx="0.03" iyy="0.03" izz="0.03" ixy="0" ixz="0" iyx="0"/>
		</inertial>
	</link>
	<link name="591">
		<visual>
			<geometry>
				<cylinder length="0.3981271315755335" radius="0.6282750377540588"/>
			</geometry>
		</visual>
		<collision>
			<geometry>
				<cylinder length="0.3981271315755335" radius="0.6282750377540588"/>
			</geometry>
		</collision>
		<inertial>
			<mass value="0.49370924243067194"/>
			<inertia ixx="0.03" iyy="0.03" izz="0.03" ixy="0" ixz="0" iyx="0"/>
		</inertial>
	</link>
	<link name="692">
		<visual>
			<geometry>
				<cylinder length="1.9998" radius="0.9247680377079103"/>
			</geometry>
		</visual>
		<collision>
			<geometry>
				<cylinder length="1.9998" radius="0.9247680377079103"/>
			</geometry>
		</collision>
		<inertial>
			<mass value="5.3728171262644695"/>
			<inertia ixx="0.03" iyy="0.03" izz="0.03" ixy="0" ixz="0" iyx="0"/>
		</inertial>
	</link>
	<link name="593">
		<visual>
			<geometry>
				<cylinder length="0.3981271315755335" radius="0.6282750377540588"/>
			</geometry>
		</visual>
		<collision>
			<geometry>
				<cylinder length="0.3981271315755335" radius="0.6282750377540588"/>
			</geometry>
		</collision>
		<inertial>
			<mass value="0.49370924243067194"/>
			<inertia ixx="0.03" iyy="0.03" izz="0.03" ixy="0" ixz="0" iyx="0"/>
		</inertial>
	</link>
	<link name="694">
		<visual>
			<geometry>
				<cylinder length="1.9998" radius="0.9247680377079103"/>
			</geometry>
		</visual>
		<collision>
			<geometry>
				<cylinder length="1.9998" radius="0.9247680377079103"/>
			</geometry>
		</collision>
		<inertial>
			<mass value="5.3728171262644695"/>
			<inertia ixx="0.03" iyy="0.03" izz="0.03" ixy="0" ixz="0" iyx="0"/>
		</inertial>
	</link>
	<link name="395">
		<visual>
			<geometry>
				<cylinder length="1.7248786681420325" radius="0.921018508619313"/>
			</geometry>
		</visual>
		<collision>
			<geometry>
				<cylinder length="1.7248786681420325" radius="0.921018508619313"/>
			</geometry>
		</collision>
		<inertial>
			<mass value="4.596689190374097"/>
			<inertia ixx="0.03" iyy="0.03" izz="0.03" ixy="0" ixz="0" iyx="0"/>
		</inertial>
	</link>
	<link name="496">
		<visual>
			<geometry>
				<cylinder length="1.9998" radius="0.9247680377079103"/>
			</geometry>
		</visual>
		<collision>
			<geometry>
				<cylinder length="1.9998" radius="0.9247680377079103"/>
			</geometry>
		</collision>
		<inertial>
			<mass value="5.3728171262644695"/>
			<inertia ixx="0.03" iyy="0.03" izz="0.03" ixy="0" ixz="0" iyx="0"/>
		</inertial>
	</link>
	<link name="597">
		<visual>
			<geometry>
				<cylinder length="0.3981271315755335" radius="0.6282750377540588"/>
			</geometry>
		</visual>
		<collision>
			<geometry>
				<cylinder length="0.3981271315755335" radius="0.6282750377540588"/>
			</geometry>
		</collision>
		<inertial>
			<mass value="0.49370924243067194"/>
			<inertia ixx="0.03" iyy="0.03" izz="0.03" ixy="0" ixz="0" iyx="0"/>
		</inertial>
	</link>
	<link name="698">
		<visual>
			<geometry>
				<cylinder length="1.9998" radius="0.9247680377079103"/>
			</geometry>
		</visual>
		<collision>
			<geometry>
				<cylinder length="1.9998" radius="0.9247680377079103"/>
			</geometry>
		</collision>
		<inertial>
			<mass value="5.3728171262644695"/>
			<inertia ixx="0.03" iyy="0.03" izz="0.03" ixy="0" ixz="0" iyx="0"/>
		</inertial>
	</link>
	<link name="599">
		<visual>
			<geometry>
				<cylinder length="0.3981271315755335" radius="0.6282750377540588"/>
			</geometry>
		</visual>
		<collision>
			<geometry>
				<cylinder length="0.3981271315755335" radius="0.6282750377540588"/>
			</geometry>
		</collision>
		<inertial>
			<mass value="0.49370924243067194"/>
			<inertia ixx="0.03" iyy="0.03" izz="0.03" ixy="0" ixz="0" iyx="0"/>
		</inertial>
	</link>
	<link name="6100">
		<visual>
			<geometry>
				<cylinder length="1.9998" radius="0.9247680377079103"/>
			</geometry>
		</visual>
		<collision>
			<geometry>
				<cylinder length="1.9998" radius="0.9247680377079103"/>
			</geometry>
		</collision>
		<inertial>
			<mass value="5.3728171262644695"/>
			<inertia ixx="0.03" iyy="0.03" izz="0.03" ixy="0" ixz="0" iyx="0"/>
		</inertial>
	</link>
	<link name="5101">
		<visual>
			<geometry>
				<cylinder length="0.3981271315755335" radius="0.6282750377540588"/>
			</geometry>
		</visual>
		<collision>
			<geometry>
				<cylinder length="0.3981271315755335" radius="0.6282750377540588"/>
			</geometry>
		</collision>
		<inertial>
			<mass value="0.49370924243067194"/>
			<inertia ixx="0.03" iyy="0.03" izz="0.03" ixy="0" ixz="0" iyx="0"/>
		</inertial>
	</link>
	<link name="6102">
		<visual>
			<geometry>
				<cylinder length="1.9998" radius="0.9247680377079103"/>
			</geometry>
		</visual>
		<collision>
			<geometry>
				<cylinder length="1.9998" radius="0.9247680377079103"/>
			</geometry>
		</collision>
		<inertial>
			<mass value="5.3728171262644695"/>
			<inertia ixx="0.03" iyy="0.03" izz="0.03" ixy="0" ixz="0" iyx="0"/>
		</inertial>
	</link>
	<link name="1103">
		<visual>
			<geometry>
				<cylinder length="0.46760508841096937" radius="0.7927918971962551"/>
			</geometry>
		</visual>
		<collision>
			<geometry>
				<cylinder length="0.46760508841096937" radius="0.7927918971962551"/>
			</geometry>
		</collision>
		<inertial>
			<mass value="0.9233099306693617"/>
			<inertia ixx="0.03" iyy="0.03" izz="0.03" ixy="0" ixz="0" iyx="0"/>
		</inertial>
	</link>
	<link name="2104">
		<visual>
			<geometry>
				<cylinder length="0.3511852875271282" radius="0.9999"/>
			</geometry>
		</visual>
		<collision>
			<geometry>
				<cylinder length="0.3511852875271282" radius="0.9999"/>
			</geometry>
		</collision>
		<inertial>
			<mass value="1.1030604741529875"/>
			<inertia ixx="0.03" iyy="0.03" izz="0.03" ixy="0" ixz="0" iyx="0"/>
		</inertial>
	</link>
	<link name="3105">
		<visual>
			<geometry>
				<cylinder length="1.7248786681420325" radius="0.921018508619313"/>
			</geometry>
		</visual>
		<collision>
			<geometry>
				<cylinder length="1.7248786681420325" radius="0.921018508619313"/>
			</geometry>
		</collision>
		<inertial>
			<mass value="4.596689190374097"/>
			<inertia ixx="0.03" iyy="0.03" izz="0.03" ixy="0" ixz="0" iyx="0"/>
		</inertial>
	</link>
	<link name="4106">
		<visual>
			<geometry>
				<cylinder length="1.9998" radius="0.9247680377079103"/>
			</geometry>
		</visual>
		<collision>
			<geometry>
				<cylinder length="1.9998" radius="0.9247680377079103"/>
			</geometry>
		</collision>
		<inertial>
			<mass value="5.3728171262644695"/>
			<inertia ixx="0.03" iyy="0.03" izz="0.03" ixy="0" ixz="0" iyx="0"/>
		</inertial>
	</link>
	<link name="5107">
		<visual>
			<geometry>
				<cylinder length="0.3981271315755335" radius="0.6282750377540588"/>
			</geometry>
		</visual>
		<collision>
			<geometry>
				<cylinder length="0.3981271315755335" radius="0.6282750377540588"/>
			</geometry>
		</collision>
		<inertial>
			<mass value="0.49370924243067194"/>
			<inertia ixx="0.03" iyy="0.03" izz="0.03" ixy="0" ixz="0" iyx="0"/>
		</inertial>
	</link>
	<link name="6108">
		<visual>
			<geometry>
				<cylinder length="1.9998" radius="0.9247680377079103"/>
			</geometry>
		</visual>
		<collision>
			<geometry>
				<cylinder length="1.9998" radius="0.9247680377079103"/>
			</geometry>
		</collision>
		<inertial>
			<mass value="5.3728171262644695"/>
			<inertia ixx="0.03" iyy="0.03" izz="0.03" ixy="0" ixz="0" iyx="0"/>
		</inertial>
	</link>
	<link name="5109">
		<visual>
			<geometry>
				<cylinder length="0.3981271315755335" radius="0.6282750377540588"/>
			</geometry>
		</visual>
		<collision>
			<geometry>
				<cylinder length="0.3981271315755335" radius="0.6282750377540588"/>
			</geometry>
		</collision>
		<inertial>
			<mass value="0.49370924243067194"/>
			<inertia ixx="0.03" iyy="0.03" izz="0.03" ixy="0" ixz="0" iyx="0"/>
		</inertial>
	</link>
	<link name="6110">
		<visual>
			<geometry>
				<cylinder length="1.9998" radius="0.9247680377079103"/>
			</geometry>
		</visual>
		<collision>
			<geometry>
				<cylinder length="1.9998" radius="0.9247680377079103"/>
			</geometry>
		</collision>
		<inertial>
			<mass value="5.3728171262644695"/>
			<inertia ixx="0.03" iyy="0.03" izz="0.03" ixy="0" ixz="0" iyx="0"/>
		</inertial>
	</link>
	<link name="5111">
		<visual>
			<geometry>
				<cylinder length="0.3981271315755335" radius="0.6282750377540588"/>
			</geometry>
		</visual>
		<collision>
			<geometry>
				<cylinder length="0.3981271315755335" radius="0.6282750377540588"/>
			</geometry>
		</collision>
		<inertial>
			<mass value="0.49370924243067194"/>
			<inertia ixx="0.03" iyy="0.03" izz="0.03" ixy="0" ixz="0" iyx="0"/>
		</inertial>
	</link>
	<link name="6112">
		<visual>
			<geometry>
				<cylinder length="1.9998" radius="0.9247680377079103"/>
			</geometry>
		</visual>
		<collision>
			<geometry>
				<cylinder length="1.9998" radius="0.9247680377079103"/>
			</geometry>
		</collision>
		<inertial>
			<mass value="5.3728171262644695"/>
			<inertia ixx="0.03" iyy="0.03" izz="0.03" ixy="0" ixz="0" iyx="0"/>
		</inertial>
	</link>
	<link name="3113">
		<visual>
			<geometry>
				<cylinder length="1.7248786681420325" radius="0.921018508619313"/>
			</geometry>
		</visual>
		<collision>
			<geometry>
				<cylinder length="1.7248786681420325" radius="0.921018508619313"/>
			</geometry>
		</collision>
		<inertial>
			<mass value="4.596689190374097"/>
			<inertia ixx="0.03" iyy="0.03" izz="0.03" ixy="0" ixz="0" iyx="0"/>
		</inertial>
	</link>
	<link name="4114">
		<visual>
			<geometry>
				<cylinder length="1.9998" radius="0.9247680377079103"/>
			</geometry>
		</visual>
		<collision>
			<geometry>
				<cylinder length="1.9998" radius="0.9247680377079103"/>
			</geometry>
		</collision>
		<inertial>
			<mass value="5.3728171262644695"/>
			<inertia ixx="0.03" iyy="0.03" izz="0.03" ixy="0" ixz="0" iyx="0"/>
		</inertial>
	</link>
	<link name="5115">
		<visual>
			<geometry>
				<cylinder length="0.3981271315755335" radius="0.6282750377540588"/>
			</geometry>
		</visual>
		<collision>
			<geometry>
				<cylinder length="0.3981271315755335" radius="0.6282750377540588"/>
			</geometry>
		</collision>
		<inertial>
			<mass value="0.49370924243067194"/>
			<inertia ixx="0.03" iyy="0.03" izz="0.03" ixy="0" ixz="0" iyx="0"/>
		</inertial>
	</link>
	<link name="6116">
		<visual>
			<geometry>
				<cylinder length="1.9998" radius="0.9247680377079103"/>
			</geometry>
		</visual>
		<collision>
			<geometry>
				<cylinder length="1.9998" radius="0.9247680377079103"/>
			</geometry>
		</collision>
		<inertial>
			<mass value="5.3728171262644695"/>
			<inertia ixx="0.03" iyy="0.03" izz="0.03" ixy="0" ixz="0" iyx="0"/>
		</inertial>
	</link>
	<link name="5117">
		<visual>
			<geometry>
				<cylinder length="0.3981271315755335" radius="0.6282750377540588"/>
			</geometry>
		</visual>
		<collision>
			<geometry>
				<cylinder length="0.3981271315755335" radius="0.6282750377540588"/>
			</geometry>
		</collision>
		<inertial>
			<mass value="0.49370924243067194"/>
			<inertia ixx="0.03" iyy="0.03" izz="0.03" ixy="0" ixz="0" iyx="0"/>
		</inertial>
	</link>
	<link name="6118">
		<visual>
			<geometry>
				<cylinder length="1.9998" radius="0.9247680377079103"/>
			</geometry>
		</visual>
		<collision>
			<geometry>
				<cylinder length="1.9998" radius="0.9247680377079103"/>
			</geometry>
		</collision>
		<inertial>
			<mass value="5.3728171262644695"/>
			<inertia ixx="0.03" iyy="0.03" izz="0.03" ixy="0" ixz="0" iyx="0"/>
		</inertial>
	</link>
	<link name="5119">
		<visual>
			<geometry>
				<cylinder length="0.3981271315755335" radius="0.6282750377540588"/>
			</geometry>
		</visual>
		<collision>
			<geometry>
				<cylinder length="0.3981271315755335" radius="0.6282750377540588"/>
			</geometry>
		</collision>
		<inertial>
			<mass value="0.49370924243067194"/>
			<inertia ixx="0.03" iyy="0.03" izz="0.03" ixy="0" ixz="0" iyx="0"/>
		</inertial>
	</link>
	<link name="6120">
		<visual>
			<geometry>
				<cylinder length="1.9998" radius="0.9247680377079103"/>
			</geometry>
		</visual>
		<collision>
			<geometry>
				<cylinder length="1.9998" radius="0.9247680377079103"/>
			</geometry>
		</collision>
		<inertial>
			<mass value="5.3728171262644695"/>
			<inertia ixx="0.03" iyy="0.03" izz="0.03" ixy="0" ixz="0" iyx="0"/>
		</inertial>
	</link>
	<link name="3121">
		<visual>
			<geometry>
				<cylinder length="1.7248786681420325" radius="0.921018508619313"/>
			</geometry>
		</visual>
		<collision>
			<geometry>
				<cylinder length="1.7248786681420325" radius="0.921018508619313"/>
			</geometry>
		</collision>
		<inertial>
			<mass value="4.596689190374097"/>
			<inertia ixx="0.03" iyy="0.03" izz="0.03" ixy="0" ixz="0" iyx="0"/>
		</inertial>
	</link>
	<link name="4122">
		<visual>
			<geometry>
				<cylinder length="1.9998" radius="0.9247680377079103"/>
			</geometry>
		</visual>
		<collision>
			<geometry>
				<cylinder length="1.9998" radius="0.9247680377079103"/>
			</geometry>
		</collision>
		<inertial>
			<mass value="5.3728171262644695"/>
			<inertia ixx="0.03" iyy="0.03" izz="0.03" ixy="0" ixz="0" iyx="0"/>
		</inertial>
	</link>
	<link name="5123">
		<visual>
			<geometry>
				<cylinder length="0.3981271315755335" radius="0.6282750377540588"/>
			</geometry>
		</visual>
		<collision>
			<geometry>
				<cylinder length="0.3981271315755335" radius="0.6282750377540588"/>
			</geometry>
		</collision>
		<inertial>
			<mass value="0.49370924243067194"/>
			<inertia ixx="0.03" iyy="0.03" izz="0.03" ixy="0" ixz="0" iyx="0"/>
		</inertial>
	</link>
	<link name="6124">
		<visual>
			<geometry>
				<cylinder length="1.9998" radius="0.9247680377079103"/>
			</geometry>
		</visual>
		<collision>
			<geometry>
				<cylinder length="1.9998" radius="0.9247680377079103"/>
			</geometry>
		</collision>
		<inertial>
			<mass value="5.3728171262644695"/>
			<inertia ixx="0.03" iyy="0.03" izz="0.03" ixy="0" ixz="0" iyx="0"/>
		</inertial>
	</link>
	<link name="5125">
		<visual>
			<geometry>
				<cylinder length="0.3981271315755335" radius="0.6282750377540588"/>
			</geometry>
		</visual>
		<collision>
			<geometry>
				<cylinder length="0.3981271315755335" radius="0.6282750377540588"/>
			</geometry>
		</collision>
		<inertial>
			<mass value="0.49370924243067194"/>
			<inertia ixx="0.03" iyy="0.03" izz="0.03" ixy="0" ixz="0" iyx="0"/>
		</inertial>
	</link>
	<link name="6126">
		<visual>
			<geometry>
				<cylinder length="1.9998" radius="0.9247680377079103"/>
			</geometry>
		</visual>
		<collision>
			<geometry>
				<cylinder length="1.9998" radius="0.9247680377079103"/>
			</geometry>
		</collision>
		<inertial>
			<mass value="5.3728171262644695"/>
			<inertia ixx="0.03" iyy="0.03" izz="0.03" ixy="0" ixz="0" iyx="0"/>
		</inertial>
	</link>
	<link name="5127">
		<visual>
			<geometry>
				<cylinder length="0.3981271315755335" radius="0.6282750377540588"/>
			</geometry>
		</visual>
		<collision>
			<geometry>
				<cylinder length="0.3981271315755335" radius="0.6282750377540588"/>
			</geometry>
		</collision>
		<inertial>
			<mass value="0.49370924243067194"/>
			<inertia ixx="0.03" iyy="0.03" izz="0.03" ixy="0" ixz="0" iyx="0"/>
		</inertial>
	</link>
	<link name="6128">
		<visual>
			<geometry>
				<cylinder length="1.9998" radius="0.9247680377079103"/>
			</geometry>
		</visual>
		<collision>
			<geometry>
				<cylinder length="1.9998" radius="0.9247680377079103"/>
			</geometry>
		</collision>
		<inertial>
			<mass value="5.3728171262644695"/>
			<inertia ixx="0.03" iyy="0.03" izz="0.03" ixy="0" ixz="0" iyx="0"/>
		</inertial>
	</link>
	<link name="2129">
		<visual>
			<geometry>
				<cylinder length="0.3511852875271282" radius="0.9999"/>
			</geometry>
		</visual>
		<collision>
			<geometry>
				<cylinder length="0.3511852875271282" radius="0.9999"/>
			</geometry>
		</collision>
		<inertial>
			<mass value="1.1030604741529875"/>
			<inertia ixx="0.03" iyy="0.03" izz="0.03" ixy="0" ixz="0" iyx="0"/>
		</inertial>
	</link>
	<link name="3130">
		<visual>
			<geometry>
				<cylinder length="1.7248786681420325" radius="0.921018508619313"/>
			</geometry>
		</visual>
		<collision>
			<geometry>
				<cylinder length="1.7248786681420325" radius="0.921018508619313"/>
			</geometry>
		</collision>
		<inertial>
			<mass value="4.596689190374097"/>
			<inertia ixx="0.03" iyy="0.03" izz="0.03" ixy="0" ixz="0" iyx="0"/>
		</inertial>
	</link>
	<link name="4131">
		<visual>
			<geometry>
				<cylinder length="1.9998" radius="0.9247680377079103"/>
			</geometry>
		</visual>
		<collision>
			<geometry>
				<cylinder length="1.9998" radius="0.9247680377079103"/>
			</geometry>
		</collision>
		<inertial>
			<mass value="5.3728171262644695"/>
			<inertia ixx="0.03" iyy="0.03" izz="0.03" ixy="0" ixz="0" iyx="0"/>
		</inertial>
	</link>
	<link name="5132">
		<visual>
			<geometry>
				<cylinder length="0.3981271315755335" radius="0.6282750377540588"/>
			</geometry>
		</visual>
		<collision>
			<geometry>
				<cylinder length="0.3981271315755335" radius="0.6282750377540588"/>
			</geometry>
		</collision>
		<inertial>
			<mass value="0.49370924243067194"/>
			<inertia ixx="0.03" iyy="0.03" izz="0.03" ixy="0" ixz="0" iyx="0"/>
		</inertial>
	</link>
	<link name="6133">
		<visual>
			<geometry>
				<cylinder length="1.9998" radius="0.9247680377079103"/>
			</geometry>
		</visual>
		<collision>
			<geometry>
				<cylinder length="1.9998" radius="0.9247680377079103"/>
			</geometry>
		</collision>
		<inertial>
			<mass value="5.3728171262644695"/>
			<inertia ixx="0.03" iyy="0.03" izz="0.03" ixy="0" ixz="0" iyx="0"/>
		</inertial>
	</link>
	<link name="5134">
		<visual>
			<geometry>
				<cylinder length="0.3981271315755335" radius="0.6282750377540588"/>
			</geometry>
		</visual>
		<collision>
			<geometry>
				<cylinder length="0.3981271315755335" radius="0.6282750377540588"/>
			</geometry>
		</collision>
		<inertial>
			<mass value="0.49370924243067194"/>
			<inertia ixx="0.03" iyy="0.03" izz="0.03" ixy="0" ixz="0" iyx="0"/>
		</inertial>
	</link>
	<link name="6135">
		<visual>
			<geometry>
				<cylinder length="1.9998" radius="0.9247680377079103"/>
			</geometry>
		</visual>
		<collision>
			<geometry>
				<cylinder length="1.9998" radius="0.9247680377079103"/>
			</geometry>
		</collision>
		<inertial>
			<mass value="5.3728171262644695"/>
			<inertia ixx="0.03" iyy="0.03" izz="0.03" ixy="0" ixz="0" iyx="0"/>
		</inertial>
	</link>
	<link name="5136">
		<visual>
			<geometry>
				<cylinder length="0.3981271315755335" radius="0.6282750377540588"/>
			</geometry>
		</visual>
		<collision>
			<geometry>
				<cylinder length="0.3981271315755335" radius="0.6282750377540588"/>
			</geometry>
		</collision>
		<inertial>
			<mass value="0.49370924243067194"/>
			<inertia ixx="0.03" iyy="0.03" izz="0.03" ixy="0" ixz="0" iyx="0"/>
		</inertial>
	</link>
	<link name="6137">
		<visual>
			<geometry>
				<cylinder length="1.9998" radius="0.9247680377079103"/>
			</geometry>
		</visual>
		<collision>
			<geometry>
				<cylinder length="1.9998" radius="0.9247680377079103"/>
			</geometry>
		</collision>
		<inertial>
			<mass value="5.3728171262644695"/>
			<inertia ixx="0.03" iyy="0.03" izz="0.03" ixy="0" ixz="0" iyx="0"/>
		</inertial>
	</link>
	<link name="3138">
		<visual>
			<geometry>
				<cylinder length="1.7248786681420325" radius="0.921018508619313"/>
			</geometry>
		</visual>
		<collision>
			<geometry>
				<cylinder length="1.7248786681420325" radius="0.921018508619313"/>
			</geometry>
		</collision>
		<inertial>
			<mass value="4.596689190374097"/>
			<inertia ixx="0.03" iyy="0.03" izz="0.03" ixy="0" ixz="0" iyx="0"/>
		</inertial>
	</link>
	<link name="4139">
		<visual>
			<geometry>
				<cylinder length="1.9998" radius="0.9247680377079103"/>
			</geometry>
		</visual>
		<collision>
			<geometry>
				<cylinder length="1.9998" radius="0.9247680377079103"/>
			</geometry>
		</collision>
		<inertial>
			<mass value="5.3728171262644695"/>
			<inertia ixx="0.03" iyy="0.03" izz="0.03" ixy="0" ixz="0" iyx="0"/>
		</inertial>
	</link>
	<link name="5140">
		<visual>
			<geometry>
				<cylinder length="0.3981271315755335" radius="0.6282750377540588"/>
			</geometry>
		</visual>
		<collision>
			<geometry>
				<cylinder length="0.3981271315755335" radius="0.6282750377540588"/>
			</geometry>
		</collision>
		<inertial>
			<mass value="0.49370924243067194"/>
			<inertia ixx="0.03" iyy="0.03" izz="0.03" ixy="0" ixz="0" iyx="0"/>
		</inertial>
	</link>
	<link name="6141">
		<visual>
			<geometry>
				<cylinder length="1.9998" radius="0.9247680377079103"/>
			</geometry>
		</visual>
		<collision>
			<geometry>
				<cylinder length="1.9998" radius="0.9247680377079103"/>
			</geometry>
		</collision>
		<inertial>
			<mass value="5.3728171262644695"/>
			<inertia ixx="0.03" iyy="0.03" izz="0.03" ixy="0" ixz="0" iyx="0"/>
		</inertial>
	</link>
	<link name="5142">
		<visual>
			<geometry>
				<cylinder length="0.3981271315755335" radius="0.6282750377540588"/>
			</geometry>
		</visual>
		<collision>
			<geometry>
				<cylinder length="0.3981271315755335" radius="0.6282750377540588"/>
			</geometry>
		</collision>
		<inertial>
			<mass value="0.49370924243067194"/>
			<inertia ixx="0.03" iyy="0.03" izz="0.03" ixy="0" ixz="0" iyx="0"/>
		</inertial>
	</link>
	<link name="6143">
		<visual>
			<geometry>
				<cylinder length="1.9998" radius="0.9247680377079103"/>
			</geometry>
		</visual>
		<collision>
			<geometry>
				<cylinder length="1.9998" radius="0.9247680377079103"/>
			</geometry>
		</collision>
		<inertial>
			<mass value="5.3728171262644695"/>
			<inertia ixx="0.03" iyy="0.03" izz="0.03" ixy="0" ixz="0" iyx="0"/>
		</inertial>
	</link>
	<link name="5144">
		<visual>
			<geometry>
				<cylinder length="0.3981271315755335" radius="0.6282750377540588"/>
			</geometry>
		</visual>
		<collision>
			<geometry>
				<cylinder length="0.3981271315755335" radius="0.6282750377540588"/>
			</geometry>
		</collision>
		<inertial>
			<mass value="0.49370924243067194"/>
			<inertia ixx="0.03" iyy="0.03" izz="0.03" ixy="0" ixz="0" iyx="0"/>
		</inertial>
	</link>
	<link name="6145">
		<visual>
			<geometry>
				<cylinder length="1.9998" radius="0.9247680377079103"/>
			</geometry>
		</visual>
		<collision>
			<geometry>
				<cylinder length="1.9998" radius="0.9247680377079103"/>
			</geometry>
		</collision>
		<inertial>
			<mass value="5.3728171262644695"/>
			<inertia ixx="0.03" iyy="0.03" izz="0.03" ixy="0" ixz="0" iyx="0"/>
		</inertial>
	</link>
	<link name="3146">
		<visual>
			<geometry>
				<cylinder length="1.7248786681420325" radius="0.921018508619313"/>
			</geometry>
		</visual>
		<collision>
			<geometry>
				<cylinder length="1.7248786681420325" radius="0.921018508619313"/>
			</geometry>
		</collision>
		<inertial>
			<mass value="4.596689190374097"/>
			<inertia ixx="0.03" iyy="0.03" izz="0.03" ixy="0" ixz="0" iyx="0"/>
		</inertial>
	</link>
	<link name="4147">
		<visual>
			<geometry>
				<cylinder length="1.9998" radius="0.9247680377079103"/>
			</geometry>
		</visual>
		<collision>
			<geometry>
				<cylinder length="1.9998" radius="0.9247680377079103"/>
			</geometry>
		</collision>
		<inertial>
			<mass value="5.3728171262644695"/>
			<inertia ixx="0.03" iyy="0.03" izz="0.03" ixy="0" ixz="0" iyx="0"/>
		</inertial>
	</link>
	<link name="5148">
		<visual>
			<geometry>
				<cylinder length="0.3981271315755335" radius="0.6282750377540588"/>
			</geometry>
		</visual>
		<collision>
			<geometry>
				<cylinder length="0.3981271315755335" radius="0.6282750377540588"/>
			</geometry>
		</collision>
		<inertial>
			<mass value="0.49370924243067194"/>
			<inertia ixx="0.03" iyy="0.03" izz="0.03" ixy="0" ixz="0" iyx="0"/>
		</inertial>
	</link>
	<link name="6149">
		<visual>
			<geometry>
				<cylinder length="1.9998" radius="0.9247680377079103"/>
			</geometry>
		</visual>
		<collision>
			<geometry>
				<cylinder length="1.9998" radius="0.9247680377079103"/>
			</geometry>
		</collision>
		<inertial>
			<mass value="5.3728171262644695"/>
			<inertia ixx="0.03" iyy="0.03" izz="0.03" ixy="0" ixz="0" iyx="0"/>
		</inertial>
	</link>
	<link name="5150">
		<visual>
			<geometry>
				<cylinder length="0.3981271315755335" radius="0.6282750377540588"/>
			</geometry>
		</visual>
		<collision>
			<geometry>
				<cylinder length="0.3981271315755335" radius="0.6282750377540588"/>
			</geometry>
		</collision>
		<inertial>
			<mass value="0.49370924243067194"/>
			<inertia ixx="0.03" iyy="0.03" izz="0.03" ixy="0" ixz="0" iyx="0"/>
		</inertial>
	</link>
	<link name="6151">
		<visual>
			<geometry>
				<cylinder length="1.9998" radius="0.9247680377079103"/>
			</geometry>
		</visual>
		<collision>
			<geometry>
				<cylinder length="1.9998" radius="0.9247680377079103"/>
			</geometry>
		</collision>
		<inertial>
			<mass value="5.3728171262644695"/>
			<inertia ixx="0.03" iyy="0.03" izz="0.03" ixy="0" ixz="0" iyx="0"/>
		</inertial>
	</link>
	<link name="5152">
		<visual>
			<geometry>
				<cylinder length="0.3981271315755335" radius="0.6282750377540588"/>
			</geometry>
		</visual>
		<collision>
			<geometry>
				<cylinder length="0.3981271315755335" radius="0.6282750377540588"/>
			</geometry>
		</collision>
		<inertial>
			<mass value="0.49370924243067194"/>
			<inertia ixx="0.03" iyy="0.03" izz="0.03" ixy="0" ixz="0" iyx="0"/>
		</inertial>
	</link>
	<link name="6153">
		<visual>
			<geometry>
				<cylinder length="1.9998" radius="0.9247680377079103"/>
			</geometry>
		</visual>
		<collision>
			<geometry>
				<cylinder length="1.9998" radius="0.9247680377079103"/>
			</geometry>
		</collision>
		<inertial>
			<mass value="5.3728171262644695"/>
			<inertia ixx="0.03" iyy="0.03" izz="0.03" ixy="0" ixz="0" iyx="0"/>
		</inertial>
	</link>
	<joint name="11_to_0" type="revolute">
		<parent link="0"/>
		<child link="11"/>
		<axis xyz="0 1 0"/>
		<limit effort="1" upper="-3.1415" lower="3.1415" velocity="1"/>
		<origin rpy="10.808392987238653 6.282556988648868 0.5422677742866492" xyz="0.8496673682276968 0.23520769677330514 0.326170469526187"/>
	</joint>
	<joint name="22_to_11" type="revolute">
		<parent link="11"/>
		<child link="22"/>
		<axis xyz="0 1 0"/>
		<limit effort="1" upper="-3.1415" lower="3.1415" velocity="1"/>
		<origin rpy="11.916016987748984 5.747039156528198 0.28559947335639824" xyz="0.4752396645251993 0.5727739914430996 0.9144225102689908"/>
	</joint>
	<joint name="33_to_22" type="revolute">
		<parent link="22"/>
		<child link="33"/>
		<axis xyz="0 0 1"/>
		<limit effort="1" upper="-3.1415" lower="3.1415" velocity="1"/>
		<origin rpy="2.0196063457226643 4.196372075190924 2.6166338695673788" xyz="0.5357034826864502 0.4667766319268153 0.20217506366350713"/>
	</joint>
	<joint name="44_to_33" type="revolute">
		<parent link="33"/>
		<child link="44"/>
		<axis xyz="0 1 0"/>
		<limit effort="1" upper="-3.1415" lower="3.1415" velocity="1"/>
		<origin rpy="2.728284631912176 4.267526873767507 6.190859567942483" xyz="0.8105301357078135 0.646351205990926 0.68710199183315"/>
	</joint>
	<joint name="55_to_44" type="revolute">
		<parent link="44"/>
		<child link="55"/>
		<axis xyz="0 1 0"/>
		<limit effort="1" upper="-3.1415" lower="3.1415" velocity="1"/>
		<origin rpy="6.042061451063851 5.494964011385597 1.7547235459826243" xyz="0.15581604867367727 0.4058499647541277 0.8068836205509428"/>
	</joint>
	<joint name="66_to_55" type="revolute">
		<parent link="55"/>
		<child link="66"/>
		<axis xyz="0 1 0"/>
		<limit effort="1" upper="-3.1415" lower="3.1415" velocity="1"/>
		<origin rpy="2.728284631912176 4.895845404485465 5.562541037224525" xyz="0.9105301357078135 0.646351205990926 0.68710199183315"/>
	</joint>
	<joint name="57_to_44" type="revolute">
		<parent link="44"/>
		<child link="57"/>
		<axis xyz="0 1 0"/>
		<limit effort="1" upper="-3.1415" lower="3.1415" velocity="1"/>
		<origin rpy="9.063092176595775 5.494964011385597 1.7547235459826243" xyz="0.15581604867367727 0.4058499647541277 0.8068836205509428"/>
	</joint>
	<joint name="68_to_57" type="revolute">
		<parent link="57"/>
		<child link="68"/>
		<axis xyz="0 1 0"/>
		<limit effort="1" upper="-3.1415" lower="3.1415" velocity="1"/>
		<origin rpy="2.728284631912176 4.895845404485465 5.562541037224525" xyz="0.9105301357078135 0.646351205990926 0.68710199183315"/>
	</joint>
	<joint name="59_to_44" type="revolute">
		<parent link="44"/>
		<child link="59"/>
		<axis xyz="0 1 0"/>
		<limit effort="1" upper="-3.1415" lower="3.1415" velocity="1"/>
		<origin rpy="12.084122902127701 5.494964011385597 1.7547235459826243" xyz="0.15581604867367727 0.4058499647541277 0.8068836205509428"/>
	</joint>
	<joint name="610_to_59" type="revolute">
		<parent link="59"/>
		<child link="610"/>
		<axis xyz="0 1 0"/>
		<limit effort="1" upper="-3.1415" lower="3.1415" velocity="1"/>
		<origin rpy="2.728284631912176 4.895845404485465 5.562541037224525" xyz="0.9105301357078135 0.646351205990926 0.68710199183315"/>
	</joint>
	<joint name="311_to_22" type="revolute">
		<parent link="22"/>
		<child link="311"/>
		<axis xyz="0 0 1"/>
		<limit effort="1" upper="-3.1415" lower="3.1415" velocity="1"/>
		<origin rpy="3.0294095185839964 4.196372075190924 2.6166338695673788" xyz="0.5357034826864502 0.4667766319268153 0.20217506366350713"/>
	</joint>
	<joint name="412_to_311" type="revolute">
		<parent link="311"/>
		<child link="412"/>
		<axis xyz="0 1 0"/>
		<limit effort="1" upper="-3.1415" lower="3.1415" velocity="1"/>
		<origin rpy="2.728284631912176 4.267526873767507 6.190859567942483" xyz="0.8105301357078135 0.646351205990926 0.68710199183315"/>
	</joint>
	<joint name="513_to_412" type="revolute">
		<parent link="412"/>
		<child link="513"/>
		<axis xyz="0 1 0"/>
		<limit effort="1" upper="-3.1415" lower="3.1415" velocity="1"/>
		<origin rpy="6.042061451063851 5.494964011385597 1.7547235459826243" xyz="0.15581604867367727 0.4058499647541277 0.8068836205509428"/>
	</joint>
	<joint name="614_to_513" type="revolute">
		<parent link="513"/>
		<child link="614"/>
		<axis xyz="0 1 0"/>
		<limit effort="1" upper="-3.1415" lower="3.1415" velocity="1"/>
		<origin rpy="2.728284631912176 4.895845404485465 5.562541037224525" xyz="0.9105301357078135 0.646351205990926 0.68710199183315"/>
	</joint>
	<joint name="515_to_412" type="revolute">
		<parent link="412"/>
		<child link="515"/>
		<axis xyz="0 1 0"/>
		<limit effort="1" upper="-3.1415" lower="3.1415" velocity="1"/>
		<origin rpy="9.063092176595775 5.494964011385597 1.7547235459826243" xyz="0.15581604867367727 0.4058499647541277 0.8068836205509428"/>
	</joint>
	<joint name="616_to_515" type="revolute">
		<parent link="515"/>
		<child link="616"/>
		<axis xyz="0 1 0"/>
		<limit effort="1" upper="-3.1415" lower="3.1415" velocity="1"/>
		<origin rpy="2.728284631912176 4.895845404485465 5.562541037224525" xyz="0.9105301357078135 0.646351205990926 0.68710199183315"/>
	</joint>
	<joint name="517_to_412" type="revolute">
		<parent link="412"/>
		<child link="517"/>
		<axis xyz="0 1 0"/>
		<limit effort="1" upper="-3.1415" lower="3.1415" velocity="1"/>
		<origin rpy="12.084122902127701 5.494964011385597 1.7547235459826243" xyz="0.15581604867367727 0.4058499647541277 0.8068836205509428"/>
	</joint>
	<joint name="618_to_517" type="revolute">
		<parent link="517"/>
		<child link="618"/>
		<axis xyz="0 1 0"/>
		<limit effort="1" upper="-3.1415" lower="3.1415" velocity="1"/>
		<origin rpy="2.728284631912176 4.895845404485465 5.562541037224525" xyz="0.9105301357078135 0.646351205990926 0.68710199183315"/>
	</joint>
	<joint name="319_to_22" type="revolute">
		<parent link="22"/>
		<child link="319"/>
		<axis xyz="0 0 1"/>
		<limit effort="1" upper="-3.1415" lower="3.1415" velocity="1"/>
		<origin rpy="4.039212691445329 4.196372075190924 2.6166338695673788" xyz="0.5357034826864502 0.4667766319268153 0.20217506366350713"/>
	</joint>
	<joint name="420_to_319" type="revolute">
		<parent link="319"/>
		<child link="420"/>
		<axis xyz="0 1 0"/>
		<limit effort="1" upper="-3.1415" lower="3.1415" velocity="1"/>
		<origin rpy="2.728284631912176 4.267526873767507 6.190859567942483" xyz="0.8105301357078135 0.646351205990926 0.68710199183315"/>
	</joint>
	<joint name="521_to_420" type="revolute">
		<parent link="420"/>
		<child link="521"/>
		<axis xyz="0 1 0"/>
		<limit effort="1" upper="-3.1415" lower="3.1415" velocity="1"/>
		<origin rpy="6.042061451063851 5.494964011385597 1.7547235459826243" xyz="0.15581604867367727 0.4058499647541277 0.8068836205509428"/>
	</joint>
	<joint name="622_to_521" type="revolute">
		<parent link="521"/>
		<child link="622"/>
		<axis xyz="0 1 0"/>
		<limit effort="1" upper="-3.1415" lower="3.1415" velocity="1"/>
		<origin rpy="2.728284631912176 4.895845404485465 5.562541037224525" xyz="0.9105301357078135 0.646351205990926 0.68710199183315"/>
	</joint>
	<joint name="523_to_420" type="revolute">
		<parent link="420"/>
		<child link="523"/>
		<axis xyz="0 1 0"/>
		<limit effort="1" upper="-3.1415" lower="3.1415" velocity="1"/>
		<origin rpy="9.063092176595775 5.494964011385597 1.7547235459826243" xyz="0.15581604867367727 0.4058499647541277 0.8068836205509428"/>
	</joint>
	<joint name="624_to_523" type="revolute">
		<parent link="523"/>
		<child link="624"/>
		<axis xyz="0 1 0"/>
		<limit effort="1" upper="-3.1415" lower="3.1415" velocity="1"/>
		<origin rpy="2.728284631912176 4.895845404485465 5.562541037224525" xyz="0.9105301357078135 0.646351205990926 0.68710199183315"/>
	</joint>
	<joint name="525_to_420" type="revolute">
		<parent link="420"/>
		<child link="525"/>
		<axis xyz="0 1 0"/>
		<limit effort="1" upper="-3.1415" lower="3.1415" velocity="1"/>
		<origin rpy="12.084122902127701 5.494964011385597 1.7547235459826243" xyz="0.15581604867367727 0.4058499647541277 0.8068836205509428"/>
	</joint>
	<joint name="626_to_525" type="revolute">
		<parent link="525"/>
		<child link="626"/>
		<axis xyz="0 1 0"/>
		<limit effort="1" upper="-3.1415" lower="3.1415" velocity="1"/>
		<origin rpy="2.728284631912176 4.895845404485465 5.562541037224525" xyz="0.9105301357078135 0.646351205990926 0.68710199183315"/>
	</joint>
	<joint name="227_to_11" type="revolute">
		<parent link="11"/>
		<child link="227"/>
		<axis xyz="0 1 0"/>
		<limit effort="1" upper="-3.1415" lower="3.1415" velocity="1"/>
		<origin rpy="17.874025481623477 5.747039156528198 0.28559947335639824" xyz="0.4752396645251993 0.5727739914430996 0.9144225102689908"/>
	</joint>
	<joint name="328_to_227" type="revolute">
		<parent link="227"/>
		<child link="328"/>
		<axis xyz="0 0 1"/>
		<limit effort="1" upper="-3.1415" lower="3.1415" velocity="1"/>
		<origin rpy="2.0196063457226643 4.196372075190924 2.6166338695673788" xyz="0.5357034826864502 0.4667766319268153 0.20217506366350713"/>
	</joint>
	<joint name="429_to_328" type="revolute">
		<parent link="328"/>
		<child link="429"/>
		<axis xyz="0 1 0"/>
		<limit effort="1" upper="-3.1415" lower="3.1415" velocity="1"/>
		<origin rpy="2.728284631912176 4.267526873767507 6.190859567942483" xyz="0.8105301357078135 0.646351205990926 0.68710199183315"/>
	</joint>
	<joint name="530_to_429" type="revolute">
		<parent link="429"/>
		<child link="530"/>
		<axis xyz="0 1 0"/>
		<limit effort="1" upper="-3.1415" lower="3.1415" velocity="1"/>
		<origin rpy="6.042061451063851 5.494964011385597 1.7547235459826243" xyz="0.15581604867367727 0.4058499647541277 0.8068836205509428"/>
	</joint>
	<joint name="631_to_530" type="revolute">
		<parent link="530"/>
		<child link="631"/>
		<axis xyz="0 1 0"/>
		<limit effort="1" upper="-3.1415" lower="3.1415" velocity="1"/>
		<origin rpy="2.728284631912176 4.895845404485465 5.562541037224525" xyz="0.9105301357078135 0.646351205990926 0.68710199183315"/>
	</joint>
	<joint name="532_to_429" type="revolute">
		<parent link="429"/>
		<child link="532"/>
		<axis xyz="0 1 0"/>
		<limit effort="1" upper="-3.1415" lower="3.1415" velocity="1"/>
		<origin rpy="9.063092176595775 5.494964011385597 1.7547235459826243" xyz="0.15581604867367727 0.4058499647541277 0.8068836205509428"/>
	</joint>
	<joint name="633_to_532" type="revolute">
		<parent link="532"/>
		<child link="633"/>
		<axis xyz="0 1 0"/>
		<limit effort="1" upper="-3.1415" lower="3.1415" velocity="1"/>
		<origin rpy="2.728284631912176 4.895845404485465 5.562541037224525" xyz="0.9105301357078135 0.646351205990926 0.68710199183315"/>
	</joint>
	<joint name="534_to_429" type="revolute">
		<parent link="429"/>
		<child link="534"/>
		<axis xyz="0 1 0"/>
		<limit effort="1" upper="-3.1415" lower="3.1415" velocity="1"/>
		<origin rpy="12.084122902127701 5.494964011385597 1.7547235459826243" xyz="0.15581604867367727 0.4058499647541277 0.8068836205509428"/>
	</joint>
	<joint name="635_to_534" type="revolute">
		<parent link="534"/>
		<child link="635"/>
		<axis xyz="0 1 0"/>
		<limit effort="1" upper="-3.1415" lower="3.1415" velocity="1"/>
		<origin rpy="2.728284631912176 4.895845404485465 5.562541037224525" xyz="0.9105301357078135 0.646351205990926 0.68710199183315"/>
	</joint>
	<joint name="336_to_227" type="revolute">
		<parent link="227"/>
		<child link="336"/>
		<axis xyz="0 0 1"/>
		<limit effort="1" upper="-3.1415" lower="3.1415" velocity="1"/>
		<origin rpy="3.0294095185839964 4.196372075190924 2.6166338695673788" xyz="0.5357034826864502 0.4667766319268153 0.20217506366350713"/>
	</joint>
	<joint name="437_to_336" type="revolute">
		<parent link="336"/>
		<child link="437"/>
		<axis xyz="0 1 0"/>
		<limit effort="1" upper="-3.1415" lower="3.1415" velocity="1"/>
		<origin rpy="2.728284631912176 4.267526873767507 6.190859567942483" xyz="0.8105301357078135 0.646351205990926 0.68710199183315"/>
	</joint>
	<joint name="538_to_437" type="revolute">
		<parent link="437"/>
		<child link="538"/>
		<axis xyz="0 1 0"/>
		<limit effort="1" upper="-3.1415" lower="3.1415" velocity="1"/>
		<origin rpy="6.042061451063851 5.494964011385597 1.7547235459826243" xyz="0.15581604867367727 0.4058499647541277 0.8068836205509428"/>
	</joint>
	<joint name="639_to_538" type="revolute">
		<parent link="538"/>
		<child link="639"/>
		<axis xyz="0 1 0"/>
		<limit effort="1" upper="-3.1415" lower="3.1415" velocity="1"/>
		<origin rpy="2.728284631912176 4.895845404485465 5.562541037224525" xyz="0.9105301357078135 0.646351205990926 0.68710199183315"/>
	</joint>
	<joint name="540_to_437" type="revolute">
		<parent link="437"/>
		<child link="540"/>
		<axis xyz="0 1 0"/>
		<limit effort="1" upper="-3.1415" lower="3.1415" velocity="1"/>
		<origin rpy="9.063092176595775 5.494964011385597 1.7547235459826243" xyz="0.15581604867367727 0.4058499647541277 0.8068836205509428"/>
	</joint>
	<joint name="641_to_540" type="revolute">
		<parent link="540"/>
		<child link="641"/>
		<axis xyz="0 1 0"/>
		<limit effort="1" upper="-3.1415" lower="3.1415" velocity="1"/>
		<origin rpy="2.728284631912176 4.895845404485465 5.562541037224525" xyz="0.9105301357078135 0.646351205990926 0.68710199183315"/>
	</joint>
	<joint name="542_to_437" type="revolute">
		<parent link="437"/>
		<child link="542"/>
		<axis xyz="0 1 0"/>
		<limit effort="1" upper="-3.1415" lower="3.1415" velocity="1"/>
		<origin rpy="12.084122902127701 5.494964011385597 1.7547235459826243" xyz="0.15581604867367727 0.4058499647541277 0.8068836205509428"/>
	</joint>
	<joint name="643_to_542" type="revolute">
		<parent link="542"/>
		<child link="643"/>
		<axis xyz="0 1 0"/>
		<limit effort="1" upper="-3.1415" lower="3.1415" velocity="1"/>
		<origin rpy="2.728284631912176 4.895845404485465 5.562541037224525" xyz="0.9105301357078135 0.646351205990926 0.68710199183315"/>
	</joint>
	<joint name="344_to_227" type="revolute">
		<parent link="227"/>
		<child link="344"/>
		<axis xyz="0 0 1"/>
		<limit effort="1" upper="-3.1415" lower="3.1415" velocity="1"/>
		<origin rpy="4.039212691445329 4.196372075190924 2.6166338695673788" xyz="0.5357034826864502 0.4667766319268153 0.20217506366350713"/>
	</joint>
	<joint name="445_to_344" type="revolute">
		<parent link="344"/>
		<child link="445"/>
		<axis xyz="0 1 0"/>
		<limit effort="1" upper="-3.1415" lower="3.1415" velocity="1"/>
		<origin rpy="2.728284631912176 4.267526873767507 6.190859567942483" xyz="0.8105301357078135 0.646351205990926 0.68710199183315"/>
	</joint>
	<joint name="546_to_445" type="revolute">
		<parent link="445"/>
		<child link="546"/>
		<axis xyz="0 1 0"/>
		<limit effort="1" upper="-3.1415" lower="3.1415" velocity="1"/>
		<origin rpy="6.042061451063851 5.494964011385597 1.7547235459826243" xyz="0.15581604867367727 0.4058499647541277 0.8068836205509428"/>
	</joint>
	<joint name="647_to_546" type="revolute">
		<parent link="546"/>
		<child link="647"/>
		<axis xyz="0 1 0"/>
		<limit effort="1" upper="-3.1415" lower="3.1415" velocity="1"/>
		<origin rpy="2.728284631912176 4.895845404485465 5.562541037224525" xyz="0.9105301357078135 0.646351205990926 0.68710199183315"/>
	</joint>
	<joint name="548_to_445" type="revolute">
		<parent link="445"/>
		<child link="548"/>
		<axis xyz="0 1 0"/>
		<limit effort="1" upper="-3.1415" lower="3.1415" velocity="1"/>
		<origin rpy="9.063092176595775 5.494964011385597 1.7547235459826243" xyz="0.15581604867367727 0.4058499647541277 0.8068836205509428"/>
	</joint>
	<joint name="649_to_548" type="revolute">
		<parent link="548"/>
		<child link="649"/>
		<axis xyz="0 1 0"/>
		<limit effort="1" upper="-3.1415" lower="3.1415" velocity="1"/>
		<origin rpy="2.728284631912176 4.895845404485465 5.562541037224525" xyz="0.9105301357078135 0.646351205990926 0.68710199183315"/>
	</joint>
	<joint name="550_to_445" type="revolute">
		<parent link="445"/>
		<child link="550"/>
		<axis xyz="0 1 0"/>
		<limit effort="1" upper="-3.1415" lower="3.1415" velocity="1"/>
		<origin rpy="12.084122902127701 5.494964011385597 1.7547235459826243" xyz="0.15581604867367727 0.4058499647541277 0.8068836205509428"/>
	</joint>
	<joint name="651_to_550" type="revolute">
		<parent link="550"/>
		<child link="651"/>
		<axis xyz="0 1 0"/>
		<limit effort="1" upper="-3.1415" lower="3.1415" velocity="1"/>
		<origin rpy="2.728284631912176 4.895845404485465 5.562541037224525" xyz="0.9105301357078135 0.646351205990926 0.68710199183315"/>
	</joint>
	<joint name="152_to_0" type="revolute">
		<parent link="0"/>
		<child link="152"/>
		<axis xyz="0 1 0"/>
		<limit effort="1" upper="-3.1415" lower="3.1415" velocity="1"/>
		<origin rpy="16.21258948085798 6.282556988648868 0.5422677742866492" xyz="0.8496673682276968 0.23520769677330514 0.326170469526187"/>
	</joint>
	<joint name="253_to_152" type="revolute">
		<parent link="152"/>
		<child link="253"/>
		<axis xyz="0 1 0"/>
		<limit effort="1" upper="-3.1415" lower="3.1415" velocity="1"/>
		<origin rpy="11.916016987748984 5.747039156528198 0.28559947335639824" xyz="0.4752396645251993 0.5727739914430996 0.9144225102689908"/>
	</joint>
	<joint name="354_to_253" type="revolute">
		<parent link="253"/>
		<child link="354"/>
		<axis xyz="0 0 1"/>
		<limit effort="1" upper="-3.1415" lower="3.1415" velocity="1"/>
		<origin rpy="2.0196063457226643 4.196372075190924 2.6166338695673788" xyz="0.5357034826864502 0.4667766319268153 0.20217506366350713"/>
	</joint>
	<joint name="455_to_354" type="revolute">
		<parent link="354"/>
		<child link="455"/>
		<axis xyz="0 1 0"/>
		<limit effort="1" upper="-3.1415" lower="3.1415" velocity="1"/>
		<origin rpy="2.728284631912176 4.267526873767507 6.190859567942483" xyz="0.8105301357078135 0.646351205990926 0.68710199183315"/>
	</joint>
	<joint name="556_to_455" type="revolute">
		<parent link="455"/>
		<child link="556"/>
		<axis xyz="0 1 0"/>
		<limit effort="1" upper="-3.1415" lower="3.1415" velocity="1"/>
		<origin rpy="6.042061451063851 5.494964011385597 1.7547235459826243" xyz="0.15581604867367727 0.4058499647541277 0.8068836205509428"/>
	</joint>
	<joint name="657_to_556" type="revolute">
		<parent link="556"/>
		<child link="657"/>
		<axis xyz="0 1 0"/>
		<limit effort="1" upper="-3.1415" lower="3.1415" velocity="1"/>
		<origin rpy="2.728284631912176 4.895845404485465 5.562541037224525" xyz="0.9105301357078135 0.646351205990926 0.68710199183315"/>
	</joint>
	<joint name="558_to_455" type="revolute">
		<parent link="455"/>
		<child link="558"/>
		<axis xyz="0 1 0"/>
		<limit effort="1" upper="-3.1415" lower="3.1415" velocity="1"/>
		<origin rpy="9.063092176595775 5.494964011385597 1.7547235459826243" xyz="0.15581604867367727 0.4058499647541277 0.8068836205509428"/>
	</joint>
	<joint name="659_to_558" type="revolute">
		<parent link="558"/>
		<child link="659"/>
		<axis xyz="0 1 0"/>
		<limit effort="1" upper="-3.1415" lower="3.1415" velocity="1"/>
		<origin rpy="2.728284631912176 4.895845404485465 5.562541037224525" xyz="0.9105301357078135 0.646351205990926 0.68710199183315"/>
	</joint>
	<joint name="560_to_455" type="revolute">
		<parent link="455"/>
		<child link="560"/>
		<axis xyz="0 1 0"/>
		<limit effort="1" upper="-3.1415" lower="3.1415" velocity="1"/>
		<origin rpy="12.084122902127701 5.494964011385597 1.7547235459826243" xyz="0.15581604867367727 0.4058499647541277 0.8068836205509428"/>
	</joint>
	<joint name="661_to_560" type="revolute">
		<parent link="560"/>
		<child link="661"/>
		<axis xyz="0 1 0"/>
		<limit effort="1" upper="-3.1415" lower="3.1415" velocity="1"/>
		<origin rpy="2.728284631912176 4.895845404485465 5.562541037224525" xyz="0.9105301357078135 0.646351205990926 0.68710199183315"/>
	</joint>
	<joint name="362_to_253" type="revolute">
		<parent link="253"/>
		<child link="362"/>
		<axis xyz="0 0 1"/>
		<limit effort="1" upper="-3.1415" lower="3.1415" velocity="1"/>
		<origin rpy="3.0294095185839964 4.196372075190924 2.6166338695673788" xyz="0.5357034826864502 0.4667766319268153 0.20217506366350713"/>
	</joint>
	<joint name="463_to_362" type="revolute">
		<parent link="362"/>
		<child link="463"/>
		<axis xyz="0 1 0"/>
		<limit effort="1" upper="-3.1415" lower="3.1415" velocity="1"/>
		<origin rpy="2.728284631912176 4.267526873767507 6.190859567942483" xyz="0.8105301357078135 0.646351205990926 0.68710199183315"/>
	</joint>
	<joint name="564_to_463" type="revolute">
		<parent link="463"/>
		<child link="564"/>
		<axis xyz="0 1 0"/>
		<limit effort="1" upper="-3.1415" lower="3.1415" velocity="1"/>
		<origin rpy="6.042061451063851 5.494964011385597 1.7547235459826243" xyz="0.15581604867367727 0.4058499647541277 0.8068836205509428"/>
	</joint>
	<joint name="665_to_564" type="revolute">
		<parent link="564"/>
		<child link="665"/>
		<axis xyz="0 1 0"/>
		<limit effort="1" upper="-3.1415" lower="3.1415" velocity="1"/>
		<origin rpy="2.728284631912176 4.895845404485465 5.562541037224525" xyz="0.9105301357078135 0.646351205990926 0.68710199183315"/>
	</joint>
	<joint name="566_to_463" type="revolute">
		<parent link="463"/>
		<child link="566"/>
		<axis xyz="0 1 0"/>
		<limit effort="1" upper="-3.1415" lower="3.1415" velocity="1"/>
		<origin rpy="9.063092176595775 5.494964011385597 1.7547235459826243" xyz="0.15581604867367727 0.4058499647541277 0.8068836205509428"/>
	</joint>
	<joint name="667_to_566" type="revolute">
		<parent link="566"/>
		<child link="667"/>
		<axis xyz="0 1 0"/>
		<limit effort="1" upper="-3.1415" lower="3.1415" velocity="1"/>
		<origin rpy="2.728284631912176 4.895845404485465 5.562541037224525" xyz="0.9105301357078135 0.646351205990926 0.68710199183315"/>
	</joint>
	<joint name="568_to_463" type="revolute">
		<parent link="463"/>
		<child link="568"/>
		<axis xyz="0 1 0"/>
		<limit effort="1" upper="-3.1415" lower="3.1415" velocity="1"/>
		<origin rpy="12.084122902127701 5.494964011385597 1.7547235459826243" xyz="0.15581604867367727 0.4058499647541277 0.8068836205509428"/>
	</joint>
	<joint name="669_to_568" type="revolute">
		<parent link="568"/>
		<child link="669"/>
		<axis xyz="0 1 0"/>
		<limit effort="1" upper="-3.1415" lower="3.1415" velocity="1"/>
		<origin rpy="2.728284631912176 4.895845404485465 5.562541037224525" xyz="0.9105301357078135 0.646351205990926 0.68710199183315"/>
	</joint>
	<joint name="370_to_253" type="revolute">
		<parent link="253"/>
		<child link="370"/>
		<axis xyz="0 0 1"/>
		<limit effort="1" upper="-3.1415" lower="3.1415" velocity="1"/>
		<origin rpy="4.039212691445329 4.196372075190924 2.6166338695673788" xyz="0.5357034826864502 0.4667766319268153 0.20217506366350713"/>
	</joint>
	<joint name="471_to_370" type="revolute">
		<parent link="370"/>
		<child link="471"/>
		<axis xyz="0 1 0"/>
		<limit effort="1" upper="-3.1415" lower="3.1415" velocity="1"/>
		<origin rpy="2.728284631912176 4.267526873767507 6.190859567942483" xyz="0.8105301357078135 0.646351205990926 0.68710199183315"/>
	</joint>
	<joint name="572_to_471" type="revolute">
		<parent link="471"/>
		<child link="572"/>
		<axis xyz="0 1 0"/>
		<limit effort="1" upper="-3.1415" lower="3.1415" velocity="1"/>
		<origin rpy="6.042061451063851 5.494964011385597 1.7547235459826243" xyz="0.15581604867367727 0.4058499647541277 0.8068836205509428"/>
	</joint>
	<joint name="673_to_572" type="revolute">
		<parent link="572"/>
		<child link="673"/>
		<axis xyz="0 1 0"/>
		<limit effort="1" upper="-3.1415" lower="3.1415" velocity="1"/>
		<origin rpy="2.728284631912176 4.895845404485465 5.562541037224525" xyz="0.9105301357078135 0.646351205990926 0.68710199183315"/>
	</joint>
	<joint name="574_to_471" type="revolute">
		<parent link="471"/>
		<child link="574"/>
		<axis xyz="0 1 0"/>
		<limit effort="1" upper="-3.1415" lower="3.1415" velocity="1"/>
		<origin rpy="9.063092176595775 5.494964011385597 1.7547235459826243" xyz="0.15581604867367727 0.4058499647541277 0.8068836205509428"/>
	</joint>
	<joint name="675_to_574" type="revolute">
		<parent link="574"/>
		<child link="675"/>
		<axis xyz="0 1 0"/>
		<limit effort="1" upper="-3.1415" lower="3.1415" velocity="1"/>
		<origin rpy="2.728284631912176 4.895845404485465 5.562541037224525" xyz="0.9105301357078135 0.646351205990926 0.68710199183315"/>
	</joint>
	<joint name="576_to_471" type="revolute">
		<parent link="471"/>
		<child link="576"/>
		<axis xyz="0 1 0"/>
		<limit effort="1" upper="-3.1415" lower="3.1415" velocity="1"/>
		<origin rpy="12.084122902127701 5.494964011385597 1.7547235459826243" xyz="0.15581604867367727 0.4058499647541277 0.8068836205509428"/>
	</joint>
	<joint name="677_to_576" type="revolute">
		<parent link="576"/>
		<child link="677"/>
		<axis xyz="0 1 0"/>
		<limit effort="1" upper="-3.1415" lower="3.1415" velocity="1"/>
		<origin rpy="2.728284631912176 4.895845404485465 5.562541037224525" xyz="0.9105301357078135 0.646351205990926 0.68710199183315"/>
	</joint>
	<joint name="278_to_152" type="revolute">
		<parent link="152"/>
		<child link="278"/>
		<axis xyz="0 1 0"/>
		<limit effort="1" upper="-3.1415" lower="3.1415" velocity="1"/>
		<origin rpy="17.874025481623477 5.747039156528198 0.28559947335639824" xyz="0.4752396645251993 0.5727739914430996 0.9144225102689908"/>
	</joint>
	<joint name="379_to_278" type="revolute">
		<parent link="278"/>
		<child link="379"/>
		<axis xyz="0 0 1"/>
		<limit effort="1" upper="-3.1415" lower="3.1415" velocity="1"/>
		<origin rpy="2.0196063457226643 4.196372075190924 2.6166338695673788" xyz="0.5357034826864502 0.4667766319268153 0.20217506366350713"/>
	</joint>
	<joint name="480_to_379" type="revolute">
		<parent link="379"/>
		<child link="480"/>
		<axis xyz="0 1 0"/>
		<limit effort="1" upper="-3.1415" lower="3.1415" velocity="1"/>
		<origin rpy="2.728284631912176 4.267526873767507 6.190859567942483" xyz="0.8105301357078135 0.646351205990926 0.68710199183315"/>
	</joint>
	<joint name="581_to_480" type="revolute">
		<parent link="480"/>
		<child link="581"/>
		<axis xyz="0 1 0"/>
		<limit effort="1" upper="-3.1415" lower="3.1415" velocity="1"/>
		<origin rpy="6.042061451063851 5.494964011385597 1.7547235459826243" xyz="0.15581604867367727 0.4058499647541277 0.8068836205509428"/>
	</joint>
	<joint name="682_to_581" type="revolute">
		<parent link="581"/>
		<child link="682"/>
		<axis xyz="0 1 0"/>
		<limit effort="1" upper="-3.1415" lower="3.1415" velocity="1"/>
		<origin rpy="2.728284631912176 4.895845404485465 5.562541037224525" xyz="0.9105301357078135 0.646351205990926 0.68710199183315"/>
	</joint>
	<joint name="583_to_480" type="revolute">
		<parent link="480"/>
		<child link="583"/>
		<axis xyz="0 1 0"/>
		<limit effort="1" upper="-3.1415" lower="3.1415" velocity="1"/>
		<origin rpy="9.063092176595775 5.494964011385597 1.7547235459826243" xyz="0.15581604867367727 0.4058499647541277 0.8068836205509428"/>
	</joint>
	<joint name="684_to_583" type="revolute">
		<parent link="583"/>
		<child link="684"/>
		<axis xyz="0 1 0"/>
		<limit effort="1" upper="-3.1415" lower="3.1415" velocity="1"/>
		<origin rpy="2.728284631912176 4.895845404485465 5.562541037224525" xyz="0.9105301357078135 0.646351205990926 0.68710199183315"/>
	</joint>
	<joint name="585_to_480" type="revolute">
		<parent link="480"/>
		<child link="585"/>
		<axis xyz="0 1 0"/>
		<limit effort="1" upper="-3.1415" lower="3.1415" velocity="1"/>
		<origin rpy="12.084122902127701 5.494964011385597 1.7547235459826243" xyz="0.15581604867367727 0.4058499647541277 0.8068836205509428"/>
	</joint>
	<joint name="686_to_585" type="revolute">
		<parent link="585"/>
		<child link="686"/>
		<axis xyz="0 1 0"/>
		<limit effort="1" upper="-3.1415" lower="3.1415" velocity="1"/>
		<origin rpy="2.728284631912176 4.895845404485465 5.562541037224525" xyz="0.9105301357078135 0.646351205990926 0.68710199183315"/>
	</joint>
	<joint name="387_to_278" type="revolute">
		<parent link="278"/>
		<child link="387"/>
		<axis xyz="0 0 1"/>
		<limit effort="1" upper="-3.1415" lower="3.1415" velocity="1"/>
		<origin rpy="3.0294095185839964 4.196372075190924 2.6166338695673788" xyz="0.5357034826864502 0.4667766319268153 0.20217506366350713"/>
	</joint>
	<joint name="488_to_387" type="revolute">
		<parent link="387"/>
		<child link="488"/>
		<axis xyz="0 1 0"/>
		<limit effort="1" upper="-3.1415" lower="3.1415" velocity="1"/>
		<origin rpy="2.728284631912176 4.267526873767507 6.190859567942483" xyz="0.8105301357078135 0.646351205990926 0.68710199183315"/>
	</joint>
	<joint name="589_to_488" type="revolute">
		<parent link="488"/>
		<child link="589"/>
		<axis xyz="0 1 0"/>
		<limit effort="1" upper="-3.1415" lower="3.1415" velocity="1"/>
		<origin rpy="6.042061451063851 5.494964011385597 1.7547235459826243" xyz="0.15581604867367727 0.4058499647541277 0.8068836205509428"/>
	</joint>
	<joint name="690_to_589" type="revolute">
		<parent link="589"/>
		<child link="690"/>
		<axis xyz="0 1 0"/>
		<limit effort="1" upper="-3.1415" lower="3.1415" velocity="1"/>
		<origin rpy="2.728284631912176 4.895845404485465 5.562541037224525" xyz="0.9105301357078135 0.646351205990926 0.68710199183315"/>
	</joint>
	<joint name="591_to_488" type="revolute">
		<parent link="488"/>
		<child link="591"/>
		<axis xyz="0 1 0"/>
		<limit effort="1" upper="-3.1415" lower="3.1415" velocity="1"/>
		<origin rpy="9.063092176595775 5.494964011385597 1.7547235459826243" xyz="0.15581604867367727 0.4058499647541277 0.8068836205509428"/>
	</joint>
	<joint name="692_to_591" type="revolute">
		<parent link="591"/>
		<child link="692"/>
		<axis xyz="0 1 0"/>
		<limit effort="1" upper="-3.1415" lower="3.1415" velocity="1"/>
		<origin rpy="2.728284631912176 4.895845404485465 5.562541037224525" xyz="0.9105301357078135 0.646351205990926 0.68710199183315"/>
	</joint>
	<joint name="593_to_488" type="revolute">
		<parent link="488"/>
		<child link="593"/>
		<axis xyz="0 1 0"/>
		<limit effort="1" upper="-3.1415" lower="3.1415" velocity="1"/>
		<origin rpy="12.084122902127701 5.494964011385597 1.7547235459826243" xyz="0.15581604867367727 0.4058499647541277 0.8068836205509428"/>
	</joint>
	<joint name="694_to_593" type="revolute">
		<parent link="593"/>
		<child link="694"/>
		<axis xyz="0 1 0"/>
		<limit effort="1" upper="-3.1415" lower="3.1415" velocity="1"/>
		<origin rpy="2.728284631912176 4.895845404485465 5.562541037224525" xyz="0.9105301357078135 0.646351205990926 0.68710199183315"/>
	</joint>
	<joint name="395_to_278" type="revolute">
		<parent link="278"/>
		<child link="395"/>
		<axis xyz="0 0 1"/>
		<limit effort="1" upper="-3.1415" lower="3.1415" velocity="1"/>
		<origin rpy="4.039212691445329 4.196372075190924 2.6166338695673788" xyz="0.5357034826864502 0.4667766319268153 0.20217506366350713"/>
	</joint>
	<joint name="496_to_395" type="revolute">
		<parent link="395"/>
		<child link="496"/>
		<axis xyz="0 1 0"/>
		<limit effort="1" upper="-3.1415" lower="3.1415" velocity="1"/>
		<origin rpy="2.728284631912176 4.267526873767507 6.190859567942483" xyz="0.8105301357078135 0.646351205990926 0.68710199183315"/>
	</joint>
	<joint name="597_to_496" type="revolute">
		<parent link="496"/>
		<child link="597"/>
		<axis xyz="0 1 0"/>
		<limit effort="1" upper="-3.1415" lower="3.1415" velocity="1"/>
		<origin rpy="6.042061451063851 5.494964011385597 1.7547235459826243" xyz="0.15581604867367727 0.4058499647541277 0.8068836205509428"/>
	</joint>
	<joint name="698_to_597" type="revolute">
		<parent link="597"/>
		<child link="698"/>
		<axis xyz="0 1 0"/>
		<limit effort="1" upper="-3.1415" lower="3.1415" velocity="1"/>
		<origin rpy="2.728284631912176 4.895845404485465 5.562541037224525" xyz="0.9105301357078135 0.646351205990926 0.68710199183315"/>
	</joint>
	<joint name="599_to_496" type="revolute">
		<parent link="496"/>
		<child link="599"/>
		<axis xyz="0 1 0"/>
		<limit effort="1" upper="-3.1415" lower="3.1415" velocity="1"/>
		<origin rpy="9.063092176595775 5.494964011385597 1.7547235459826243" xyz="0.15581604867367727 0.4058499647541277 0.8068836205509428"/>
	</joint>
	<joint name="6100_to_599" type="revolute">
		<parent link="599"/>
		<child link="6100"/>
		<axis xyz="0 1 0"/>
		<limit effort="1" upper="-3.1415" lower="3.1415" velocity="1"/>
		<origin rpy="2.728284631912176 4.895845404485465 5.562541037224525" xyz="0.9105301357078135 0.646351205990926 0.68710199183315"/>
	</joint>
	<joint name="5101_to_496" type="revolute">
		<parent link="496"/>
		<child link="5101"/>
		<axis xyz="0 1 0"/>
		<limit effort="1" upper="-3.1415" lower="3.1415" velocity="1"/>
		<origin rpy="12.084122902127701 5.494964011385597 1.7547235459826243" xyz="0.15581604867367727 0.4058499647541277 0.8068836205509428"/>
	</joint>
	<joint name="6102_to_5101" type="revolute">
		<parent link="5101"/>
		<child link="6102"/>
		<axis xyz="0 1 0"/>
		<limit effort="1" upper="-3.1415" lower="3.1415" velocity="1"/>
		<origin rpy="2.728284631912176 4.895845404485465 5.562541037224525" xyz="0.9105301357078135 0.646351205990926 0.68710199183315"/>
	</joint>
	<joint name="1103_to_0" type="revolute">
		<parent link="0"/>
		<child link="1103"/>
		<axis xyz="0 1 0"/>
		<limit effort="1" upper="-3.1415" lower="3.1415" velocity="1"/>
		<origin rpy="21.616785974477306 6.282556988648868 0.5422677742866492" xyz="0.8496673682276968 0.23520769677330514 0.326170469526187"/>
	</joint>
	<joint name="2104_to_1103" type="revolute">
		<parent link="1103"/>
		<child link="2104"/>
		<axis xyz="0 1 0"/>
		<limit effort="1" upper="-3.1415" lower="3.1415" velocity="1"/>
		<origin rpy="11.916016987748984 5.747039156528198 0.28559947335639824" xyz="0.4752396645251993 0.5727739914430996 0.9144225102689908"/>
	</joint>
	<joint name="3105_to_2104" type="revolute">
		<parent link="2104"/>
		<child link="3105"/>
		<axis xyz="0 0 1"/>
		<limit effort="1" upper="-3.1415" lower="3.1415" velocity="1"/>
		<origin rpy="2.0196063457226643 4.196372075190924 2.6166338695673788" xyz="0.5357034826864502 0.4667766319268153 0.20217506366350713"/>
	</joint>
	<joint name="4106_to_3105" type="revolute">
		<parent link="3105"/>
		<child link="4106"/>
		<axis xyz="0 1 0"/>
		<limit effort="1" upper="-3.1415" lower="3.1415" velocity="1"/>
		<origin rpy="2.728284631912176 4.267526873767507 6.190859567942483" xyz="0.8105301357078135 0.646351205990926 0.68710199183315"/>
	</joint>
	<joint name="5107_to_4106" type="revolute">
		<parent link="4106"/>
		<child link="5107"/>
		<axis xyz="0 1 0"/>
		<limit effort="1" upper="-3.1415" lower="3.1415" velocity="1"/>
		<origin rpy="6.042061451063851 5.494964011385597 1.7547235459826243" xyz="0.15581604867367727 0.4058499647541277 0.8068836205509428"/>
	</joint>
	<joint name="6108_to_5107" type="revolute">
		<parent link="5107"/>
		<child link="6108"/>
		<axis xyz="0 1 0"/>
		<limit effort="1" upper="-3.1415" lower="3.1415" velocity="1"/>
		<origin rpy="2.728284631912176 4.895845404485465 5.562541037224525" xyz="0.9105301357078135 0.646351205990926 0.68710199183315"/>
	</joint>
	<joint name="5109_to_4106" type="revolute">
		<parent link="4106"/>
		<child link="5109"/>
		<axis xyz="0 1 0"/>
		<limit effort="1" upper="-3.1415" lower="3.1415" velocity="1"/>
		<origin rpy="9.063092176595775 5.494964011385597 1.7547235459826243" xyz="0.15581604867367727 0.4058499647541277 0.8068836205509428"/>
	</joint>
	<joint name="6110_to_5109" type="revolute">
		<parent link="5109"/>
		<child link="6110"/>
		<axis xyz="0 1 0"/>
		<limit effort="1" upper="-3.1415" lower="3.1415" velocity="1"/>
		<origin rpy="2.728284631912176 4.895845404485465 5.562541037224525" xyz="0.9105301357078135 0.646351205990926 0.68710199183315"/>
	</joint>
	<joint name="5111_to_4106" type="revolute">
		<parent link="4106"/>
		<child link="5111"/>
		<axis xyz="0 1 0"/>
		<limit effort="1" upper="-3.1415" lower="3.1415" velocity="1"/>
		<origin rpy="12.084122902127701 5.494964011385597 1.7547235459826243" xyz="0.15581604867367727 0.4058499647541277 0.8068836205509428"/>
	</joint>
	<joint name="6112_to_5111" type="revolute">
		<parent link="5111"/>
		<child link="6112"/>
		<axis xyz="0 1 0"/>
		<limit effort="1" upper="-3.1415" lower="3.1415" velocity="1"/>
		<origin rpy="2.728284631912176 4.895845404485465 5.562541037224525" xyz="0.9105301357078135 0.646351205990926 0.68710199183315"/>
	</joint>
	<joint name="3113_to_2104" type="revolute">
		<parent link="2104"/>
		<child link="3113"/>
		<axis xyz="0 0 1"/>
		<limit effort="1" upper="-3.1415" lower="3.1415" velocity="1"/>
		<origin rpy="3.0294095185839964 4.196372075190924 2.6166338695673788" xyz="0.5357034826864502 0.4667766319268153 0.20217506366350713"/>
	</joint>
	<joint name="4114_to_3113" type="revolute">
		<parent link="3113"/>
		<child link="4114"/>
		<axis xyz="0 1 0"/>
		<limit effort="1" upper="-3.1415" lower="3.1415" velocity="1"/>
		<origin rpy="2.728284631912176 4.267526873767507 6.190859567942483" xyz="0.8105301357078135 0.646351205990926 0.68710199183315"/>
	</joint>
	<joint name="5115_to_4114" type="revolute">
		<parent link="4114"/>
		<child link="5115"/>
		<axis xyz="0 1 0"/>
		<limit effort="1" upper="-3.1415" lower="3.1415" velocity="1"/>
		<origin rpy="6.042061451063851 5.494964011385597 1.7547235459826243" xyz="0.15581604867367727 0.4058499647541277 0.8068836205509428"/>
	</joint>
	<joint name="6116_to_5115" type="revolute">
		<parent link="5115"/>
		<child link="6116"/>
		<axis xyz="0 1 0"/>
		<limit effort="1" upper="-3.1415" lower="3.1415" velocity="1"/>
		<origin rpy="2.728284631912176 4.895845404485465 5.562541037224525" xyz="0.9105301357078135 0.646351205990926 0.68710199183315"/>
	</joint>
	<joint name="5117_to_4114" type="revolute">
		<parent link="4114"/>
		<child link="5117"/>
		<axis xyz="0 1 0"/>
		<limit effort="1" upper="-3.1415" lower="3.1415" velocity="1"/>
		<origin rpy="9.063092176595775 5.494964011385597 1.7547235459826243" xyz="0.15581604867367727 0.4058499647541277 0.8068836205509428"/>
	</joint>
	<joint name="6118_to_5117" type="revolute">
		<parent link="5117"/>
		<child link="6118"/>
		<axis xyz="0 1 0"/>
		<limit effort="1" upper="-3.1415" lower="3.1415" velocity="1"/>
		<origin rpy="2.728284631912176 4.895845404485465 5.562541037224525" xyz="0.9105301357078135 0.646351205990926 0.68710199183315"/>
	</joint>
	<joint name="5119_to_4114" type="revolute">
		<parent link="4114"/>
		<child link="5119"/>
		<axis xyz="0 1 0"/>
		<limit effort="1" upper="-3.1415" lower="3.1415" velocity="1"/>
		<origin rpy="12.084122902127701 5.494964011385597 1.7547235459826243" xyz="0.15581604867367727 0.4058499647541277 0.8068836205509428"/>
	</joint>
	<joint name="6120_to_5119" type="revolute">
		<parent link="5119"/>
		<child link="6120"/>
		<axis xyz="0 1 0"/>
		<limit effort="1" upper="-3.1415" lower="3.1415" velocity="1"/>
		<origin rpy="2.728284631912176 4.895845404485465 5.562541037224525" xyz="0.9105301357078135 0.646351205990926 0.68710199183315"/>
	</joint>
	<joint name="3121_to_2104" type="revolute">
		<parent link="2104"/>
		<child link="3121"/>
		<axis xyz="0 0 1"/>
		<limit effort="1" upper="-3.1415" lower="3.1415" velocity="1"/>
		<origin rpy="4.039212691445329 4.196372075190924 2.6166338695673788" xyz="0.5357034826864502 0.4667766319268153 0.20217506366350713"/>
	</joint>
	<joint name="4122_to_3121" type="revolute">
		<parent link="3121"/>
		<child link="4122"/>
		<axis xyz="0 1 0"/>
		<limit effort="1" upper="-3.1415" lower="3.1415" velocity="1"/>
		<origin rpy="2.728284631912176 4.267526873767507 6.190859567942483" xyz="0.8105301357078135 0.646351205990926 0.68710199183315"/>
	</joint>
	<joint name="5123_to_4122" type="revolute">
		<parent link="4122"/>
		<child link="5123"/>
		<axis xyz="0 1 0"/>
		<limit effort="1" upper="-3.1415" lower="3.1415" velocity="1"/>
		<origin rpy="6.042061451063851 5.494964011385597 1.7547235459826243" xyz="0.15581604867367727 0.4058499647541277 0.8068836205509428"/>
	</joint>
	<joint name="6124_to_5123" type="revolute">
		<parent link="5123"/>
		<child link="6124"/>
		<axis xyz="0 1 0"/>
		<limit effort="1" upper="-3.1415" lower="3.1415" velocity="1"/>
		<origin rpy="2.728284631912176 4.895845404485465 5.562541037224525" xyz="0.9105301357078135 0.646351205990926 0.68710199183315"/>
	</joint>
	<joint name="5125_to_4122" type="revolute">
		<parent link="4122"/>
		<child link="5125"/>
		<axis xyz="0 1 0"/>
		<limit effort="1" upper="-3.1415" lower="3.1415" velocity="1"/>
		<origin rpy="9.063092176595775 5.494964011385597 1.7547235459826243" xyz="0.15581604867367727 0.4058499647541277 0.8068836205509428"/>
	</joint>
	<joint name="6126_to_5125" type="revolute">
		<parent link="5125"/>
		<child link="6126"/>
		<axis xyz="0 1 0"/>
		<limit effort="1" upper="-3.1415" lower="3.1415" velocity="1"/>
		<origin rpy="2.728284631912176 4.895845404485465 5.562541037224525" xyz="0.9105301357078135 0.646351205990926 0.68710199183315"/>
	</joint>
	<joint name="5127_to_4122" type="revolute">
		<parent link="4122"/>
		<child link="5127"/>
		<axis xyz="0 1 0"/>
		<limit effort="1" upper="-3.1415" lower="3.1415" velocity="1"/>
		<origin rpy="12.084122902127701 5.494964011385597 1.7547235459826243" xyz="0.15581604867367727 0.4058499647541277 0.8068836205509428"/>
	</joint>
	<joint name="6128_to_5127" type="revolute">
		<parent link="5127"/>
		<child link="6128"/>
		<axis xyz="0 1 0"/>
		<limit effort="1" upper="-3.1415" lower="3.1415" velocity="1"/>
		<origin rpy="2.728284631912176 4.895845404485465 5.562541037224525" xyz="0.9105301357078135 0.646351205990926 0.68710199183315"/>
	</joint>
	<joint name="2129_to_1103" type="revolute">
		<parent link="1103"/>
		<child link="2129"/>
		<axis xyz="0 1 0"/>
		<limit effort="1" upper="-3.1415" lower="3.1415" velocity="1"/>
		<origin rpy="17.874025481623477 5.747039156528198 0.28559947335639824" xyz="0.4752396645251993 0.5727739914430996 0.9144225102689908"/>
	</joint>
	<joint name="3130_to_2129" type="revolute">
		<parent link="2129"/>
		<child link="3130"/>
		<axis xyz="0 0 1"/>
		<limit effort="1" upper="-3.1415" lower="3.1415" velocity="1"/>
		<origin rpy="2.0196063457226643 4.196372075190924 2.6166338695673788" xyz="0.5357034826864502 0.4667766319268153 0.20217506366350713"/>
	</joint>
	<joint name="4131_to_3130" type="revolute">
		<parent link="3130"/>
		<child link="4131"/>
		<axis xyz="0 1 0"/>
		<limit effort="1" upper="-3.1415" lower="3.1415" velocity="1"/>
		<origin rpy="2.728284631912176 4.267526873767507 6.190859567942483" xyz="0.8105301357078135 0.646351205990926 0.68710199183315"/>
	</joint>
	<joint name="5132_to_4131" type="revolute">
		<parent link="4131"/>
		<child link="5132"/>
		<axis xyz="0 1 0"/>
		<limit effort="1" upper="-3.1415" lower="3.1415" velocity="1"/>
		<origin rpy="6.042061451063851 5.494964011385597 1.7547235459826243" xyz="0.15581604867367727 0.4058499647541277 0.8068836205509428"/>
	</joint>
	<joint name="6133_to_5132" type="revolute">
		<parent link="5132"/>
		<child link="6133"/>
		<axis xyz="0 1 0"/>
		<limit effort="1" upper="-3.1415" lower="3.1415" velocity="1"/>
		<origin rpy="2.728284631912176 4.895845404485465 5.562541037224525" xyz="0.9105301357078135 0.646351205990926 0.68710199183315"/>
	</joint>
	<joint name="5134_to_4131" type="revolute">
		<parent link="4131"/>
		<child link="5134"/>
		<axis xyz="0 1 0"/>
		<limit effort="1" upper="-3.1415" lower="3.1415" velocity="1"/>
		<origin rpy="9.063092176595775 5.494964011385597 1.7547235459826243" xyz="0.15581604867367727 0.4058499647541277 0.8068836205509428"/>
	</joint>
	<joint name="6135_to_5134" type="revolute">
		<parent link="5134"/>
		<child link="6135"/>
		<axis xyz="0 1 0"/>
		<limit effort="1" upper="-3.1415" lower="3.1415" velocity="1"/>
		<origin rpy="2.728284631912176 4.895845404485465 5.562541037224525" xyz="0.9105301357078135 0.646351205990926 0.68710199183315"/>
	</joint>
	<joint name="5136_to_4131" type="revolute">
		<parent link="4131"/>
		<child link="5136"/>
		<axis xyz="0 1 0"/>
		<limit effort="1" upper="-3.1415" lower="3.1415" velocity="1"/>
		<origin rpy="12.084122902127701 5.494964011385597 1.7547235459826243" xyz="0.15581604867367727 0.4058499647541277 0.8068836205509428"/>
	</joint>
	<joint name="6137_to_5136" type="revolute">
		<parent link="5136"/>
		<child link="6137"/>
		<axis xyz="0 1 0"/>
		<limit effort="1" upper="-3.1415" lower="3.1415" velocity="1"/>
		<origin rpy="2.728284631912176 4.895845404485465 5.562541037224525" xyz="0.9105301357078135 0.646351205990926 0.68710199183315"/>
	</joint>
	<joint name="3138_to_2129" type="revolute">
		<parent link="2129"/>
		<child link="3138"/>
		<axis xyz="0 0 1"/>
		<limit effort="1" upper="-3.1415" lower="3.1415" velocity="1"/>
		<origin rpy="3.0294095185839964 4.196372075190924 2.6166338695673788" xyz="0.5357034826864502 0.4667766319268153 0.20217506366350713"/>
	</joint>
	<joint name="4139_to_3138" type="revolute">
		<parent link="3138"/>
		<child link="4139"/>
		<axis xyz="0 1 0"/>
		<limit effort="1" upper="-3.1415" lower="3.1415" velocity="1"/>
		<origin rpy="2.728284631912176 4.267526873767507 6.190859567942483" xyz="0.8105301357078135 0.646351205990926 0.68710199183315"/>
	</joint>
	<joint name="5140_to_4139" type="revolute">
		<parent link="4139"/>
		<child link="5140"/>
		<axis xyz="0 1 0"/>
		<limit effort="1" upper="-3.1415" lower="3.1415" velocity="1"/>
		<origin rpy="6.042061451063851 5.494964011385597 1.7547235459826243" xyz="0.15581604867367727 0.4058499647541277 0.8068836205509428"/>
	</joint>
	<joint name="6141_to_5140" type="revolute">
		<parent link="5140"/>
		<child link="6141"/>
		<axis xyz="0 1 0"/>
		<limit effort="1" upper="-3.1415" lower="3.1415" velocity="1"/>
		<origin rpy="2.728284631912176 4.895845404485465 5.562541037224525" xyz="0.9105301357078135 0.646351205990926 0.68710199183315"/>
	</joint>
	<joint name="5142_to_4139" type="revolute">
		<parent link="4139"/>
		<child link="5142"/>
		<axis xyz="0 1 0"/>
		<limit effort="1" upper="-3.1415" lower="3.1415" velocity="1"/>
		<origin rpy="9.063092176595775 5.494964011385597 1.7547235459826243" xyz="0.15581604867367727 0.4058499647541277 0.8068836205509428"/>
	</joint>
	<joint name="6143_to_5142" type="revolute">
		<parent link="5142"/>
		<child link="6143"/>
		<axis xyz="0 1 0"/>
		<limit effort="1" upper="-3.1415" lower="3.1415" velocity="1"/>
		<origin rpy="2.728284631912176 4.895845404485465 5.562541037224525" xyz="0.9105301357078135 0.646351205990926 0.68710199183315"/>
	</joint>
	<joint name="5144_to_4139" type="revolute">
		<parent link="4139"/>
		<child link="5144"/>
		<axis xyz="0 1 0"/>
		<limit effort="1" upper="-3.1415" lower="3.1415" velocity="1"/>
		<origin rpy="12.084122902127701 5.494964011385597 1.7547235459826243" xyz="0.15581604867367727 0.4058499647541277 0.8068836205509428"/>
	</joint>
	<joint name="6145_to_5144" type="revolute">
		<parent link="5144"/>
		<child link="6145"/>
		<axis xyz="0 1 0"/>
		<limit effort="1" upper="-3.1415" lower="3.1415" velocity="1"/>
		<origin rpy="2.728284631912176 4.895845404485465 5.562541037224525" xyz="0.9105301357078135 0.646351205990926 0.68710199183315"/>
	</joint>
	<joint name="3146_to_2129" type="revolute">
		<parent link="2129"/>
		<child link="3146"/>
		<axis xyz="0 0 1"/>
		<limit effort="1" upper="-3.1415" lower="3.1415" velocity="1"/>
		<origin rpy="4.039212691445329 4.196372075190924 2.6166338695673788" xyz="0.5357034826864502 0.4667766319268153 0.20217506366350713"/>
	</joint>
	<joint name="4147_to_3146" type="revolute">
		<parent link="3146"/>
		<child link="4147"/>
		<axis xyz="0 1 0"/>
		<limit effort="1" upper="-3.1415" lower="3.1415" velocity="1"/>
		<origin rpy="2.728284631912176 4.267526873767507 6.190859567942483" xyz="0.8105301357078135 0.646351205990926 0.68710199183315"/>
	</joint>
	<joint name="5148_to_4147" type="revolute">
		<parent link="4147"/>
		<child link="5148"/>
		<axis xyz="0 1 0"/>
		<limit effort="1" upper="-3.1415" lower="3.1415" velocity="1"/>
		<origin rpy="6.042061451063851 5.494964011385597 1.7547235459826243" xyz="0.15581604867367727 0.4058499647541277 0.8068836205509428"/>
	</joint>
	<joint name="6149_to_5148" type="revolute">
		<parent link="5148"/>
		<child link="6149"/>
		<axis xyz="0 1 0"/>
		<limit effort="1" upper="-3.1415" lower="3.1415" velocity="1"/>
		<origin rpy="2.728284631912176 4.895845404485465 5.562541037224525" xyz="0.9105301357078135 0.646351205990926 0.68710199183315"/>
	</joint>
	<joint name="5150_to_4147" type="revolute">
		<parent link="4147"/>
		<child link="5150"/>
		<axis xyz="0 1 0"/>
		<limit effort="1" upper="-3.1415" lower="3.1415" velocity="1"/>
		<origin rpy="9.063092176595775 5.494964011385597 1.7547235459826243" xyz="0.15581604867367727 0.4058499647541277 0.8068836205509428"/>
	</joint>
	<joint name="6151_to_5150" type="revolute">
		<parent link="5150"/>
		<child link="6151"/>
		<axis xyz="0 1 0"/>
		<limit effort="1" upper="-3.1415" lower="3.1415" velocity="1"/>
		<origin rpy="2.728284631912176 4.895845404485465 5.562541037224525" xyz="0.9105301357078135 0.646351205990926 0.68710199183315"/>
	</joint>
	<joint name="5152_to_4147" type="revolute">
		<parent link="4147"/>
		<child link="5152"/>
		<axis xyz="0 1 0"/>
		<limit effort="1" upper="-3.1415" lower="3.1415" velocity="1"/>
		<origin rpy="12.084122902127701 5.494964011385597 1.7547235459826243" xyz="0.15581604867367727 0.4058499647541277 0.8068836205509428"/>
	</joint>
	<joint name="6153_to_5152" type="revolute">
		<parent link="5152"/>
		<child link="6153"/>
		<axis xyz="0 1 0"/>
		<limit effort="1" upper="-3.1415" lower="3.1415" velocity="1"/>
		<origin rpy="2.728284631912176 4.895845404485465 5.562541037224525" xyz="0.9105301357078135 0.646351205990926 0.68710199183315"/>
	</joint>
</robot>
