<?xml version="1.0"?><robot name="pepe">
	<link name="0">
		<visual>
			<geometry>
				<cylinder length="1.023101065282027" radius="0.05094999422222135"/>
			</geometry>
		</visual>
		<collision>
			<geometry>
				<cylinder length="1.023101065282027" radius="0.05094999422222135"/>
			</geometry>
		</collision>
		<inertial>
			<mass value="0.008343661714698665"/>
			<inertia ixx="0.03" iyy="0.03" izz="0.03" ixy="0" ixz="0" iyx="0"/>
		</inertial>
	</link>
	<link name="11">
		<visual>
			<geometry>
				<cylinder length="1.4779301218557808" radius="0.5042351726760189"/>
			</geometry>
		</visual>
		<collision>
			<geometry>
				<cylinder length="1.4779301218557808" radius="0.5042351726760189"/>
			</geometry>
		</collision>
		<inertial>
			<mass value="1.1805110215364507"/>
			<inertia ixx="0.03" iyy="0.03" izz="0.03" ixy="0" ixz="0" iyx="0"/>
		</inertial>
	</link>
	<link name="12">
		<visual>
			<geometry>
				<cylinder length="1.4779301218557808" radius="0.5042351726760189"/>
			</geometry>
		</visual>
		<collision>
			<geometry>
				<cylinder length="1.4779301218557808" radius="0.5042351726760189"/>
			</geometry>
		</collision>
		<inertial>
			<mass value="1.1805110215364507"/>
			<inertia ixx="0.03" iyy="0.03" izz="0.03" ixy="0" ixz="0" iyx="0"/>
		</inertial>
	</link>
	<link name="23">
		<visual>
			<geometry>
				<cylinder length="1.8879267890973488" radius="0.9379421538681382"/>
			</geometry>
		</visual>
		<collision>
			<geometry>
				<cylinder length="1.8879267890973488" radius="0.9379421538681382"/>
			</geometry>
		</collision>
		<inertial>
			<mass value="5.217796429387148"/>
			<inertia ixx="0.03" iyy="0.03" izz="0.03" ixy="0" ixz="0" iyx="0"/>
		</inertial>
	</link>
	<link name="24">
		<visual>
			<geometry>
				<cylinder length="1.8879267890973488" radius="0.9379421538681382"/>
			</geometry>
		</visual>
		<collision>
			<geometry>
				<cylinder length="1.8879267890973488" radius="0.9379421538681382"/>
			</geometry>
		</collision>
		<inertial>
			<mass value="5.217796429387148"/>
			<inertia ixx="0.03" iyy="0.03" izz="0.03" ixy="0" ixz="0" iyx="0"/>
		</inertial>
	</link>
	<joint name="11_to_0" type="revolute">
		<parent link="0"/>
		<child link="11"/>
		<axis xyz="0 1 0"/>
		<limit effort="1" upper="-3.1415" lower="3.1415" velocity="1"/>
		<origin rpy="6.917068562644353 5.196394829557684 4.873947370565327" xyz="0.0810917475125349 0.15760646038614268 0.1950018362705248"/>
	</joint>
	<joint name="12_to_0" type="revolute">
		<parent link="0"/>
		<child link="12"/>
		<axis xyz="0 1 0"/>
		<limit effort="1" upper="-3.1415" lower="3.1415" velocity="1"/>
		<origin rpy="10.37560284396653 5.196394829557684 4.873947370565327" xyz="0.0810917475125349 0.15760646038614268 0.1950018362705248"/>
	</joint>
	<joint name="23_to_0" type="revolute">
		<parent link="0"/>
		<child link="23"/>
		<axis xyz="0 0 1"/>
		<limit effort="1" upper="-3.1415" lower="3.1415" velocity="1"/>
		<origin rpy="2.9296242116595708 6.0447012073280755 0.08493053139483625" xyz="0.9833007992615643 0.9081687840147478 0.3782157956702127"/>
	</joint>
	<joint name="24_to_0" type="revolute">
		<parent link="0"/>
		<child link="24"/>
		<axis xyz="0 0 1"/>
		<limit effort="1" upper="-3.1415" lower="3.1415" velocity="1"/>
		<origin rpy="3.6620302645744633 6.0447012073280755 0.08493053139483625" xyz="0.9833007992615643 0.9081687840147478 0.3782157956702127"/>
	</joint>
</robot>
