<?xml version="1.0"?><robot name="pepe">
	<link name="0">
		<visual>
			<geometry>
				<cylinder length="0.10959542754246421" radius="0.9999764888571718"/>
			</geometry>
		</visual>
		<collision>
			<geometry>
				<cylinder length="0.10959542754246421" radius="0.9999764888571718"/>
			</geometry>
		</collision>
		<inertial>
			<mass value="0.3442880002547839"/>
			<inertia ixx="0.03" iyy="0.03" izz="0.03" ixy="0" ixz="0" iyx="0"/>
		</inertial>
	</link>
	<link name="11">
		<visual>
			<geometry>
				<cylinder length="1.1872376092644017" radius="0.3991789327641704"/>
			</geometry>
		</visual>
		<collision>
			<geometry>
				<cylinder length="1.1872376092644017" radius="0.3991789327641704"/>
			</geometry>
		</collision>
		<inertial>
			<mass value="0.594323282278726"/>
			<inertia ixx="0.03" iyy="0.03" izz="0.03" ixy="0" ixz="0" iyx="0"/>
		</inertial>
	</link>
	<link name="22">
		<visual>
			<geometry>
				<cylinder length="0.669974225979638" radius="0.7302644817118741"/>
			</geometry>
		</visual>
		<collision>
			<geometry>
				<cylinder length="0.669974225979638" radius="0.7302644817118741"/>
			</geometry>
		</collision>
		<inertial>
			<mass value="1.1224534124002217"/>
			<inertia ixx="0.03" iyy="0.03" izz="0.03" ixy="0" ixz="0" iyx="0"/>
		</inertial>
	</link>
	<link name="23">
		<visual>
			<geometry>
				<cylinder length="0.669974225979638" radius="0.7302644817118741"/>
			</geometry>
		</visual>
		<collision>
			<geometry>
				<cylinder length="0.669974225979638" radius="0.7302644817118741"/>
			</geometry>
		</collision>
		<inertial>
			<mass value="1.1224534124002217"/>
			<inertia ixx="0.03" iyy="0.03" izz="0.03" ixy="0" ixz="0" iyx="0"/>
		</inertial>
	</link>
	<link name="24">
		<visual>
			<geometry>
				<cylinder length="0.669974225979638" radius="0.7302644817118741"/>
			</geometry>
		</visual>
		<collision>
			<geometry>
				<cylinder length="0.669974225979638" radius="0.7302644817118741"/>
			</geometry>
		</collision>
		<inertial>
			<mass value="1.1224534124002217"/>
			<inertia ixx="0.03" iyy="0.03" izz="0.03" ixy="0" ixz="0" iyx="0"/>
		</inertial>
	</link>
	<link name="15">
		<visual>
			<geometry>
				<cylinder length="1.1872376092644017" radius="0.3991789327641704"/>
			</geometry>
		</visual>
		<collision>
			<geometry>
				<cylinder length="1.1872376092644017" radius="0.3991789327641704"/>
			</geometry>
		</collision>
		<inertial>
			<mass value="0.594323282278726"/>
			<inertia ixx="0.03" iyy="0.03" izz="0.03" ixy="0" ixz="0" iyx="0"/>
		</inertial>
	</link>
	<link name="26">
		<visual>
			<geometry>
				<cylinder length="0.669974225979638" radius="0.7302644817118741"/>
			</geometry>
		</visual>
		<collision>
			<geometry>
				<cylinder length="0.669974225979638" radius="0.7302644817118741"/>
			</geometry>
		</collision>
		<inertial>
			<mass value="1.1224534124002217"/>
			<inertia ixx="0.03" iyy="0.03" izz="0.03" ixy="0" ixz="0" iyx="0"/>
		</inertial>
	</link>
	<link name="27">
		<visual>
			<geometry>
				<cylinder length="0.669974225979638" radius="0.7302644817118741"/>
			</geometry>
		</visual>
		<collision>
			<geometry>
				<cylinder length="0.669974225979638" radius="0.7302644817118741"/>
			</geometry>
		</collision>
		<inertial>
			<mass value="1.1224534124002217"/>
			<inertia ixx="0.03" iyy="0.03" izz="0.03" ixy="0" ixz="0" iyx="0"/>
		</inertial>
	</link>
	<link name="28">
		<visual>
			<geometry>
				<cylinder length="0.669974225979638" radius="0.7302644817118741"/>
			</geometry>
		</visual>
		<collision>
			<geometry>
				<cylinder length="0.669974225979638" radius="0.7302644817118741"/>
			</geometry>
		</collision>
		<inertial>
			<mass value="1.1224534124002217"/>
			<inertia ixx="0.03" iyy="0.03" izz="0.03" ixy="0" ixz="0" iyx="0"/>
		</inertial>
	</link>
	<link name="19">
		<visual>
			<geometry>
				<cylinder length="1.1872376092644017" radius="0.3991789327641704"/>
			</geometry>
		</visual>
		<collision>
			<geometry>
				<cylinder length="1.1872376092644017" radius="0.3991789327641704"/>
			</geometry>
		</collision>
		<inertial>
			<mass value="0.594323282278726"/>
			<inertia ixx="0.03" iyy="0.03" izz="0.03" ixy="0" ixz="0" iyx="0"/>
		</inertial>
	</link>
	<link name="210">
		<visual>
			<geometry>
				<cylinder length="0.669974225979638" radius="0.7302644817118741"/>
			</geometry>
		</visual>
		<collision>
			<geometry>
				<cylinder length="0.669974225979638" radius="0.7302644817118741"/>
			</geometry>
		</collision>
		<inertial>
			<mass value="1.1224534124002217"/>
			<inertia ixx="0.03" iyy="0.03" izz="0.03" ixy="0" ixz="0" iyx="0"/>
		</inertial>
	</link>
	<link name="211">
		<visual>
			<geometry>
				<cylinder length="0.669974225979638" radius="0.7302644817118741"/>
			</geometry>
		</visual>
		<collision>
			<geometry>
				<cylinder length="0.669974225979638" radius="0.7302644817118741"/>
			</geometry>
		</collision>
		<inertial>
			<mass value="1.1224534124002217"/>
			<inertia ixx="0.03" iyy="0.03" izz="0.03" ixy="0" ixz="0" iyx="0"/>
		</inertial>
	</link>
	<link name="212">
		<visual>
			<geometry>
				<cylinder length="0.669974225979638" radius="0.7302644817118741"/>
			</geometry>
		</visual>
		<collision>
			<geometry>
				<cylinder length="0.669974225979638" radius="0.7302644817118741"/>
			</geometry>
		</collision>
		<inertial>
			<mass value="1.1224534124002217"/>
			<inertia ixx="0.03" iyy="0.03" izz="0.03" ixy="0" ixz="0" iyx="0"/>
		</inertial>
	</link>
	<joint name="11_to_0" type="revolute">
		<parent link="0"/>
		<child link="11"/>
		<axis xyz="0 1 0"/>
		<limit effort="1" upper="-3.1415" lower="3.1415" velocity="1"/>
		<origin rpy="5.778931544968686 4.588609673539818 0.1419210292937197" xyz="0.39375438723311196 0.7626037178264388 0.25863347841572515"/>
	</joint>
	<joint name="22_to_11" type="revolute">
		<parent link="11"/>
		<child link="22"/>
		<axis xyz="1 0 0"/>
		<limit effort="1" upper="-3.1415" lower="3.1415" velocity="1"/>
		<origin rpy="0.5613268204832329 4.050807946371586 0.5191958401016188" xyz="0.8802687168556907 0.4251184254746059 0.09822746496964774"/>
	</joint>
	<joint name="23_to_11" type="revolute">
		<parent link="11"/>
		<child link="23"/>
		<axis xyz="1 0 0"/>
		<limit effort="1" upper="-3.1415" lower="3.1415" velocity="1"/>
		<origin rpy="0.8419902307248494 4.050807946371586 0.5191958401016188" xyz="0.8802687168556907 0.4251184254746059 0.09822746496964774"/>
	</joint>
	<joint name="24_to_11" type="revolute">
		<parent link="11"/>
		<child link="24"/>
		<axis xyz="1 0 0"/>
		<limit effort="1" upper="-3.1415" lower="3.1415" velocity="1"/>
		<origin rpy="1.1226536409664658 4.050807946371586 0.5191958401016188" xyz="0.8802687168556907 0.4251184254746059 0.09822746496964774"/>
	</joint>
	<joint name="15_to_0" type="revolute">
		<parent link="0"/>
		<child link="15"/>
		<axis xyz="0 1 0"/>
		<limit effort="1" upper="-3.1415" lower="3.1415" velocity="1"/>
		<origin rpy="8.66839731745303 4.588609673539818 0.1419210292937197" xyz="0.39375438723311196 0.7626037178264388 0.25863347841572515"/>
	</joint>
	<joint name="26_to_15" type="revolute">
		<parent link="15"/>
		<child link="26"/>
		<axis xyz="1 0 0"/>
		<limit effort="1" upper="-3.1415" lower="3.1415" velocity="1"/>
		<origin rpy="0.5613268204832329 4.050807946371586 0.5191958401016188" xyz="0.8802687168556907 0.4251184254746059 0.09822746496964774"/>
	</joint>
	<joint name="27_to_15" type="revolute">
		<parent link="15"/>
		<child link="27"/>
		<axis xyz="1 0 0"/>
		<limit effort="1" upper="-3.1415" lower="3.1415" velocity="1"/>
		<origin rpy="0.8419902307248494 4.050807946371586 0.5191958401016188" xyz="0.8802687168556907 0.4251184254746059 0.09822746496964774"/>
	</joint>
	<joint name="28_to_15" type="revolute">
		<parent link="15"/>
		<child link="28"/>
		<axis xyz="1 0 0"/>
		<limit effort="1" upper="-3.1415" lower="3.1415" velocity="1"/>
		<origin rpy="1.1226536409664658 4.050807946371586 0.5191958401016188" xyz="0.8802687168556907 0.4251184254746059 0.09822746496964774"/>
	</joint>
	<joint name="19_to_0" type="revolute">
		<parent link="0"/>
		<child link="19"/>
		<axis xyz="0 1 0"/>
		<limit effort="1" upper="-3.1415" lower="3.1415" velocity="1"/>
		<origin rpy="11.557863089937372 4.588609673539818 0.1419210292937197" xyz="0.39375438723311196 0.7626037178264388 0.25863347841572515"/>
	</joint>
	<joint name="210_to_19" type="revolute">
		<parent link="19"/>
		<child link="210"/>
		<axis xyz="1 0 0"/>
		<limit effort="1" upper="-3.1415" lower="3.1415" velocity="1"/>
		<origin rpy="0.5613268204832329 4.050807946371586 0.5191958401016188" xyz="0.8802687168556907 0.4251184254746059 0.09822746496964774"/>
	</joint>
	<joint name="211_to_19" type="revolute">
		<parent link="19"/>
		<child link="211"/>
		<axis xyz="1 0 0"/>
		<limit effort="1" upper="-3.1415" lower="3.1415" velocity="1"/>
		<origin rpy="0.8419902307248494 4.050807946371586 0.5191958401016188" xyz="0.8802687168556907 0.4251184254746059 0.09822746496964774"/>
	</joint>
	<joint name="212_to_19" type="revolute">
		<parent link="19"/>
		<child link="212"/>
		<axis xyz="1 0 0"/>
		<limit effort="1" upper="-3.1415" lower="3.1415" velocity="1"/>
		<origin rpy="1.1226536409664658 4.050807946371586 0.5191958401016188" xyz="0.8802687168556907 0.4251184254746059 0.09822746496964774"/>
	</joint>
</robot>
