<?xml version="1.0"?><robot name="pepe">
	<link name="0">
		<visual>
			<geometry>
				<cylinder length="1.121906487419306" radius="0.21365532050541058"/>
			</geometry>
		</visual>
		<collision>
			<geometry>
				<cylinder length="1.121906487419306" radius="0.21365532050541058"/>
			</geometry>
		</collision>
		<inertial>
			<mass value="0.16089181704610028"/>
			<inertia ixx="0.03" iyy="0.03" izz="0.03" ixy="0" ixz="0" iyx="0"/>
		</inertial>
	</link>
	<link name="11">
		<visual>
			<geometry>
				<cylinder length="1.928329125693357" radius="0.9999"/>
			</geometry>
		</visual>
		<collision>
			<geometry>
				<cylinder length="1.928329125693357" radius="0.9999"/>
			</geometry>
		</collision>
		<inertial>
			<mass value="6.0568130706387295"/>
			<inertia ixx="0.03" iyy="0.03" izz="0.03" ixy="0" ixz="0" iyx="0"/>
		</inertial>
	</link>
	<link name="22">
		<visual>
			<geometry>
				<cylinder length="1.928329125693357" radius="0.9999"/>
			</geometry>
		</visual>
		<collision>
			<geometry>
				<cylinder length="1.928329125693357" radius="0.9999"/>
			</geometry>
		</collision>
		<inertial>
			<mass value="6.0568130706387295"/>
			<inertia ixx="0.03" iyy="0.03" izz="0.03" ixy="0" ixz="0" iyx="0"/>
		</inertial>
	</link>
	<link name="33">
		<visual>
			<geometry>
				<cylinder length="1.928329125693357" radius="0.9999"/>
			</geometry>
		</visual>
		<collision>
			<geometry>
				<cylinder length="1.928329125693357" radius="0.9999"/>
			</geometry>
		</collision>
		<inertial>
			<mass value="6.0568130706387295"/>
			<inertia ixx="0.03" iyy="0.03" izz="0.03" ixy="0" ixz="0" iyx="0"/>
		</inertial>
	</link>
	<link name="34">
		<visual>
			<geometry>
				<cylinder length="1.928329125693357" radius="0.9999"/>
			</geometry>
		</visual>
		<collision>
			<geometry>
				<cylinder length="1.928329125693357" radius="0.9999"/>
			</geometry>
		</collision>
		<inertial>
			<mass value="6.0568130706387295"/>
			<inertia ixx="0.03" iyy="0.03" izz="0.03" ixy="0" ixz="0" iyx="0"/>
		</inertial>
	</link>
	<link name="35">
		<visual>
			<geometry>
				<cylinder length="1.928329125693357" radius="0.9999"/>
			</geometry>
		</visual>
		<collision>
			<geometry>
				<cylinder length="1.928329125693357" radius="0.9999"/>
			</geometry>
		</collision>
		<inertial>
			<mass value="6.0568130706387295"/>
			<inertia ixx="0.03" iyy="0.03" izz="0.03" ixy="0" ixz="0" iyx="0"/>
		</inertial>
	</link>
	<link name="26">
		<visual>
			<geometry>
				<cylinder length="1.928329125693357" radius="0.9999"/>
			</geometry>
		</visual>
		<collision>
			<geometry>
				<cylinder length="1.928329125693357" radius="0.9999"/>
			</geometry>
		</collision>
		<inertial>
			<mass value="6.0568130706387295"/>
			<inertia ixx="0.03" iyy="0.03" izz="0.03" ixy="0" ixz="0" iyx="0"/>
		</inertial>
	</link>
	<link name="37">
		<visual>
			<geometry>
				<cylinder length="1.928329125693357" radius="0.9999"/>
			</geometry>
		</visual>
		<collision>
			<geometry>
				<cylinder length="1.928329125693357" radius="0.9999"/>
			</geometry>
		</collision>
		<inertial>
			<mass value="6.0568130706387295"/>
			<inertia ixx="0.03" iyy="0.03" izz="0.03" ixy="0" ixz="0" iyx="0"/>
		</inertial>
	</link>
	<link name="38">
		<visual>
			<geometry>
				<cylinder length="1.928329125693357" radius="0.9999"/>
			</geometry>
		</visual>
		<collision>
			<geometry>
				<cylinder length="1.928329125693357" radius="0.9999"/>
			</geometry>
		</collision>
		<inertial>
			<mass value="6.0568130706387295"/>
			<inertia ixx="0.03" iyy="0.03" izz="0.03" ixy="0" ixz="0" iyx="0"/>
		</inertial>
	</link>
	<link name="39">
		<visual>
			<geometry>
				<cylinder length="1.928329125693357" radius="0.9999"/>
			</geometry>
		</visual>
		<collision>
			<geometry>
				<cylinder length="1.928329125693357" radius="0.9999"/>
			</geometry>
		</collision>
		<inertial>
			<mass value="6.0568130706387295"/>
			<inertia ixx="0.03" iyy="0.03" izz="0.03" ixy="0" ixz="0" iyx="0"/>
		</inertial>
	</link>
	<link name="210">
		<visual>
			<geometry>
				<cylinder length="1.928329125693357" radius="0.9999"/>
			</geometry>
		</visual>
		<collision>
			<geometry>
				<cylinder length="1.928329125693357" radius="0.9999"/>
			</geometry>
		</collision>
		<inertial>
			<mass value="6.0568130706387295"/>
			<inertia ixx="0.03" iyy="0.03" izz="0.03" ixy="0" ixz="0" iyx="0"/>
		</inertial>
	</link>
	<link name="311">
		<visual>
			<geometry>
				<cylinder length="1.928329125693357" radius="0.9999"/>
			</geometry>
		</visual>
		<collision>
			<geometry>
				<cylinder length="1.928329125693357" radius="0.9999"/>
			</geometry>
		</collision>
		<inertial>
			<mass value="6.0568130706387295"/>
			<inertia ixx="0.03" iyy="0.03" izz="0.03" ixy="0" ixz="0" iyx="0"/>
		</inertial>
	</link>
	<link name="312">
		<visual>
			<geometry>
				<cylinder length="1.928329125693357" radius="0.9999"/>
			</geometry>
		</visual>
		<collision>
			<geometry>
				<cylinder length="1.928329125693357" radius="0.9999"/>
			</geometry>
		</collision>
		<inertial>
			<mass value="6.0568130706387295"/>
			<inertia ixx="0.03" iyy="0.03" izz="0.03" ixy="0" ixz="0" iyx="0"/>
		</inertial>
	</link>
	<link name="313">
		<visual>
			<geometry>
				<cylinder length="1.928329125693357" radius="0.9999"/>
			</geometry>
		</visual>
		<collision>
			<geometry>
				<cylinder length="1.928329125693357" radius="0.9999"/>
			</geometry>
		</collision>
		<inertial>
			<mass value="6.0568130706387295"/>
			<inertia ixx="0.03" iyy="0.03" izz="0.03" ixy="0" ixz="0" iyx="0"/>
		</inertial>
	</link>
	<link name="114">
		<visual>
			<geometry>
				<cylinder length="1.928329125693357" radius="0.9999"/>
			</geometry>
		</visual>
		<collision>
			<geometry>
				<cylinder length="1.928329125693357" radius="0.9999"/>
			</geometry>
		</collision>
		<inertial>
			<mass value="6.0568130706387295"/>
			<inertia ixx="0.03" iyy="0.03" izz="0.03" ixy="0" ixz="0" iyx="0"/>
		</inertial>
	</link>
	<link name="215">
		<visual>
			<geometry>
				<cylinder length="1.928329125693357" radius="0.9999"/>
			</geometry>
		</visual>
		<collision>
			<geometry>
				<cylinder length="1.928329125693357" radius="0.9999"/>
			</geometry>
		</collision>
		<inertial>
			<mass value="6.0568130706387295"/>
			<inertia ixx="0.03" iyy="0.03" izz="0.03" ixy="0" ixz="0" iyx="0"/>
		</inertial>
	</link>
	<link name="316">
		<visual>
			<geometry>
				<cylinder length="1.928329125693357" radius="0.9999"/>
			</geometry>
		</visual>
		<collision>
			<geometry>
				<cylinder length="1.928329125693357" radius="0.9999"/>
			</geometry>
		</collision>
		<inertial>
			<mass value="6.0568130706387295"/>
			<inertia ixx="0.03" iyy="0.03" izz="0.03" ixy="0" ixz="0" iyx="0"/>
		</inertial>
	</link>
	<link name="317">
		<visual>
			<geometry>
				<cylinder length="1.928329125693357" radius="0.9999"/>
			</geometry>
		</visual>
		<collision>
			<geometry>
				<cylinder length="1.928329125693357" radius="0.9999"/>
			</geometry>
		</collision>
		<inertial>
			<mass value="6.0568130706387295"/>
			<inertia ixx="0.03" iyy="0.03" izz="0.03" ixy="0" ixz="0" iyx="0"/>
		</inertial>
	</link>
	<link name="318">
		<visual>
			<geometry>
				<cylinder length="1.928329125693357" radius="0.9999"/>
			</geometry>
		</visual>
		<collision>
			<geometry>
				<cylinder length="1.928329125693357" radius="0.9999"/>
			</geometry>
		</collision>
		<inertial>
			<mass value="6.0568130706387295"/>
			<inertia ixx="0.03" iyy="0.03" izz="0.03" ixy="0" ixz="0" iyx="0"/>
		</inertial>
	</link>
	<link name="219">
		<visual>
			<geometry>
				<cylinder length="1.928329125693357" radius="0.9999"/>
			</geometry>
		</visual>
		<collision>
			<geometry>
				<cylinder length="1.928329125693357" radius="0.9999"/>
			</geometry>
		</collision>
		<inertial>
			<mass value="6.0568130706387295"/>
			<inertia ixx="0.03" iyy="0.03" izz="0.03" ixy="0" ixz="0" iyx="0"/>
		</inertial>
	</link>
	<link name="320">
		<visual>
			<geometry>
				<cylinder length="1.928329125693357" radius="0.9999"/>
			</geometry>
		</visual>
		<collision>
			<geometry>
				<cylinder length="1.928329125693357" radius="0.9999"/>
			</geometry>
		</collision>
		<inertial>
			<mass value="6.0568130706387295"/>
			<inertia ixx="0.03" iyy="0.03" izz="0.03" ixy="0" ixz="0" iyx="0"/>
		</inertial>
	</link>
	<link name="321">
		<visual>
			<geometry>
				<cylinder length="1.928329125693357" radius="0.9999"/>
			</geometry>
		</visual>
		<collision>
			<geometry>
				<cylinder length="1.928329125693357" radius="0.9999"/>
			</geometry>
		</collision>
		<inertial>
			<mass value="6.0568130706387295"/>
			<inertia ixx="0.03" iyy="0.03" izz="0.03" ixy="0" ixz="0" iyx="0"/>
		</inertial>
	</link>
	<link name="322">
		<visual>
			<geometry>
				<cylinder length="1.928329125693357" radius="0.9999"/>
			</geometry>
		</visual>
		<collision>
			<geometry>
				<cylinder length="1.928329125693357" radius="0.9999"/>
			</geometry>
		</collision>
		<inertial>
			<mass value="6.0568130706387295"/>
			<inertia ixx="0.03" iyy="0.03" izz="0.03" ixy="0" ixz="0" iyx="0"/>
		</inertial>
	</link>
	<link name="223">
		<visual>
			<geometry>
				<cylinder length="1.928329125693357" radius="0.9999"/>
			</geometry>
		</visual>
		<collision>
			<geometry>
				<cylinder length="1.928329125693357" radius="0.9999"/>
			</geometry>
		</collision>
		<inertial>
			<mass value="6.0568130706387295"/>
			<inertia ixx="0.03" iyy="0.03" izz="0.03" ixy="0" ixz="0" iyx="0"/>
		</inertial>
	</link>
	<link name="324">
		<visual>
			<geometry>
				<cylinder length="1.928329125693357" radius="0.9999"/>
			</geometry>
		</visual>
		<collision>
			<geometry>
				<cylinder length="1.928329125693357" radius="0.9999"/>
			</geometry>
		</collision>
		<inertial>
			<mass value="6.0568130706387295"/>
			<inertia ixx="0.03" iyy="0.03" izz="0.03" ixy="0" ixz="0" iyx="0"/>
		</inertial>
	</link>
	<link name="325">
		<visual>
			<geometry>
				<cylinder length="1.928329125693357" radius="0.9999"/>
			</geometry>
		</visual>
		<collision>
			<geometry>
				<cylinder length="1.928329125693357" radius="0.9999"/>
			</geometry>
		</collision>
		<inertial>
			<mass value="6.0568130706387295"/>
			<inertia ixx="0.03" iyy="0.03" izz="0.03" ixy="0" ixz="0" iyx="0"/>
		</inertial>
	</link>
	<link name="326">
		<visual>
			<geometry>
				<cylinder length="1.928329125693357" radius="0.9999"/>
			</geometry>
		</visual>
		<collision>
			<geometry>
				<cylinder length="1.928329125693357" radius="0.9999"/>
			</geometry>
		</collision>
		<inertial>
			<mass value="6.0568130706387295"/>
			<inertia ixx="0.03" iyy="0.03" izz="0.03" ixy="0" ixz="0" iyx="0"/>
		</inertial>
	</link>
	<link name="127">
		<visual>
			<geometry>
				<cylinder length="1.928329125693357" radius="0.9999"/>
			</geometry>
		</visual>
		<collision>
			<geometry>
				<cylinder length="1.928329125693357" radius="0.9999"/>
			</geometry>
		</collision>
		<inertial>
			<mass value="6.0568130706387295"/>
			<inertia ixx="0.03" iyy="0.03" izz="0.03" ixy="0" ixz="0" iyx="0"/>
		</inertial>
	</link>
	<link name="228">
		<visual>
			<geometry>
				<cylinder length="1.928329125693357" radius="0.9999"/>
			</geometry>
		</visual>
		<collision>
			<geometry>
				<cylinder length="1.928329125693357" radius="0.9999"/>
			</geometry>
		</collision>
		<inertial>
			<mass value="6.0568130706387295"/>
			<inertia ixx="0.03" iyy="0.03" izz="0.03" ixy="0" ixz="0" iyx="0"/>
		</inertial>
	</link>
	<link name="329">
		<visual>
			<geometry>
				<cylinder length="1.928329125693357" radius="0.9999"/>
			</geometry>
		</visual>
		<collision>
			<geometry>
				<cylinder length="1.928329125693357" radius="0.9999"/>
			</geometry>
		</collision>
		<inertial>
			<mass value="6.0568130706387295"/>
			<inertia ixx="0.03" iyy="0.03" izz="0.03" ixy="0" ixz="0" iyx="0"/>
		</inertial>
	</link>
	<link name="330">
		<visual>
			<geometry>
				<cylinder length="1.928329125693357" radius="0.9999"/>
			</geometry>
		</visual>
		<collision>
			<geometry>
				<cylinder length="1.928329125693357" radius="0.9999"/>
			</geometry>
		</collision>
		<inertial>
			<mass value="6.0568130706387295"/>
			<inertia ixx="0.03" iyy="0.03" izz="0.03" ixy="0" ixz="0" iyx="0"/>
		</inertial>
	</link>
	<link name="331">
		<visual>
			<geometry>
				<cylinder length="1.928329125693357" radius="0.9999"/>
			</geometry>
		</visual>
		<collision>
			<geometry>
				<cylinder length="1.928329125693357" radius="0.9999"/>
			</geometry>
		</collision>
		<inertial>
			<mass value="6.0568130706387295"/>
			<inertia ixx="0.03" iyy="0.03" izz="0.03" ixy="0" ixz="0" iyx="0"/>
		</inertial>
	</link>
	<link name="232">
		<visual>
			<geometry>
				<cylinder length="1.928329125693357" radius="0.9999"/>
			</geometry>
		</visual>
		<collision>
			<geometry>
				<cylinder length="1.928329125693357" radius="0.9999"/>
			</geometry>
		</collision>
		<inertial>
			<mass value="6.0568130706387295"/>
			<inertia ixx="0.03" iyy="0.03" izz="0.03" ixy="0" ixz="0" iyx="0"/>
		</inertial>
	</link>
	<link name="333">
		<visual>
			<geometry>
				<cylinder length="1.928329125693357" radius="0.9999"/>
			</geometry>
		</visual>
		<collision>
			<geometry>
				<cylinder length="1.928329125693357" radius="0.9999"/>
			</geometry>
		</collision>
		<inertial>
			<mass value="6.0568130706387295"/>
			<inertia ixx="0.03" iyy="0.03" izz="0.03" ixy="0" ixz="0" iyx="0"/>
		</inertial>
	</link>
	<link name="334">
		<visual>
			<geometry>
				<cylinder length="1.928329125693357" radius="0.9999"/>
			</geometry>
		</visual>
		<collision>
			<geometry>
				<cylinder length="1.928329125693357" radius="0.9999"/>
			</geometry>
		</collision>
		<inertial>
			<mass value="6.0568130706387295"/>
			<inertia ixx="0.03" iyy="0.03" izz="0.03" ixy="0" ixz="0" iyx="0"/>
		</inertial>
	</link>
	<link name="335">
		<visual>
			<geometry>
				<cylinder length="1.928329125693357" radius="0.9999"/>
			</geometry>
		</visual>
		<collision>
			<geometry>
				<cylinder length="1.928329125693357" radius="0.9999"/>
			</geometry>
		</collision>
		<inertial>
			<mass value="6.0568130706387295"/>
			<inertia ixx="0.03" iyy="0.03" izz="0.03" ixy="0" ixz="0" iyx="0"/>
		</inertial>
	</link>
	<link name="236">
		<visual>
			<geometry>
				<cylinder length="1.928329125693357" radius="0.9999"/>
			</geometry>
		</visual>
		<collision>
			<geometry>
				<cylinder length="1.928329125693357" radius="0.9999"/>
			</geometry>
		</collision>
		<inertial>
			<mass value="6.0568130706387295"/>
			<inertia ixx="0.03" iyy="0.03" izz="0.03" ixy="0" ixz="0" iyx="0"/>
		</inertial>
	</link>
	<link name="337">
		<visual>
			<geometry>
				<cylinder length="1.928329125693357" radius="0.9999"/>
			</geometry>
		</visual>
		<collision>
			<geometry>
				<cylinder length="1.928329125693357" radius="0.9999"/>
			</geometry>
		</collision>
		<inertial>
			<mass value="6.0568130706387295"/>
			<inertia ixx="0.03" iyy="0.03" izz="0.03" ixy="0" ixz="0" iyx="0"/>
		</inertial>
	</link>
	<link name="338">
		<visual>
			<geometry>
				<cylinder length="1.928329125693357" radius="0.9999"/>
			</geometry>
		</visual>
		<collision>
			<geometry>
				<cylinder length="1.928329125693357" radius="0.9999"/>
			</geometry>
		</collision>
		<inertial>
			<mass value="6.0568130706387295"/>
			<inertia ixx="0.03" iyy="0.03" izz="0.03" ixy="0" ixz="0" iyx="0"/>
		</inertial>
	</link>
	<link name="339">
		<visual>
			<geometry>
				<cylinder length="1.928329125693357" radius="0.9999"/>
			</geometry>
		</visual>
		<collision>
			<geometry>
				<cylinder length="1.928329125693357" radius="0.9999"/>
			</geometry>
		</collision>
		<inertial>
			<mass value="6.0568130706387295"/>
			<inertia ixx="0.03" iyy="0.03" izz="0.03" ixy="0" ixz="0" iyx="0"/>
		</inertial>
	</link>
	<joint name="11_to_0" type="revolute">
		<parent link="0"/>
		<child link="11"/>
		<axis xyz="1 0 0"/>
		<limit effort="1" upper="-3.1415" lower="3.1415" velocity="1"/>
		<origin rpy="11.274370204840425 6.282556988648868 6.0958890871509315" xyz="0.9999 0.3535889622219287 0.9606944566278526"/>
	</joint>
	<joint name="22_to_11" type="revolute">
		<parent link="11"/>
		<child link="22"/>
		<axis xyz="1 0 0"/>
		<limit effort="1" upper="-3.1415" lower="3.1415" velocity="1"/>
		<origin rpy="10.017733143404508 5.356506984867917 6.0958890871509315" xyz="0.864255060277676 0.7535889622219286 0.8606944566278526"/>
	</joint>
	<joint name="33_to_22" type="revolute">
		<parent link="22"/>
		<child link="33"/>
		<axis xyz="1 0 0"/>
		<limit effort="1" upper="-3.1415" lower="3.1415" velocity="1"/>
		<origin rpy="12.53100726627634 6.282556988648868 6.0958890871509315" xyz="0.9999 0.4535889622219287 0.8606944566278526"/>
	</joint>
	<joint name="34_to_22" type="revolute">
		<parent link="22"/>
		<child link="34"/>
		<axis xyz="1 0 0"/>
		<limit effort="1" upper="-3.1415" lower="3.1415" velocity="1"/>
		<origin rpy="18.79651089941451 6.282556988648868 6.0958890871509315" xyz="0.9999 0.4535889622219287 0.8606944566278526"/>
	</joint>
	<joint name="35_to_22" type="revolute">
		<parent link="22"/>
		<child link="35"/>
		<axis xyz="1 0 0"/>
		<limit effort="1" upper="-3.1415" lower="3.1415" velocity="1"/>
		<origin rpy="25.06201453255268 6.282556988648868 6.0958890871509315" xyz="0.9999 0.4535889622219287 0.8606944566278526"/>
	</joint>
	<joint name="26_to_11" type="revolute">
		<parent link="11"/>
		<child link="26"/>
		<axis xyz="1 0 0"/>
		<limit effort="1" upper="-3.1415" lower="3.1415" velocity="1"/>
		<origin rpy="15.026599715106762 5.356506984867917 6.0958890871509315" xyz="0.864255060277676 0.7535889622219286 0.8606944566278526"/>
	</joint>
	<joint name="37_to_26" type="revolute">
		<parent link="26"/>
		<child link="37"/>
		<axis xyz="1 0 0"/>
		<limit effort="1" upper="-3.1415" lower="3.1415" velocity="1"/>
		<origin rpy="12.53100726627634 6.282556988648868 6.0958890871509315" xyz="0.9999 0.4535889622219287 0.8606944566278526"/>
	</joint>
	<joint name="38_to_26" type="revolute">
		<parent link="26"/>
		<child link="38"/>
		<axis xyz="1 0 0"/>
		<limit effort="1" upper="-3.1415" lower="3.1415" velocity="1"/>
		<origin rpy="18.79651089941451 6.282556988648868 6.0958890871509315" xyz="0.9999 0.4535889622219287 0.8606944566278526"/>
	</joint>
	<joint name="39_to_26" type="revolute">
		<parent link="26"/>
		<child link="39"/>
		<axis xyz="1 0 0"/>
		<limit effort="1" upper="-3.1415" lower="3.1415" velocity="1"/>
		<origin rpy="25.06201453255268 6.282556988648868 6.0958890871509315" xyz="0.9999 0.4535889622219287 0.8606944566278526"/>
	</joint>
	<joint name="210_to_11" type="revolute">
		<parent link="11"/>
		<child link="210"/>
		<axis xyz="1 0 0"/>
		<limit effort="1" upper="-3.1415" lower="3.1415" velocity="1"/>
		<origin rpy="20.035466286809015 5.356506984867917 6.0958890871509315" xyz="0.864255060277676 0.7535889622219286 0.8606944566278526"/>
	</joint>
	<joint name="311_to_210" type="revolute">
		<parent link="210"/>
		<child link="311"/>
		<axis xyz="1 0 0"/>
		<limit effort="1" upper="-3.1415" lower="3.1415" velocity="1"/>
		<origin rpy="12.53100726627634 6.282556988648868 6.0958890871509315" xyz="0.9999 0.4535889622219287 0.8606944566278526"/>
	</joint>
	<joint name="312_to_210" type="revolute">
		<parent link="210"/>
		<child link="312"/>
		<axis xyz="1 0 0"/>
		<limit effort="1" upper="-3.1415" lower="3.1415" velocity="1"/>
		<origin rpy="18.79651089941451 6.282556988648868 6.0958890871509315" xyz="0.9999 0.4535889622219287 0.8606944566278526"/>
	</joint>
	<joint name="313_to_210" type="revolute">
		<parent link="210"/>
		<child link="313"/>
		<axis xyz="1 0 0"/>
		<limit effort="1" upper="-3.1415" lower="3.1415" velocity="1"/>
		<origin rpy="25.06201453255268 6.282556988648868 6.0958890871509315" xyz="0.9999 0.4535889622219287 0.8606944566278526"/>
	</joint>
	<joint name="114_to_0" type="revolute">
		<parent link="0"/>
		<child link="114"/>
		<axis xyz="1 0 0"/>
		<limit effort="1" upper="-3.1415" lower="3.1415" velocity="1"/>
		<origin rpy="16.911555307260638 6.282556988648868 6.0958890871509315" xyz="0.9999 0.3535889622219287 0.9606944566278526"/>
	</joint>
	<joint name="215_to_114" type="revolute">
		<parent link="114"/>
		<child link="215"/>
		<axis xyz="1 0 0"/>
		<limit effort="1" upper="-3.1415" lower="3.1415" velocity="1"/>
		<origin rpy="10.017733143404508 5.356506984867917 6.0958890871509315" xyz="0.864255060277676 0.7535889622219286 0.8606944566278526"/>
	</joint>
	<joint name="316_to_215" type="revolute">
		<parent link="215"/>
		<child link="316"/>
		<axis xyz="1 0 0"/>
		<limit effort="1" upper="-3.1415" lower="3.1415" velocity="1"/>
		<origin rpy="12.53100726627634 6.282556988648868 6.0958890871509315" xyz="0.9999 0.4535889622219287 0.8606944566278526"/>
	</joint>
	<joint name="317_to_215" type="revolute">
		<parent link="215"/>
		<child link="317"/>
		<axis xyz="1 0 0"/>
		<limit effort="1" upper="-3.1415" lower="3.1415" velocity="1"/>
		<origin rpy="18.79651089941451 6.282556988648868 6.0958890871509315" xyz="0.9999 0.4535889622219287 0.8606944566278526"/>
	</joint>
	<joint name="318_to_215" type="revolute">
		<parent link="215"/>
		<child link="318"/>
		<axis xyz="1 0 0"/>
		<limit effort="1" upper="-3.1415" lower="3.1415" velocity="1"/>
		<origin rpy="25.06201453255268 6.282556988648868 6.0958890871509315" xyz="0.9999 0.4535889622219287 0.8606944566278526"/>
	</joint>
	<joint name="219_to_114" type="revolute">
		<parent link="114"/>
		<child link="219"/>
		<axis xyz="1 0 0"/>
		<limit effort="1" upper="-3.1415" lower="3.1415" velocity="1"/>
		<origin rpy="15.026599715106762 5.356506984867917 6.0958890871509315" xyz="0.864255060277676 0.7535889622219286 0.8606944566278526"/>
	</joint>
	<joint name="320_to_219" type="revolute">
		<parent link="219"/>
		<child link="320"/>
		<axis xyz="1 0 0"/>
		<limit effort="1" upper="-3.1415" lower="3.1415" velocity="1"/>
		<origin rpy="12.53100726627634 6.282556988648868 6.0958890871509315" xyz="0.9999 0.4535889622219287 0.8606944566278526"/>
	</joint>
	<joint name="321_to_219" type="revolute">
		<parent link="219"/>
		<child link="321"/>
		<axis xyz="1 0 0"/>
		<limit effort="1" upper="-3.1415" lower="3.1415" velocity="1"/>
		<origin rpy="18.79651089941451 6.282556988648868 6.0958890871509315" xyz="0.9999 0.4535889622219287 0.8606944566278526"/>
	</joint>
	<joint name="322_to_219" type="revolute">
		<parent link="219"/>
		<child link="322"/>
		<axis xyz="1 0 0"/>
		<limit effort="1" upper="-3.1415" lower="3.1415" velocity="1"/>
		<origin rpy="25.06201453255268 6.282556988648868 6.0958890871509315" xyz="0.9999 0.4535889622219287 0.8606944566278526"/>
	</joint>
	<joint name="223_to_114" type="revolute">
		<parent link="114"/>
		<child link="223"/>
		<axis xyz="1 0 0"/>
		<limit effort="1" upper="-3.1415" lower="3.1415" velocity="1"/>
		<origin rpy="20.035466286809015 5.356506984867917 6.0958890871509315" xyz="0.864255060277676 0.7535889622219286 0.8606944566278526"/>
	</joint>
	<joint name="324_to_223" type="revolute">
		<parent link="223"/>
		<child link="324"/>
		<axis xyz="1 0 0"/>
		<limit effort="1" upper="-3.1415" lower="3.1415" velocity="1"/>
		<origin rpy="12.53100726627634 6.282556988648868 6.0958890871509315" xyz="0.9999 0.4535889622219287 0.8606944566278526"/>
	</joint>
	<joint name="325_to_223" type="revolute">
		<parent link="223"/>
		<child link="325"/>
		<axis xyz="1 0 0"/>
		<limit effort="1" upper="-3.1415" lower="3.1415" velocity="1"/>
		<origin rpy="18.79651089941451 6.282556988648868 6.0958890871509315" xyz="0.9999 0.4535889622219287 0.8606944566278526"/>
	</joint>
	<joint name="326_to_223" type="revolute">
		<parent link="223"/>
		<child link="326"/>
		<axis xyz="1 0 0"/>
		<limit effort="1" upper="-3.1415" lower="3.1415" velocity="1"/>
		<origin rpy="25.06201453255268 6.282556988648868 6.0958890871509315" xyz="0.9999 0.4535889622219287 0.8606944566278526"/>
	</joint>
	<joint name="127_to_0" type="revolute">
		<parent link="0"/>
		<child link="127"/>
		<axis xyz="1 0 0"/>
		<limit effort="1" upper="-3.1415" lower="3.1415" velocity="1"/>
		<origin rpy="22.54874040968085 6.282556988648868 6.0958890871509315" xyz="0.9999 0.3535889622219287 0.9606944566278526"/>
	</joint>
	<joint name="228_to_127" type="revolute">
		<parent link="127"/>
		<child link="228"/>
		<axis xyz="1 0 0"/>
		<limit effort="1" upper="-3.1415" lower="3.1415" velocity="1"/>
		<origin rpy="10.017733143404508 5.356506984867917 6.0958890871509315" xyz="0.864255060277676 0.7535889622219286 0.8606944566278526"/>
	</joint>
	<joint name="329_to_228" type="revolute">
		<parent link="228"/>
		<child link="329"/>
		<axis xyz="1 0 0"/>
		<limit effort="1" upper="-3.1415" lower="3.1415" velocity="1"/>
		<origin rpy="12.53100726627634 6.282556988648868 6.0958890871509315" xyz="0.9999 0.4535889622219287 0.8606944566278526"/>
	</joint>
	<joint name="330_to_228" type="revolute">
		<parent link="228"/>
		<child link="330"/>
		<axis xyz="1 0 0"/>
		<limit effort="1" upper="-3.1415" lower="3.1415" velocity="1"/>
		<origin rpy="18.79651089941451 6.282556988648868 6.0958890871509315" xyz="0.9999 0.4535889622219287 0.8606944566278526"/>
	</joint>
	<joint name="331_to_228" type="revolute">
		<parent link="228"/>
		<child link="331"/>
		<axis xyz="1 0 0"/>
		<limit effort="1" upper="-3.1415" lower="3.1415" velocity="1"/>
		<origin rpy="25.06201453255268 6.282556988648868 6.0958890871509315" xyz="0.9999 0.4535889622219287 0.8606944566278526"/>
	</joint>
	<joint name="232_to_127" type="revolute">
		<parent link="127"/>
		<child link="232"/>
		<axis xyz="1 0 0"/>
		<limit effort="1" upper="-3.1415" lower="3.1415" velocity="1"/>
		<origin rpy="15.026599715106762 5.356506984867917 6.0958890871509315" xyz="0.864255060277676 0.7535889622219286 0.8606944566278526"/>
	</joint>
	<joint name="333_to_232" type="revolute">
		<parent link="232"/>
		<child link="333"/>
		<axis xyz="1 0 0"/>
		<limit effort="1" upper="-3.1415" lower="3.1415" velocity="1"/>
		<origin rpy="12.53100726627634 6.282556988648868 6.0958890871509315" xyz="0.9999 0.4535889622219287 0.8606944566278526"/>
	</joint>
	<joint name="334_to_232" type="revolute">
		<parent link="232"/>
		<child link="334"/>
		<axis xyz="1 0 0"/>
		<limit effort="1" upper="-3.1415" lower="3.1415" velocity="1"/>
		<origin rpy="18.79651089941451 6.282556988648868 6.0958890871509315" xyz="0.9999 0.4535889622219287 0.8606944566278526"/>
	</joint>
	<joint name="335_to_232" type="revolute">
		<parent link="232"/>
		<child link="335"/>
		<axis xyz="1 0 0"/>
		<limit effort="1" upper="-3.1415" lower="3.1415" velocity="1"/>
		<origin rpy="25.06201453255268 6.282556988648868 6.0958890871509315" xyz="0.9999 0.4535889622219287 0.8606944566278526"/>
	</joint>
	<joint name="236_to_127" type="revolute">
		<parent link="127"/>
		<child link="236"/>
		<axis xyz="1 0 0"/>
		<limit effort="1" upper="-3.1415" lower="3.1415" velocity="1"/>
		<origin rpy="20.035466286809015 5.356506984867917 6.0958890871509315" xyz="0.864255060277676 0.7535889622219286 0.8606944566278526"/>
	</joint>
	<joint name="337_to_236" type="revolute">
		<parent link="236"/>
		<child link="337"/>
		<axis xyz="1 0 0"/>
		<limit effort="1" upper="-3.1415" lower="3.1415" velocity="1"/>
		<origin rpy="12.53100726627634 6.282556988648868 6.0958890871509315" xyz="0.9999 0.4535889622219287 0.8606944566278526"/>
	</joint>
	<joint name="338_to_236" type="revolute">
		<parent link="236"/>
		<child link="338"/>
		<axis xyz="1 0 0"/>
		<limit effort="1" upper="-3.1415" lower="3.1415" velocity="1"/>
		<origin rpy="18.79651089941451 6.282556988648868 6.0958890871509315" xyz="0.9999 0.4535889622219287 0.8606944566278526"/>
	</joint>
	<joint name="339_to_236" type="revolute">
		<parent link="236"/>
		<child link="339"/>
		<axis xyz="1 0 0"/>
		<limit effort="1" upper="-3.1415" lower="3.1415" velocity="1"/>
		<origin rpy="25.06201453255268 6.282556988648868 6.0958890871509315" xyz="0.9999 0.4535889622219287 0.8606944566278526"/>
	</joint>
</robot>
