<?xml version="1.0"?><robot name="pepe">
	<link name="0">
		<visual>
			<geometry>
				<cylinder length="1.287093381513912" radius="0.8819807015086888"/>
			</geometry>
		</visual>
		<collision>
			<geometry>
				<cylinder length="1.287093381513912" radius="0.8819807015086888"/>
			</geometry>
		</collision>
		<inertial>
			<mass value="3.1454160229753874"/>
			<inertia ixx="0.03" iyy="0.03" izz="0.03" ixy="0" ixz="0" iyx="0"/>
		</inertial>
	</link>
	<link name="11">
		<visual>
			<geometry>
				<cylinder length="1.487093381513912" radius="0.7819807015086888"/>
			</geometry>
		</visual>
		<collision>
			<geometry>
				<cylinder length="1.487093381513912" radius="0.7819807015086888"/>
			</geometry>
		</collision>
		<inertial>
			<mass value="2.856802280917818"/>
			<inertia ixx="0.03" iyy="0.03" izz="0.03" ixy="0" ixz="0" iyx="0"/>
		</inertial>
	</link>
	<link name="12">
		<visual>
			<geometry>
				<cylinder length="1.487093381513912" radius="0.7819807015086888"/>
			</geometry>
		</visual>
		<collision>
			<geometry>
				<cylinder length="1.487093381513912" radius="0.7819807015086888"/>
			</geometry>
		</collision>
		<inertial>
			<mass value="2.856802280917818"/>
			<inertia ixx="0.03" iyy="0.03" izz="0.03" ixy="0" ixz="0" iyx="0"/>
		</inertial>
	</link>
	<link name="13">
		<visual>
			<geometry>
				<cylinder length="1.487093381513912" radius="0.7819807015086888"/>
			</geometry>
		</visual>
		<collision>
			<geometry>
				<cylinder length="1.487093381513912" radius="0.7819807015086888"/>
			</geometry>
		</collision>
		<inertial>
			<mass value="2.856802280917818"/>
			<inertia ixx="0.03" iyy="0.03" izz="0.03" ixy="0" ixz="0" iyx="0"/>
		</inertial>
	</link>
	<joint name="11_to_0" type="revolute">
		<parent link="0"/>
		<child link="11"/>
		<axis xyz="1 0 0"/>
		<limit effort="1" upper="-3.1415" lower="3.1415" velocity="1"/>
		<origin rpy="9.822124079454426 4.041582349174072 4.382430559563875" xyz="0.1462641576616387 0.5572290704684391 0.8285118940376992"/>
	</joint>
	<joint name="12_to_0" type="revolute">
		<parent link="0"/>
		<child link="12"/>
		<axis xyz="1 0 0"/>
		<limit effort="1" upper="-3.1415" lower="3.1415" velocity="1"/>
		<origin rpy="14.733186119181639 4.041582349174072 4.382430559563875" xyz="0.1462641576616387 0.5572290704684391 0.8285118940376992"/>
	</joint>
	<joint name="13_to_0" type="revolute">
		<parent link="0"/>
		<child link="13"/>
		<axis xyz="1 0 0"/>
		<limit effort="1" upper="-3.1415" lower="3.1415" velocity="1"/>
		<origin rpy="19.64424815890885 4.041582349174072 4.382430559563875" xyz="0.1462641576616387 0.5572290704684391 0.8285118940376992"/>
	</joint>
</robot>
